Workbook

Sheet chorizo
A6: 3500
A7: 2600 | B7: 2 dias

Sheet choriboni
C2: Socios | D2: Aportes | G2: tipo | H2: Aporte
C3: José Gustavo | D3: =+SUMIF(G:G,C3,D:D) -> 27808267 | G3: Patrimonio | H3: =+SUMIF($E$23:$E$87,G3,$D$23:$D$87) -> 19944350
C4: Edwin | D4: =+SUMIF(G:G,C4,D:D) -> 3198300 | G4: Costo | H4: =+SUMIF($E$23:$E$87,G4,$D$23:$D$87) -> 3683750
C5: Total | D5: =+D3+D4 -> 31006567 | G5: Inversión a recuperar | H5: =+SUMIF($E$23:$E$87,G5,$D$23:$D$87) -> 4345965
G6: INVIMA | H6: =+SUMIF($E$23:$E$87,G6,$D$23:$D$87) -> 490000
C7: Mitad | D7: =+D5/2+16.6 -> 15503300 | G7: Gasto | H7: =+SUMIF($E$23:$E$87,G7,$D$23:$D$87) -> 2542502
G8: Total | H8: =+SUM(H3:H7) -> 31006567
C9: fecha | D9: Aporte | E9: Medio
C10: 46062 | D10: 300000 | E10: NEQUI
C11: 46073 | D11: 1000000 | E11: NEQUI
C12: 46073 | D12: 3000000 | E12: BANCO CAJA SOCIAL
C13: 46080 | D13: 1000000 | E13: NEQUI
C14: 46084 | D14: 1500000 | E14: NEQUI
C15: 46086 | D15: 3855000 | E15: BANCO CAJA SOCIAL | F15: =+D19-D7 -> -0.1 | G15: =3855000-SUM(L64,L71,L67)/2 -> 2324075 | H15: SALDO A FAVOR | L15: =+SUM(L64,L71,L67)/2 -> 1530925
C16: 46098 | D16: 1650000 | E16: ARRIENDO
C17: PENDIENTE | D17: =+SUM(D10:D16) -> 12305000
C18: PAGADO | D18: 3198300
C19: Mitad | D19: =+D17+D18 -> 15503300 | E19: Aporte Edwin
C21: Total | D21: =+SUBTOTAL(9,D24:D1048576) -> 4345965
B23: id | C23: fecha | D23: valor | E23: tipo | F23: Equipo | G23: Responsable | H23: Consepto | I23: Proveedor
B24: 1 | C24: 46049 | D24: =1350000+150000 -> 1500000 | E24: Patrimonio | F24: Maquina | G24: José Gustavo | H24: Parrilla para segundo Negocio | I24: Comercializadora Las Brumas
B25: 2 | C25: 46049 | D25: =2500000+1400000+400000 -> 4300000 | E25: Patrimonio | F25: Maquina | G25: José Gustavo | H25: Nevera y Vitrina | I25: Compra y Venta El Dorado
B26: 3 | C26: 46056 | D26: =5400000+500000+(25000*2) -> 5950000 | E26: Patrimonio | F26: Maquina | G26: José Gustavo | H26: Parrilla - Chepes | I26: Muebles y Enseres CHEPE
B27: 4 | C27: 46056 | D27: 80000 | E27: Patrimonio | F27: Maquinaria y Equipo | G27: José Gustavo | H27: 2 Grameras | I27: El Cubo
B28: 5 | C28: 46056 | D28: 100000 | E28: Patrimonio | F28: Maquinaria y Equipo | G28: José Gustavo | H28: Bascula electrónica verde | I28: Dussan
B29: 6 | C29: 46056 | D29: 30000 | E29: Patrimonio | F29: Utencilios | G29: José Gustavo | H29: Despostador | I29: Dussan
B30: 7 | C30: 46060 | D30: 200000 | E30: Patrimonio | F30: Maquinaria y Equipo | G30: José Gustavo | H30: Campana con extractor a mujer bonita | I30: Compra y Venta D.C.
B31: 8 | C31: 46060 | D31: 110000 | E31: Patrimonio | F31: Maquinaria y Equipo | G31: José Gustavo | H31: Tabla de Picar | I31: LICICOL
B32: 9 | C32: 46060 | D32: =27000+35000 -> 62000 | E32: Patrimonio | F32: Maquina | G32: José Gustavo | H32: Candados | I32: RICAURTE
B33: 10 | C33: 46056 | D33: 2400000 | E33: Patrimonio | F33: Maquinaria y Equipo | G33: José Gustavo | H33: Mesas y sillas | I33: Muebles y montajes
B34: 11 | C34: 46056 | D34: 108150 | E34: Patrimonio | F34: Maquinaria y Equipo | G34: José Gustavo | H34: Canastas de aseo º Redeban | I34: RICAURTE
B35: 11 | C35: 46056 | D35: 180000 | E35: Patrimonio | G35: José Gustavo | H35: Extractores de la 19 | I35: La av 19
B36: 13 | C36: 46050 | D36: 135400 | E36: Patrimonio | F36: Utencilios | G36: José Gustavo | H36: Canastas, cuchillo, pinza, colador y otros
B37: 13 | C37: 46051 | D37: =50000+40000+10000+22000 -> 122000 | E37: Patrimonio | F37: Utencilios | G37: José Gustavo | H37: Canastas , cuchillos , piedra y pinzas
B38: 14 | C38: 46051 | D38: 21900 | E38: Inversión a recuperar | F38: Gasto - Local | G38: Edwin | H38: Certi. Tradición y libertad
B39: 15 | C39: 46051 | D39: 380000 | E39: Inversión a recuperar | F39: Gasto - Local | G39: José Gustavo | H39: Acarreos
B40: 16 | C40: 46051 | D40: 100000 | E40: Inversión a recuperar | F40: Gasto - Local | G40: Edwin | H40: Acarreos
B41: 17 | C41: 46051 | D41: 30000 | E41: Inversión a recuperar | F41: Gasto - Local | G41: Edwin | H41: Acarreos
B42: 18 | C42: 46060 | D42: 50000 | E42: Inversión a recuperar | F42: Gasto - Local | G42: Edwin | H42: Acarreos
B43: 19 | C43: 46066 | D43: 70000 | E43: Inversión a recuperar | F43: Gasto - Local | G43: José Gustavo | H43: Acarreos
...

Sheet choriboni_II
B1: gas | C1: 1800000
B2: muro y coples | C2: 500000
F7: caja 4
F8: 4 | G8: coca caola
G9: te

Sheet costeo
B2: 1600 | C2: Unidades
B3: 3700000 | C3: Costo total materias priams
B4: =+B3/B2 -> 2312.5 | C4: costo por unidad de producción
B6: 3500 | C6: precio por unidad
B7: =+B6*B2 -> 5600000 | C7: venta de producción
B8: =+B7-B3 -> 1900000 | C8: Margen de Ganancia
A10: 8 de marzo | B10: =7000*B2 -> 11200000 | C10: Venta en punto comercial
B11: =+B10-B3 -> 7500000

Sheet maquina
F1: 1200000 | G1: estufa
G2: meson cuadrado
G3: Software
E5: =+IF(E6>0,"Saldo a favor de papá","Saldo a favor a Edwin") -> Saldo a favor a Edwin | F5: =+IF(F6>0,"Saldo a favor de papá","Saldo a favor a Edwin") -> Saldo a favor a Edwin
B6: fecha | C6: Responsable | D6: Total | E6: =+SUM(E7:E1048576) -> -581250 | F6: =+SUM(F7:F1048576) -> -355925 | H6: =+E6+F6 -> -937175
B7: 46089 | C7: =+IF(E7>1," Jose","Edwin") -> Jose | D7: estufa | E7: 1300000
B8: 46089 | C8: =+IF(E8>1," Jose","Edwin") -> Edwin | D8: parrilla | E8: -1350000
B9: 46089 | C9: =+IF(E9>1," Jose","Edwin") -> Edwin | D9: mesas | E9: -400000
B10: 46089 | C10: =+IF(E10>1," Jose","Edwin") -> Edwin | D10: Campana | E10: =-500000/2 -> -250000
B11: 46089 | C11: =+IF(E11>1," Jose","Edwin") -> Edwin | D11: motor | E11: =-180000/2 -> -90000
B12: 46089 | C12: =+IF(E12>1," Jose","Edwin") -> Edwin | D12: dispositivo wifi | E12: -30000
B13: 46076 | C13: =+IF(E13>1," Jose","Edwin") -> Jose | D13: chorizo | E13: =((550-185)*3500)/2 -> 638750
B14: 46089 | C14: =+IF(E14>1," Jose","Edwin") -> Edwin | D14: Software | E14: =-800000/2 -> -400000
B16: 46097 | C16: =+IF(F16>1," Jose","Edwin") -> Edwin | D16: Caneca | F16: -50000
B17: 46097 | C17: =+IF(F17>1," Jose","Edwin") -> Edwin | D17: CCB | F17: =-60000/2 -> -30000
B18: 46089 | C18: =+IF(F18>1," Jose","Edwin") -> Jose | D18: Chorizos | F18: =(500*3500)/2 -> 875000 | G18: =+H18/2 -> 250 | H18: 500
B19: 46106 | C19: =+IF(F19>1," Jose","Edwin") -> Jose | D19: Chorizos | F19: =(230*3500)/2 -> 402500 | G19: =+H19/2 -> 115 | H19: 230
B20: 46106 | C20: =+IF(F20>1," Jose","Edwin") -> Edwin | D20: Chorizos de baja | F20: =-(50*3500)/2 -> -87500 | G20: =+H20/2 -> -25 | H20: -50
B21: 46106 | C21: =+IF(F21>1," Jose","Edwin") -> Jose | D21: Chorizos de degustaciòn | F21: =(20*3500)/2 -> 35000 | G21: =+H21/2 -> 10 | H21: 20
B22: 46107 | C22: =+IF(F22>1," Jose","Edwin") -> Jose | D22: dispositivo wifi | F22: 30000
A23: 46072 | B23: 46089 | C23: =+IF(F23>1," Jose","Edwin") -> Edwin | D23: Chorizos - REPOSICIÓN | F23: =-choriboni!$M$64 -> -1015000 | G23: 290
A24: 46073 | B24: 46084 | C24: =+IF(F24>1," Jose","Edwin") -> Edwin | D24: Cerdo y costilla | F24: =-choriboni!$M$67 -> -309925
A25: 46073 | B25: 46107 | C25: =+IF(F25>1," Jose","Edwin") -> Edwin | D25: Gaseosa | F25: =-choriboni!$M$71 -> -206000

Sheet Arqueo de Caja
C1: =+TEXT(C2,"ddd") -> sáb | E1: =+TEXT(E2,"ddd") -> vie | G1: =+TEXT(G2,"ddd") -> jue | I1: =+TEXT(I2,"ddd") -> mié | K1: =+TEXT(K2,"ddd") -> mar | M1: =+TEXT(M2,"ddd") -> lun | O1: =+TEXT(O2,"ddd") -> dom | Q1: =+TEXT(Q2,"ddd") -> sáb | S1: =+TEXT(S2,"ddd") -> vie | U1: =+TEXT(U2,"ddd") -> jue | W1: =+TEXT(W2,"ddd") -> mié | Y1: =+TEXT(Y2,"ddd") -> mar | AA1: =+TEXT(AA2,"ddd") -> lun | AC1: =+TEXT(AC2,"ddd") -> dom | AE1: =+TEXT(AE2,"ddd") -> sáb | AG1: =+TEXT(AG2,"ddd") -> vie | AI1: =+TEXT(AI2,"ddd") -> jue | AK1: =+TEXT(AK2,"ddd") -> mié | AM1: =+TEXT(AM2,"ddd") -> mar | AO1: =+TEXT(AO2,"ddd") -> lun | AQ1: =+TEXT(AQ2,"ddd") -> dom | AS1: =+TEXT(AS2,"ddd") -> sáb | AU1: =+TEXT(AU2,"ddd") -> vie | AW1: =+TEXT(AW2,"ddd") -> jue | AY1: =+TEXT(AY2,"ddd") -> mié | BA1: =+TEXT(BA2,"ddd") -> mar | BC1: =+TEXT(BC2,"ddd") -> lun | BE1: =+TEXT(BE2,"ddd") -> dom | BG1: =+TEXT(BG2,"ddd") -> sáb | BI1: =+TEXT(BI2,"ddd") -> vie | BK1: =+TEXT(BK2,"ddd") -> jue | BM1: =+TEXT(BM2,"ddd") -> mié | BO1: =+TEXT(BO2,"ddd") -> mar | BQ1: =+TEXT(BQ2,"ddd") -> lun | BS1: =+TEXT(BS2,"ddd") -> dom | BU1: =+TEXT(BU2,"ddd") -> sáb | BW1: =+TEXT(BW2,"ddd") -> vie | BY1: =+TEXT(BY2,"ddd") -> jue | CA1: =+TEXT(CA2,"ddd") -> mié | CC1: =+TEXT(CC2,"ddd") -> mar | CE1: =+TEXT(CE2,"ddd") -> lun | CG1: =+TEXT(CG2,"ddd") -> dom | CI1: =+TEXT(CI2,"ddd") -> sáb | CK1: =+TEXT(CK2,"ddd") -> vie | CM1: =+TEXT(CM2,"ddd") -> jue | CO1: =+TEXT(CO2,"ddd") -> mié | CQ1: =+TEXT(CQ2,"ddd") -> mar | CS1: =+TEXT(CS2,"ddd") -> lun
A2: valor billete | B2: Q | C2: =+E2+1 -> 46123 | D2: Q | E2: =+G2+1 -> 46122 | F2: Q | G2: =+I2+1 -> 46121 | H2: Q | I2: =+K2+1 -> 46120 | J2: Q | K2: =+M2+1 -> 46119 | L2: Q | M2: =+O2+1 -> 46118 | N2: Q | O2: =+Q2+1 -> 46117 | P2: Q | Q2: =+S2+1 -> 46116 | R2: Q | S2: =+U2+1 -> 46115 | T2: Q | U2: =+W2+1 -> 46114 | V2: Q | W2: =+Y2+1 -> 46113 | X2: Q | Y2: =+AA2+1 -> 46112 | Z2: Q | AA2: =+AC2+1 -> 46111 | AB2: Q | AC2: =+AE2+1 -> 46110 | AD2: Q | AE2: =+AG2+1 -> 46109 | AF2: Q | AG2: =+AI2+1 -> 46108 | AH2: Q | AI2: =+AK2+1 -> 46107 | AJ2: Q | AK2: =+AM2+1 -> 46106 | AL2: Q | AM2: =+AO2+1 -> 46105 | AN2: Q | AO2: =+AQ2+1 -> 46104 | AP2: Q | AQ2: =+AS2+1 -> 46103 | AR2: Q | AS2: =+AU2+1 -> 46102 | AT2: Q | AU2: =+AW2+1 -> 46101 | AV2: Q | AW2: =+AY2+1 -> 46100 | AX2: Q | AY2: =+BA2+1 -> 46099 | AZ2: Q | BA2: =+BC2+1 -> 46098 | BB2: Q | BC2: =+BE2+1 -> 46097 | BD2: Q | BE2: 46096 | BF2: Q | BG2: 46095 | BH2: Q | BI2: 46094 | BJ2: Q | BK2: 46093 | BL2: Q | BM2: 46092 | BN2: Q | BO2: 46091 | BP2: Q | BQ2: 46090 | BR2: Q | BS2: 46089 | BT2: Q | BU2: 46088 | BV2: Q | BW2: =+BY2+1 -> 46087 | BX2: Q | BY2: 46086 | BZ2: Q | CA2: 46085 | CB2: Q | CC2: 46084 | CD2: Q | CE2: 46083 | CF2: Q | CG2: 46082 | CH2: Q | CI2: 46081 | CJ2: Q | CK2: 46080 | CL2: Q | CM2: 46079 | CN2: Q | CO2: 46078 | CP2: Q | CQ2: 46077 | CR2: Q | CS2: 46076
A3: 100000 | B3: 0 | C3: =+$A3*B3 -> 0 | D3: 0 | E3: CERRADO | F3: 0 | G3: SIN ARQUEO | H3: 0 | I3: SIN ARQUEO | J3: 0 | K3: SIN ARQUEO | L3: 0 | M3: CERRADO | N3: 0 | O3: DOMINGO SANTO | P3: 0 | Q3: SÁBADO SANTO | R3: 0 | S3: VIERNES SANTO | T3: 0 | U3: JUEVES SANTO | V3: 0 | W3: =+$A3*V3 -> 0 | X3: 0 | Y3: SIN ARQUEO | Z3: 0 | AA3: SIN ARQUEO | AB3: 0 | AC3: =+$A3*AB3 -> 0 | AD3: 0 | AE3: =+$A3*AD3 -> 0 | AF3: 0 | AG3: =+$A3*AF3 -> 0 | AH3: 0 | AI3: SIN ARQUEO | AJ3: 0 | AK3: SIN ARQUEO | AL3: 0 | AM3: =+$A3*AL3 -> 0 | AN3: 0 | AO3: CERRADO | AP3: 0 | AQ3: CERRADO | AR3: 0 | AS3: =+$A3*AR3 -> 0 | AT3: 0 | AU3: =+$A3*AT3 -> 0 | AV3: 1 | AW3: =+$A3*AV3 -> 100000 | AX3: 0 | AY3: =+$A3*AX3 -> 0 | AZ3: 0 | BA3: =+$A3*AZ3 -> 0 | BC3: SIN ARQUEO | BD3: 0 | BE3: =+$A3*BD3 -> 0 | BF3: 0 | BG3: =+$A3*BF3 -> 0 | BI3: SIN ARQUEO | BJ3: 0 | BK3: =+$A3*BJ3 -> 0 | BL3: 0 | BM3: =+$A3*BL3 -> 0 | BN3: 0 | BO3: =+$A3*BN3 -> 0 | BP3: 2 | BQ3: =+$A3*BP3 -> 200000 | BR3: 0 | BS3: 0 | BT3: 0 | BU3: 0 | BW3: CERRADO | BX3: 0 | BY3: 0 | BZ3: 0 | CA3: 0 | CB3: 0 | CC3: SIN ARQUEO | CD3: 0 | CE3: =+$A3*CD3 -> 0 | CG3: CERRADO | CI3: =+$A3*CH3 -> 0 | CJ3: 1 | CK3: =+$A3*CJ3 -> 100000 | CL3: 0 | CM3: =+$A3*CL3 -> 0 | CN3: 0 | CO3: SIN ARQUEO | CP3: 0 | CQ3: =+$A3*CP3 -> 0 | CR3: 0 | CS3: =+$A3*CR3 -> 0
A4: 50000 | B4: 3 | C4: =+$A4*B4 -> 150000 | D4: 0 | F4: 0 | H4: 0 | J4: 0 | L4: 0 | N4: 0 | P4: 0 | R4: 0 | T4: 0 | V4: 0 | W4: =+$A4*V4 -> 0 | X4: 0 | Z4: 0 | AB4: 0 | AC4: =+$A4*AB4 -> 0 | AD4: 3 | AE4: =+$A4*AD4 -> 150000 | AF4: 0 | AG4: =+$A4*AF4 -> 0 | AH4: 0 | AJ4: 0 | AL4: 0 | AM4: =+$A4*AL4 -> 0 | AN4: 0 | AP4: 0 | AR4: 0 | AS4: =+$A4*AR4 -> 0 | AT4: 0 | AU4: =+$A4*AT4 -> 0 | AV4: 2 | AW4: =+$A4*AV4 -> 100000 | AX4: 0 | AY4: =+$A4*AX4 -> 0 | AZ4: 0 | BA4: =+$A4*AZ4 -> 0 | BD4: 0 | BE4: =+$A4*BD4 -> 0 | BF4: 0 | BG4: =+$A4*BF4 -> 0 | BJ4: 0 | BK4: =+$A4*BJ4 -> 0 | BL4: 0 | BM4: =+$A4*BL4 -> 0 | BN4: 1 | BO4: =+$A4*BN4 -> 50000 | BP4: 0 | BQ4: =+$A4*BP4 -> 0 | BR4: 1 | BS4: =+$A4*BR4 -> 50000 | BT4: 0 | BU4: =+$A4*BT4 -> 0 | BV4: 0 | BX4: 1 | BY4: =+$A4*BX4 -> 50000 | BZ4: 0 | CA4: =+$A4*BZ4 -> 0 | CB4: 1 | CD4: 1 | CE4: =+$A4*CD4 -> 50000 | CF4: 0 | CH4: 0 | CI4: =+$A4*CH4 -> 0 | CJ4: 2 | CK4: =+$A4*CJ4 -> 100000 | CL4: 0 | CM4: =+$A4*CL4 -> 0 | CN4: 1 | CP4: 1 | CQ4: =+$A4*CP4 -> 50000 | CR4: 1 | CS4: =+A4*CR4 -> 50000
A5: 20000 | B5: 4 | C5: =+$A5*B5 -> 80000 | D5: 0 | F5: 0 | H5: 0 | J5: 0 | L5: 0 | N5: 0 | P5: 0 | R5: 0 | T5: 0 | V5: 0 | W5: =+$A5*V5 -> 0 | X5: 0 | Z5: 0 | AB5: 2 | AC5: =+$A5*AB5 -> 40000 | AD5: 6 | AE5: =+$A5*AD5 -> 120000 | AF5: 0 | AG5: =+$A5*AF5 -> 0 | AH5: 0 | AJ5: 0 | AL5: 4 | AM5: =+$A5*AL5 -> 80000 | AN5: 0 | AP5: 0 | AR5: 3 | AS5: =+$A5*AR5 -> 60000 | AT5: 0 | AU5: =+$A5*AT5 -> 0 | AV5: 0 | AW5: =+$A5*AV5 -> 0 | AX5: 0 | AY5: =+$A5*AX5 -> 0 | AZ5: 0 | BA5: =+$A5*AZ5 -> 0 | BD5: 0 | BE5: =+$A5*BD5 -> 0 | BF5: 2 | BG5: =+$A5*BF5 -> 40000 | BJ5: 0 | BK5: =+$A5*BJ5 -> 0 | BL5: 0 | BM5: =+$A5*BL5 -> 0 | BN5: 0 | BO5: =+$A5*BN5 -> 0 | BP5: 0 | BQ5: =+$A5*BP5 -> 0 | BR5: 1 | BS5: =+$A5*BR5 -> 20000 | BT5: 0 | BU5: =+$A5*BT5 -> 0 | BV5: 0 | BX5: 0 | BY5: =+$A5*BX5 -> 0 | BZ5: 0 | CA5: =+$A5*BZ5 -> 0 | CB5: 1 | CD5: 1 | CE5: =+$A5*CD5 -> 20000 | CF5: 0 | CH5: 0 | CI5: =+$A5*CH5 -> 0 | CK5: =+$A5*CJ5 -> 0 | CL5: 4 | CM5: =+$A5*CL5 -> 80000 | CN5: 5 | CP5: 5 | CQ5: =+$A5*CP5 -> 100000 | CR5: 4 | CS5: =+A5*CR5 -> 80000
A6: 10000 | B6: 4 | C6: =+$A6*B6 -> 40000 | D6: 0 | F6: 0 | H6: 0 | J6: 0 | L6: 0 | N6: 0 | P6: 0 | R6: 0 | T6: 0 | V6: 0 | W6: =+$A6*V6 -> 0 | X6: 0 | Z6: 0 | AB6: 5 | AC6: =+$A6*AB6 -> 50000 | AD6: 7 | AE6: =+$A6*AD6 -> 70000 | AF6: 0 | AG6: =+$A6*AF6 -> 0 | AH6: 0 | AJ6: 0 | AL6: 6 | AM6: =+$A6*AL6 -> 60000 | AN6: 0 | AP6: 0 | AR6: 0 | AS6: =+$A6*AR6 -> 0 | AT6: 0 | AU6: =+$A6*AT6 -> 0 | AV6: 1 | AW6: =+$A6*AV6 -> 10000 | AX6: 5 | AY6: =+$A6*AX6 -> 50000 | AZ6: 4 | BA6: =+$A6*AZ6 -> 40000 | BD6: 0 | BE6: =+$A6*BD6 -> 0 | BF6: 4 | BG6: =+$A6*BF6 -> 40000 | BJ6: 1 | BK6: =+$A6*BJ6 -> 10000 | BL6: 0 | BM6: =+$A6*BL6 -> 0 | BN6: 1 | BO6: =+$A6*BN6 -> 10000 | BP6: 2 | BQ6: =+$A6*BP6 -> 20000 | BR6: 1 | BS6: =+$A6*BR6 -> 10000 | BT6: 1 | BU6: =+$A6*BT6 -> 10000 | BV6: 0 | BX6: 2 | BY6: =+$A6*BX6 -> 20000 | BZ6: 4 | CA6: =+$A6*BZ6 -> 40000 | CB6: 4 | CD6: 4 | CE6: =+$A6*CD6 -> 40000 | CF6: 0 | CH6: 5 | CI6: =+$A6*CH6 -> 50000 | CJ6: 1 | CK6: =+$A6*CJ6 -> 10000 | CL6: 1 | CM6: =+$A6*CL6 -> 10000 | CN6: 2 | CP6: 2 | CQ6: =+$A6*CP6 -> 20000 | CR6: 2 | CS6: =+A6*CR6 -> 20000
A7: 5000 | B7: 5 | C7: =+$A7*B7 -> 25000 | D7: 0 | F7: 0 | H7: 0 | J7: 0 | L7: 0 | N7: 0 | P7: 0 | R7: 0 | T7: 0 | V7: 0 | W7: =+$A7*V7 -> 0 | X7: 0 | Z7: 0 | AB7: 6 | AC7: =+$A7*AB7 -> 30000 | AD7: 6 | AE7: =+$A7*AD7 -> 30000 | AF7: 0 | AG7: =+$A7*AF7 -> 0 | AH7: 0 | AJ7: 0 | AL7: 1 | AM7: =+$A7*AL7 -> 5000 | AN7: 0 | AP7: 0 | AR7: 3 | AS7: =+$A7*AR7 -> 15000 | AT7: 6 | AU7: =+$A7*AT7 -> 30000 | AV7: 8 | AW7: =+$A7*AV7 -> 40000 | AX7: 10 | AY7: =+$A7*AX7 -> 50000 | AZ7: 3 | BA7: =+$A7*AZ7 -> 15000 | BD7: 3 | BE7: =+$A7*BD7 -> 15000 | BF7: 8 | BG7: =+$A7*BF7 -> 40000 | BJ7: 3 | BK7: =+$A7*BJ7 -> 15000 | BL7: 5 | BM7: =+$A7*BL7 -> 25000 | BN7: 3 | BO7: =+$A7*BN7 -> 15000 | BP7: 3 | BQ7: =+$A7*BP7 -> 15000 | BR7: 0 | BS7: =+$A7*BR7 -> 0 | BT7: 0 | BU7: =+$A7*BT7 -> 0 | BV7: 0 | BX7: 4 | BY7: =+$A7*BX7 -> 20000 | BZ7: 3 | CA7: =+$A7*BZ7 -> 15000 | CB7: 3 | CD7: 3 | CE7: =+$A7*CD7 -> 15000 | CF7: 0 | CH7: 5 | CI7: =+$A7*CH7 -> 25000 | CJ7: 5 | CK7: =+$A7*CJ7 -> 25000 | CL7: 6 | CM7: =+$A7*CL7 -> 30000 | CN7: 4 | CP7: 4 | CQ7: =+$A7*CP7 -> 20000 | CR7: 2 | CS7: =+A7*CR7 -> 10000
A8: 2000 | B8: 21 | C8: =+$A8*B8 -> 42000 | D8: 0 | F8: 0 | H8: 0 | J8: 0 | L8: 0 | N8: 0 | P8: 0 | R8: 0 | T8: 0 | V8: 17 | W8: =+$A8*V8 -> 34000 | X8: 0 | Z8: 0 | AB8: 13 | AC8: =+$A8*AB8 -> 26000 | AD8: 13 | AE8: =+$A8*AD8 -> 26000 | AF8: 0 | AG8: =+$A8*AF8 -> 0 | AH8: 0 | AJ8: 0 | AL8: 18 | AM8: =+$A8*AL8 -> 36000 | AN8: 0 | AP8: 0 | AR8: 18 | AS8: =+$A8*AR8 -> 36000 | AT8: 21 | AU8: =+$A8*AT8 -> 42000 | AV8: 23 | AW8: =+$A8*AV8 -> 46000 | AX8: 15 | AY8: =+$A8*AX8 -> 30000 | AZ8: 3 | BA8: =+$A8*AZ8 -> 6000 | BD8: 18 | BE8: =+$A8*BD8 -> 36000 | BF8: 23 | BG8: =+$A8*BF8 -> 46000 | BJ8: 20 | BK8: =+$A8*BJ8 -> 40000 | BL8: 25 | BM8: =+$A8*BL8 -> 50000 | BN8: 25 | BO8: =+$A8*BN8 -> 50000 | BP8: 25 | BQ8: =+$A8*BP8 -> 50000 | BR8: 20 | BS8: =+$A8*BR8 -> 40000 | BT8: 23 | BU8: =+$A8*BT8 -> 46000 | BV8: 0 | BX8: 22 | BY8: =+$A8*BX8 -> 44000 | BZ8: 12 | CA8: =+$A8*BZ8 -> 24000 | CB8: 10 | CD8: 10 | CE8: =+$A8*CD8 -> 20000 | CF8: 0 | CH8: 14 | CI8: =+$A8*CH8 -> 28000 | CJ8: 17 | CK8: =+$A8*CJ8 -> 34000 | CL8: 12 | CM8: =+$A8*CL8 -> 24000 | CN8: 5 | CP8: 5 | CQ8: =+$A8*CP8 -> 10000 | CR8: 4 | CS8: =+A8*CR8 -> 8000
A9: 1000 | B9: 2 | C9: =+$A9*B9 -> 2000 | D9: 0 | F9: 0 | H9: 0 | J9: 0 | L9: 0 | N9: 0 | P9: 0 | R9: 0 | T9: 0 | V9: 11 | W9: =+$A9*V9 -> 11000 | X9: 0 | Z9: 0 | AB9: 10 | AC9: =+$A9*AB9 -> 10000 | AD9: 10 | AE9: =+$A9*AD9 -> 10000 | AF9: 0 | AG9: =+$A9*AF9 -> 0 | AH9: 0 | AJ9: 0 | AL9: 6 | AM9: =+$A9*AL9 -> 6000 | AN9: 0 | AP9: 0 | AR9: 6 | AS9: =+$A9*AR9 -> 6000 | AT9: 7 | AU9: =+$A9*AT9 -> 7000 | AV9: 7 | AW9: =+$A9*AV9 -> 7000 | AX9: 14 | AY9: =+$A9*AX9 -> 14000 | AZ9: 3 | BA9: =+$A9*AZ9 -> 3000 | BD9: 9 | BE9: =+$A9*BD9 -> 9000 | BF9: 11 | BG9: =+$A9*BF9 -> 11000 | BJ9: 6 | BK9: =+$A9*BJ9 -> 6000 | BL9: 10 | BM9: =+$A9*BL9 -> 10000 | BN9: 11 | BO9: =+$A9*BN9 -> 11000 | BP9: 6 | BQ9: =+$A9*BP9 -> 6000 | BR9: 9 | BS9: =+$A9*BR9 -> 9000 | BT9: 12 | BU9: =+$A9*BT9 -> 12000 | BV9: 0 | BX9: 16 | BY9: =+$A9*BX9 -> 16000 | BZ9: 20 | CA9: =+$A9*BZ9 -> 20000 | CB9: 0 | CD9: 0 | CE9: =+$A9*CD9 -> 0 | CF9: 0 | CH9: 0 | CI9: =+$A9*CH9 -> 0 | CJ9: 2 | CK9: =+$A9*CJ9 -> 2000 | CL9: 3 | CM9: =+$A9*CL9 -> 3000 | CN9: 8 | CP9: 8 | CQ9: =+$A9*CP9 -> 8000 | CR9: 7 | CS9: =+A9*CR9 -> 7000
A10: 500 | B10: 51 | C10: =+$A10*B10 -> 25500 | D10: 0 | F10: 0 | H10: 0 | J10: 0 | L10: 0 | N10: 0 | P10: 0 | R10: 0 | T10: 0 | V10: 49 | W10: =+$A10*V10 -> 24500 | X10: 0 | Z10: 0 | AB10: 49 | AC10: =+$A10*AB10 -> 24500 | AD10: 49 | AE10: =+$A10*AD10 -> 24500 | AF10: 0 | AG10: =+$A10*AF10 -> 0 | AH10: 0 | AJ10: 0 | AL10: 49 | AM10: =+$A10*AL10 -> 24500 | AN10: 0 | AP10: 0 | AR10: 48 | AS10: =+$A10*AR10 -> 24000 | AT10: 49 | AU10: =+$A10*AT10 -> 24500 | AV10: 49 | AW10: =+$A10*AV10 -> 24500 | AX10: 50 | AY10: =+$A10*AX10 -> 25000 | AZ10: 46 | BA10: =+$A10*AZ10 -> 23000 | BD10: 44 | BE10: =+$A10*BD10 -> 22000 | BF10: 42 | BG10: =+$A10*BF10 -> 21000 | BJ10: 20 | BK10: =+$A10*BJ10 -> 10000 | BL10: 35 | BM10: =+$A10*BL10 -> 17500 | BN10: 21 | BO10: =+$A10*BN10 -> 10500 | BP10: 21 | BQ10: =+$A10*BP10 -> 10500 | BR10: 20 | BS10: =+$A10*BR10 -> 10000 | BT10: 31 | BU10: =+$A10*BT10 -> 15500 | BV10: 0 | BX10: 45 | BY10: =+$A10*BX10 -> 22500 | BZ10: 40 | CA10: =+$A10*BZ10 -> 20000 | CB10: 36 | CD10: 36 | CE10: =+$A10*CD10 -> 18000 | CF10: 0 | CH10: 36 | CI10: =+$A10*CH10 -> 18000 | CJ10: 37 | CK10: =+$A10*CJ10 -> 18500 | CL10: 38 | CM10: =+$A10*CL10 -> 19000 | CN10: 32 | CP10: 32 | CQ10: =+$A10*CP10 -> 16000 | CR10: 31 | CS10: =+A10*CR10 -> 15500
A11: 200 | B11: 21 | C11: =+$A11*B11 -> 4200 | D11: 0 | F11: 0 | H11: 0 | J11: 0 | L11: 0 | N11: 0 | P11: 0 | R11: 0 | T11: 0 | V11: 14 | W11: =+$A11*V11 -> 2800 | X11: 0 | Z11: 0 | AB11: 14 | AC11: =+$A11*AB11 -> 2800 | AD11: 14 | AE11: =+$A11*AD11 -> 2800 | AF11: 0 | AG11: =+$A11*AF11 -> 0 | AH11: 0 | AJ11: 0 | AL11: 9 | AM11: =+$A11*AL11 -> 1800 | AN11: 0 | AP11: 0 | AR11: 9 | AS11: =+$A11*AR11 -> 1800 | AT11: 14 | AU11: =+$A11*AT11 -> 2800 | AV11: 10 | AW11: =+$A11*AV11 -> 2000 | AX11: 10 | AY11: =+$A11*AX11 -> 2000 | AZ11: 25 | BA11: =+$A11*AZ11 -> 5000 | BD11: 13 | BE11: =+$A11*BD11 -> 2600 | BF11: 10 | BG11: =+$A11*BF11 -> 2000 | BJ11: 6 | BK11: =+$A11*BJ11 -> 1200 | BL11: 9 | BM11: =+$A11*BL11 -> 1800 | BN11: 13 | BO11: =+$A11*BN11 -> 2600 | BP11: 7 | BQ11: =+$A11*BP11 -> 1400 | BR11: 4 | BS11: =+$A11*BR11 -> 800 | BT11: 4 | BU11: =+$A11*BT11 -> 800 | BV11: 0 | BX11: 5 | BY11: =+$A11*BX11 -> 1000 | BZ11: 3 | CA11: =+$A11*BZ11 -> 600 | CB11: 81 | CD11: 81 | CE11: =+$A11*CD11 -> 16200 | CF11: 0 | CH11: 68 | CI11: =+$A11*CH11 -> 13600 | CJ11: 62 | CK11: =+$A11*CJ11 -> 12400 | CL11: 62 | CM11: =+$A11*CL11 -> 12400 | CN11: 56 | CP11: 56 | CQ11: =+$A11*CP11 -> 11200 | CR11: 54 | CS11: =+A11*CR11 -> 10800
A12: 100 | B12: 18 | C12: =+$A12*B12 -> 1800 | D12: 0 | F12: 0 | H12: 0 | J12: 0 | L12: 0 | N12: 0 | P12: 0 | R12: 0 | T12: 0 | V12: 20 | W12: =+$A12*V12 -> 2000 | X12: 0 | Z12: 0 | AB12: 15 | AC12: =+$A12*AB12 -> 1500 | AD12: 15 | AE12: =+$A12*AD12 -> 1500 | AF12: 0 | AG12: =+$A12*AF12 -> 0 | AH12: 0 | AJ12: 0 | AL12: 13 | AM12: =+$A12*AL12 -> 1300 | AN12: 0 | AP12: 0 | AR12: 13 | AS12: =+$A12*AR12 -> 1300 | AT12: 13 | AU12: =+$A12*AT12 -> 1300 | AV12: 11 | AW12: =+$A12*AV12 -> 1100 | AX12: 12 | AY12: =+$A12*AX12 -> 1200 | AZ12: 30 | BA12: =+$A12*AZ12 -> 3000 | BD12: 29 | BE12: =+$A12*BD12 -> 2900 | BF12: 29 | BG12: =+$A12*BF12 -> 2900 | BJ12: 17 | BK12: =+$A12*BJ12 -> 1700 | BL12: 15 | BM12: =+$A12*BL12 -> 1500 | BN12: 15 | BO12: =+$A12*BN12 -> 1500 | BP12: 14 | BQ12: =+$A12*BP12 -> 1400 | BR12: 13 | BS12: =+$A12*BR12 -> 1300 | BT12: 13 | BU12: =+$A12*BT12 -> 1300 | BV12: 0 | BX12: 11 | BY12: =+$A12*BX12 -> 1100 | BZ12: 9 | CA12: =+$A12*BZ12 -> 900 | CB12: 77 | CD12: 77 | CE12: =+$A12*CD12 -> 7700 | CF12: 0 | CH12: 63 | CI12: =+$A12*CH12 -> 6300 | CJ12: 48 | CK12: =+$A12*CJ12 -> 4800 | CL12: 51 | CM12: =+$A12*CL12 -> 5100 | CN12: 39 | CP12: 39 | CQ12: =+$A12*CP12 -> 3900 | CR12: 38 | CS12: =+A12*CR12 -> 3800
A13: 50 | B13: 1 | C13: =+$A13*B13 -> 50 | D13: 0 | F13: 0 | H13: 0 | J13: 0 | L13: 0 | N13: 0 | P13: 0 | R13: 0 | T13: 0 | V13: 29 | W13: =+$A13*V13 -> 1450 | X13: 0 | Z13: 0 | AB13: 29 | AC13: =+$A13*AB13 -> 1450 | AD13: 29 | AE13: =+$A13*AD13 -> 1450 | AF13: 0 | AG13: =+$A13*AF13 -> 0 | AH13: 0 | AJ13: 0 | AL13: 12 | AM13: =+$A13*AL13 -> 600 | AN13: 0 | AP13: 0 | AR13: 12 | AS13: =+$A13*AR13 -> 600 | AT13: 12 | AU13: =+$A13*AT13 -> 600 | AV13: 12 | AW13: =+$A13*AV13 -> 600 | AX13: 11 | AY13: =+$A13*AX13 -> 550 | AZ13: 10 | BA13: =+$A13*AZ13 -> 500 | BD13: 10 | BE13: =+$A13*BD13 -> 500 | BF13: 9 | BG13: =+$A13*BF13 -> 450 | BJ13: 7 | BK13: =+$A13*BJ13 -> 350 | BL13: 8 | BM13: =+$A13*BL13 -> 400 | BN13: 8 | BO13: =+$A13*BN13 -> 400 | BP13: 9 | BQ13: =+$A13*BP13 -> 450 | BR13: 11 | BS13: =+$A13*BR13 -> 550 | BT13: 8 | BU13: =+$A13*BT13 -> 400 | BV13: 0 | BX13: 9 | BY13: =+$A13*BX13 -> 450 | BZ13: 9 | CA13: =+$A13*BZ13 -> 450 | CB13: 14 | CD13: 14 | CE13: =+$A13*CD13 -> 700 | CF13: 0 | CH13: 10 | CI13: =+$A13*CH13 -> 500 | CJ13: 10 | CK13: =+$A13*CJ13 -> 500 | CL13: 10 | CM13: =+$A13*CL13 -> 500 | CN13: 10 | CP13: 10 | CQ13: =+$A13*CP13 -> 500 | CR13: 10 | CS13: =+A13*CR13 -> 500
C14: =+SUM(C3:C13) -> 370550 | E14: =+E23 -> 122750 | G14: =+G23 -> -6250 | I14: =+I23 -> 349000 | K14: =+K23 -> 259750 | M14: =+M23 -> 75750 | O14: =+O23 -> 75750 | Q14: =+Q23 -> 75750 | S14: =+S23 -> 75750 | U14: =+U23 -> 75750 | W14: =SUM(W3:W13) -> 75750 | Y14: =+Y23 -> 72250 | AA14: =+AA23 -> 196250 | AC14: =SUM(AC3:AC13) -> 186250 | AE14: =SUM(AE3:AE13) -> 436250 | AG14: =+AG23 -> 314850 | AI14: =+AI23 -> 334850 | AK14: =+AK23 -> 250850 | AM14: =SUM(AM3:AM13) -> 215200 | AO14: =+AO23 -> 144700 | AQ14: =+AQ23 -> 144700 | AS14: =SUM(AS3:AS13) -> 144700 | AU14: =SUM(AU3:AU13) -> 108200 | AW14: =SUM(AW3:AW13) -> 331200 | AY14: =SUM(AY3:AY13) -> 172750 | BA14: =SUM(BA3:BA13) -> 95500 | BC14: =+BC23 -> 172000 | BE14: =SUM(BE3:BE13) -> 88000 | BG14: =SUM(BG3:BG13) -> 203350 | BI14: =+BI23 -> 230450 | BK14: =SUM(BK3:BK13) -> 84250 | BM14: =SUM(BM3:BM13) -> 106200 | BO14: =SUM(BO3:BO13) -> 151000 | BQ14: =+BQ23 -> 100000 | BS14: =SUM(BS3:BS13) -> 141650 | BU14: =SUM(BU3:BU13) -> 86000 | BW14: 0 | BY14: =SUM(BY3:BY13) -> 175050 | CA14: =SUM(CA3:CA13) -> 120950 | CC14: =+CC23 -> 247700 | CE14: =SUM(CE3:CE13) -> 187600 | CG14: 0 | CI14: =SUM(CI3:CI13) -> 141400 | CK14: =+CK23 -> 43100 | CM14: =100000+(315000-10000) -> 405000 | CO14: =+CO23 -> 412900 | CQ14: =+SUM(CQ3:CQ13)+SUM('historial de venta'!G32:G37) -> 315600 | CS14: =+SUM(CS3:CS13) -> 205600
AQ15: =+AS14-AM18 -> 0 | BQ15: 62700 | CA15: 324300
AS16: =+AS18+AQ15 -> 108200 | BA16: =+BA18-BC23 -> 0 | BQ16: =18000+8000+8000 -> 34000
A17: Consepto | C17: =+C1 -> sáb | E17: =+E1 -> vie | G17: =+G1 -> jue | I17: =+I1 -> mié | K17: =+K1 -> mar | M17: =+M1 -> lun | O17: =+O1 -> dom | Q17: =+Q1 -> sáb | S17: =+S1 -> vie | U17: =+U1 -> jue | W17: =+W1 -> mié | Y17: =+Y1 -> mar | AA17: =+AA1 -> lun | AC17: =+AC1 -> dom | AE17: =+AE1 -> sáb | AG17: =+AG1 -> vie | AI17: =+AI1 -> jue | AK17: =+AK1 -> mié | AM17: =+AM1 -> mar | AO17: =+AO1 -> lun | AQ17: =+AQ1 -> dom | AS17: =+AS1 -> sáb | AU17: =+AR1 -> 0 | AW17: =+AW1 -> jue | AY17: =+AY1 -> mié | BA17: =+BA1 -> mar | BC17: =+BC1 -> lun | BE17: =+BE1 -> dom | BG17: =+BG1 -> sáb | BI17: =+BI1 -> vie | BK17: =+BK1 -> jue | BM17: =+BM1 -> mié | BO17: =+BO1 -> mar | BQ17: =+BQ1 -> lun | BS17: =+BS1 -> dom | BU17: =+BU1 -> sáb | BW17: =+BW1 -> vie | BY17: =+BY1 -> jue | CA17: =+CA1 -> mié | CC17: =+CC1 -> mar | CE17: =+CE1 -> lun | CG17: =+CG1 -> dom | CI17: sábado | CK17: viernes | CM17: jueves | CO17: miercoles | CQ17: martes | CS17: lunes
A18: Base | C18: =+E23 -> 122750 | E18: =+G23 -> -6250 | G18: =+I23 -> 349000 | I18: =+K23 -> 259750 | K18: =+M23 -> 75750 | M18: =+O23 -> 75750 | O18: =+Q23 -> 75750 | Q18: =+S23 -> 75750 | S18: =+U23 -> 75750 | U18: =+W23 -> 75750 | W18: =+Y23 -> 72250 | Y18: =+AA23 -> 196250 | AA18: =+AC23 -> 186250 | AC18: =+AE23 -> 436250 | AE18: =+AG23 -> 314850 | AG18: =+AI23 -> 334850 | AI18: =+AK23 -> 250850 | AK18: =+AM23 -> 215200 | AM18: =+AO23 -> 144700 | AO18: =+AQ18 -> 144700 | AQ18: =+AS23 -> 144700 | AS18: =+AU23 -> 108200 | AU18: =+AW23 -> 331200 | AW18: =+AY23 -> 172750 | AY18: =+BA23 -> 95500 | BA18: =+BC23 -> 172000 | BC18: =+BE23 -> 88000 | BE18: =+BG23 -> 149950 | BG18: =+BI23 -> 230450 | BI18: =+BK23 -> 97950 | BK18: =+BM23 -> 88400 | BM18: =+BO23 -> 151000 | BO18: =+BQ23 -> 100000 | BQ18: =+BS23 -> 110200 | BS18: =+BU23 -> 143550 | BU18: =+BY23 -> 131350 | BW18: 0 | BY18: =+CA23 -> 73250 | CA18: =+CC23 -> 247700 | CC18: =+CE23 -> 201400 | CE18: =+CI23 -> 141400 | CG18: 0 | CI18: =+CK23 -> 43100 | CK18: =+CM23 -> 405000 | CM18: =+CO23 -> 412900 | CO18: =+CQ23 -> 315600 | CQ18: =$CS$23 -> 205600 | CS18: 73700
A19: Caja Menor | C19: 0 | E19: 0 | G19: 0 | I19: 40250 | K19: 0 | M19: 0 | O19: 0 | Q19: 0 | S19: 0 | U19: 0 | W19: 0 | Y19: 0 | AA19: 0 | AC19: 0 | AE19: -2600 | AG19: 0 | AI19: 0 | AK19: 0 | AM19: =1800 -> 1800 | AO19: 0 | AU19: 0 | AW19: 0 | AY19: 0 | BA19: -3000 | BC19: 0 | BE19: =+SUM(BM25,BK25,BG25)+2900 -> 60400 | BI19: 0 | BK19: 0 | BM19: 0 | BO19: 0 | BQ19: =-SUM(CE25,CA25,BY25,BU25,BS25)-1200 -> -52700 | BW19: 0 | BY19: 0 | CC19: 0 | CE19: 0 | CG19: 0 | CI19: 88200 | CK19: -7900 | CM19: -7900 | CO19: 0 | CQ19: -3000 | CS19: 0
A20: Venta | C20: 282000 | E20: 153000 | G20: 68000 | I20: 134000 | K20: 247000 | M20: 0 | O20: 0 | Q20: 0 | S20: 0 | U20: 0 | W20: 3500 | Y20: 76000 | AA20: 30000 | AC20: 0 | AE20: 139000 | AG20: 0 | AI20: 104000 | AK20: 58500 | AM20: =130700+8000 -> 138700 | AO20: 0 | AS20: 126500 | AU20: 107000 | AW20: 207700 | AY20: 77250 | BA20: 176500 | BC20: 99000 | BE20: 99000 | BG20: 271000 | BI20: =Registros!$C$13 -> 132500 | BK20: =67000+24000 -> 91000 | BM20: 338500 | BO20: 51000 | BQ20: 172500 | BS20: 123500 | BU20: 225500 | BW20: 0 | BY20: 143500 | CA20: =260000-18000-8000 -> 234000 | CC20: 105000 | CE20: 60000 | CG20: 0 | CI20: 456500 | CK20: 186000 | CM20: 84000 | CO20: 344000 | CQ20: 213000 | CS20: 191900
A21: Gastos | C21: 14400 | E21: =16000+8000 -> 24000 | G21: 0 | I21: 0 | K21: 63000 | M21: 0 | O21: 0 | Q21: 0 | S21: 0 | U21: 0 | W21: 0 | Y21: 0 | AA21: 20000 | AC21: 0 | AE21: 15000 | AG21: 20000 | AI21: 20000 | AK21: 22850 | AM21: 70000 | AO21: 0 | AS21: =70000+20000 -> 90000 | AU21: =30000+70000 -> 100000 | AW21: =13500+7800+27950 -> 49250 | BC21: 15000 | BE21: =Gas!$C$15 -> 221350 | BG21: =30000+120000+50000+51500 -> 251500 | BK21: =4500+21600 -> 26100 | BM21: =140000+1000+20500+55800+43800+40000 -> 301100 | BO21: 0 | BQ21: 30000 | BS21: =10000+20000+26850 -> 56850 | BU21: 213300 | BW21: 0 | BY21: =38050+17000+7450+22400+500 -> 85400 | CA21: =20000+124400+3500+11000+16500+46350+50000+14000 -> 285750 | CC21: =30000+28700 -> 58700 | CE21: 0 | CG21: 0 | CI21: =20000+70000+6400 -> 96400 | CK21: =10000+70000+20000+20000+(120000) -> 240000 | CM21: =$CM$20 -> 84000 | CO21: =70000+36700+120000+20000 -> 246700 | CQ21: 100000 | CS21: =60000 -> 60000
A22: Retiros | C22: 0 | E22: 0 | G22: 423250 | I22: =65000+20000 -> 85000 | K22: 0 | M22: 0 | O22: 0 | Q22: 0 | S22: 0 | U22: 0 | W22: 0 | Y22: 200000 | AA22: 0 | AC22: 250000 | AE22: 0 | AG22: 0 | AI22: 0 | AK22: 0 | AM22: 0 | AO22: 0 | AQ22: 0 | AS22: 0 | AU22: 230000 | AW22: 0 | AY22: 0 | BA22: 250000 | BG22: 100000 | BK22: =4000+51350 -> 55350 | BM22: 100000 | BO22: 0 | BQ22: 100000 | BS22: 100000 | BW22: 0 | CA22: 122700 | CC22: 0 | CE22: 0 | CG22: 0 | CI22: =350000 -> 350000 | CK22: 300000
C23: =+SUM(C18:C20)-SUM(C21:C22) -> 390350 | E23: =+SUM(E18:E20)-SUM(E21:E22) -> 122750 | G23: =+SUM(G18:G20)-SUM(G21:G22) -> -6250 | I23: =+SUM(I18:I20)-SUM(I21:I22) -> 349000 | K23: =+SUM(K18:K20)-SUM(K21:K22) -> 259750 | M23: =+SUM(M18:M20)-SUM(M21:M22) -> 75750 | O23: =+SUM(O18:O20)-SUM(O21:O22) -> 75750 | Q23: =+SUM(Q18:Q20)-SUM(Q21:Q22) -> 75750 | S23: =+SUM(S18:S20)-SUM(S21:S22) -> 75750 | U23: =+SUM(U18:U20)-SUM(U21:U22) -> 75750 | W23: =+SUM(W18:W20)-SUM(W21:W22) -> 75750 | Y23: =+SUM(Y18:Y20)-SUM(Y21:Y22) -> 72250 | AA23: =+SUM(AA18:AA20)-SUM(AA21:AA22) -> 196250 | AC23: =+SUM(AC18:AC20)-SUM(AC21:AC22) -> 186250 | AE23: =+SUM(AE18:AE20)-SUM(AE21:AE22) -> 436250 | AG23: =+SUM(AG18:AG20)-SUM(AG21:AG22) -> 314850 | AI23: =+SUM(AI18:AI20)-SUM(AI21:AI22) -> 334850 | AK23: =+SUM(AK18:AK20)-SUM(AK21:AK22) -> 250850 | AM23: =+SUM(AM18:AM20)-SUM(AM21:AM22) -> 215200 | AO23: =+SUM(AO18:AO20)-SUM(AO21:AO22) -> 144700 | AQ23: =+SUM(AQ18:AQ20)-SUM(AQ21:AQ22) -> 144700 | AS23: =+SUM(AS18:AS20)-SUM(AS21:AS22) -> 144700 | AU23: =+SUM(AU18:AU20)-SUM(AU21:AU22) -> 108200 | AW23: =+SUM(AW18:AW20)-SUM(AW21:AW22) -> 331200 | AY23: =+SUM(AY18:AY20)-SUM(AY21:AY22) -> 172750 | BA23: =+SUM(BA18:BA20)-SUM(BA21:BA22) -> 95500 | BC23: =+SUM(BC18:BC20)-SUM(BC21:BC22) -> 172000 | BE23: =+SUM(BE18:BE20)-SUM(BE21:BE22) -> 88000 | BG23: =+SUM(BG18:BG20)-SUM(BG21:BG22) -> 149950 | BI23: =+SUM(BI18:BI20)-SUM(BI21:BI22) -> 230450 | BK23: =+SUM(BK18:BK20)-SUM(BK21:BK22) -> 97950 | BM23: =+SUM(BM18:BM20)-SUM(BM21:BM22) -> 88400 | BO23: =+SUM(BO18:BO20)-SUM(BO21:BO22) -> 151000 | BQ23: =+SUM(BQ18:BQ20)-SUM(BQ21:BQ22) -> 100000 | BS23: =+SUM(BS18:BS20)-SUM(BS21:BS22) -> 110200 | BU23: =+SUM(BU18:BU20)-BU21 -> 143550 | BW23: 0 | BY23: =+SUM(BY18:BY20)-BY21 -> 131350 | CA23: =+SUM(CA18:CA20)-SUM(CA21:CA22) -> 73250 | CC23: =+SUM(CC18:CC20)-SUM(CC21:CC22) -> 247700 | CE23: =+SUM(CE18:CE20)-SUM(CE21:CE22) -> 201400 | CG23: 0 | CI23: =+SUM(CI18:CI20)-SUM(CI21:CI22) -> 141400 | CK23: =+SUM(CK18:CK20)-SUM(CK21:CK22) -> 43100 | CM23: =+SUM(CM18:CM20)-CM21 -> 405000 | CO23: =+CO18+CO20-CO21 -> 412900 | CQ23: =+SUM(CQ18:CQ20)-SUM(CQ21:CQ22) -> 315600 | CS23: =+CS18+CS20-CS21 -> 205600
A25: Diferencia | C25: =C14-C23 -> -19800 | E25: =E14-E23 -> 0 | G25: =G14-G23 -> 0 | I25: =I14-I23 -> 0 | K25: =K14-K23 -> 0 | M25: =M14-M23 -> 0 | O25: =O14-O23 -> 0 | Q25: =Q14-Q23 -> 0 | S25: =S14-S23 -> 0 | U25: =U14-U23 -> 0 | W25: =W14-W23 -> 0 | Y25: =Y14-Y23 -> 0 | AA25: =AA14-AA23 -> 0 | AC25: =AC14-AC23 -> 0 | AE25: =AE14-AE23 -> 0 | AG25: =AG14-AG23 -> 0 | AI25: =AI14-AI23 -> 0 | AK25: =AK14-AK23 -> 0 | AM25: =AM14-AM23 -> 0 | AO25: =AO14-AO23 -> 0 | AQ25: =AQ14-AQ23 -> 0 | AS25: =AS14-AS23 -> 0 | AU25: =AU14-AU23 -> 0 | AW25: =AW14-AW23 -> 0 | AY25: =AY14-AY23 -> 0 | BA25: =BA14-BA23 -> 0 | BC25: =BC14-BC23 -> 0 | BE25: =BE14-BE23 -> 0 | BG25: =BG14-BG23 -> 53400 | BI25: =BI14-BI23 -> 0 | BK25: =BK14-BK23 -> -13700 | BM25: =BM14-BM23 -> 17800 | BO25: =BO14-BO23 -> 0 | BQ25: =BQ14-BQ23 -> 0 | BS25: =BS14-BS23 -> 31450 | BU25: =BU14-BU23 -> -57550 | BW25: =BW14-BW23 -> 0 | BY25: =BY14-BY23 -> 43700 | CA25: =CA14-CA23 -> 47700 | CC25: =CC14-CC23 -> 0 | CE25: =CE14-CE23 -> -13800 | CG25: =CG14-CG23 -> 0 | CI25: =CI14-CI23 -> 0 | CK25: =CK14-CK23 -> 0 | CM25: =CM14-CM23 -> 0 | CO25: =CO14-CO23 -> 0 | CQ25: =CQ14-CQ23 -> 0 | CS25: =CS14-CS23 -> 0
A27: Caja Menor EA | C27: 0 | E27: 0 | G27: 0 | I27: 0 | K27: 0 | M27: 0 | O27: 0 | Q27: 0 | S27: 0 | U27: 0 | W27: 0 | Y27: 0 | AA27: 0 | AC27: 0 | AE27: 0 | AG27: 0 | AI27: 0 | AK27: 0 | AM27: 0 | AO27: 0 | AQ27: 0 | AS27: 0 | AU27: 0 | AW27: 0 | AY27: 0 | BA27: =+BC27+BA22 -> 344950 | BC27: =+BE27 -> 94950 | BE27: =+BG27-50000 -> 94950 | BG27: =+BI27+BG22 -> 144950 | BI27: =+BK27 -> 44950 | BK27: =+BM27-43000 -> 44950 | BM27: =100000-12050 -> 87950 | BO27: =100000-12050 -> 87950 | BQ27: =+BQ22 -> 100000 | BS27: 0 | BU27: 0 | BW27: 0 | BY27: 0 | CA27: 0 | CC27: 0 | CE27: 0 | CG27: 0 | CI27: 0 | CK27: 0 | CM27: 0 | CO27: 0 | CQ27: 0 | CS27: 0
A28: Caja Menor JG | C28: 0 | E28: 0 | G28: 0 | I28: 0 | K28: 0 | M28: 0 | O28: 0 | Q28: 0 | S28: 0 | U28: 0 | W28: 0 | Y28: 0 | AA28: 0 | AC28: 0 | AE28: 0 | AG28: 0 | AI28: 0 | AK28: 0 | AM28: 0 | AO28: 0 | AQ28: 0 | AS28: 0 | AU28: =+AW28 -> 0 | AW28: =+AY28 -> 0 | AY28: =+BA28 -> 0 | BA28: =+BC28 -> 0 | BC28: =+BE28 -> 0 | BE28: =+BG28 -> 0 | BG28: =+BI28 -> 0 | BI28: =+BK28 -> 0 | BK28: =+BM28-100000 -> 0 | BM28: =+BM22 -> 100000 | BO28: 0 | BQ28: 0 | BS28: 0 | BU28: =+BU22+BW28-BU31 -> 0 | BW28: =+BW22+BY28-BW31 -> 0 | BY28: 0 | CA28: =+CC28-370000 -> 0 | CC28: =+CC22+CE28 -> 370000 | CE28: =+CE22+CG28 -> 370000 | CG28: =+CG22+CI28 -> 370000 | CI28: =+CI22+CK28-CI31 -> 370000 | CK28: =+CK22 -> 300000 | CM28: 0 | CO28: 0 | CQ28: 0 | CS28: 0
A30: NEQUI - venta | C30: 19000 | E30: 104000 | G30: 8000 | I30: 27000 | K30: 19000 | M30: 0 | O30: 0 | Q30: 0 | S30: 0 | U30: 0 | W30: =4500*20 -> 90000 | Y30: 0 | AA30: 85500 | AC30: 211000 | AE30: 86000 | AG30: 0 | AI30: 24000 | AK30: 48000 | AM30: 127000 | AO30: 0 | AQ30: 0 | AS30: 11000 | AU30: 65700 | AW30: 169800 | AY30: =71000 -> 71000 | BA30: =78000+32000 -> 110000 | BC30: =11000+10000 -> 21000 | BE30: =19000+(45000-9000) -> 55000 | BG30: =+(98000-5000) -> 93000 | BI30: 0 | BK30: 70000 | BM30: 113000 | BO30: =43000-2000 -> 41000 | BQ30: 0 | BS30: =92000+16000+30000 -> 138000 | BU30: =43000+28000 -> 71000 | BW30: 0 | BY30: =115500+16000 -> 131500 | CA30: =83000+18000+8000+8000 -> 117000 | CC30: =33000+27000+20000 -> 80000 | CE30: 0 | CG30: 0 | CI30: 47000 | CK30: 45000 | CM30: 125000 | CO30: 46500 | CQ30: =8000+3000 -> 11000 | CS30: =24000+6500 -> 30500
A31: NEQUI - transfer/egreso | C31: 0 | E31: 0 | G31: 0 | I31: 0 | K31: 0 | M31: 0 | O31: 0 | Q31: 0 | S31: 0 | U31: -60000 | W31: =-350000 -> -350000 | Y31: 0 | AA31: 0 | AC31: =-363853+AC22 -> -113853 | AE31: 0 | AG31: 0 | AI31: 0 | AK31: =-114000-40000 -> -154000 | AM31: 0 | AO31: 0 | AQ31: 0 | AS31: 0 | AU31: =AU22-21000 -> 209000 | AW31: =-404000-50000 -> -454000 | AY31: =+BA27-260500 -> 84450 | BA31: =-60000 -> -60000 | BM31: 0 | BO31: =-BO34-412000 -> -322000 | BQ31: 0 | BS31: 0 | BU31: 0 | BW31: 0 | BY31: 0 | CA31: 0 | CC31: -619850 | CE31: 0 | CG31: 0 | CI31: 280000 | CK31: 0 | CM31: 0 | CO31: 0 | CQ31: 0 | CS31: 0
A32: NEQUI Acum. | C32: =+E32+SUM(C30:C31) -> 951247 | E32: =+G32+SUM(E30:E31) -> 932247 | G32: =+I32+SUM(G30:G31) -> 828247 | I32: =+K32+SUM(I30:I31) -> 820247 | K32: =+M32+SUM(K30:K31) -> 793247 | M32: =+O32+SUM(M30:M31) -> 774247 | O32: =+Q32+SUM(O30:O31) -> 774247 | Q32: =+S32+SUM(Q30:Q31) -> 774247 | S32: =+U32+SUM(S30:S31) -> 774247 | U32: =+W32+SUM(U30:U31) -> 774247 | W32: =+Y32+SUM(W30:W31) -> 834247 | Y32: =+AA32+SUM(Y30:Y31) -> 1094247 | AA32: =+AC32+SUM(AA30:AA31) -> 1094247 | AC32: =+AE32+SUM(AC30:AC31) -> 1008747 | AE32: =+AG32+SUM(AE30:AE31) -> 911600 | AG32: =+AI32+SUM(AG30:AG31) -> 825600 | AI32: =+AK32+SUM(AI30:AI31) -> 825600 | AK32: =+AM32+SUM(AK30:AK31) -> 801600 | AM32: =+AO32+SUM(AM30:AM31) -> 907600 | AO32: =+AS32+SUM(AO30:AO31) -> 780600 | AQ32: =+AS32+SUM(AQ30:AQ31) -> 780600 | AS32: =+AU32+SUM(AS30:AS31) -> 780600 | AU32: =+AW32+SUM(AU30:AU31) -> 769600 | AW32: =+AY32+SUM(AW30:AW31) -> 494900 | AY32: =+BA32+SUM(AY30:AY31) -> 779100 | BA32: =+BC32+SUM(BA30:BA31) -> 623650 | BC32: =+BE32+SUM(BC30:BC31) -> 573650 | BE32: =+BG32+SUM(BE30:BE31) -> 552650 | BG32: =+BI32+SUM(BG30:BG31) -> 497650 | BI32: =+BK32+SUM(BI30:BI31) -> 404650 | BK32: =+BM32+SUM(BK30:BK31) -> 404650 | BM32: =+BO32+SUM(BM30:BM31) -> 334650 | BO32: =+BQ32+SUM(BO30:BO31) -> 221650 | BQ32: =+BS32+SUM(BQ30:BQ31) -> 502650 | BS32: =+BU32+SUM(BS30:BS31) -> 502650 | BU32: =+BW32+SUM(BU30:BU31) -> 364650 | BW32: =+BY32+SUM(BW30:BW31) -> 293650 | BY32: =+CA32+SUM(BY30:BY31) -> 293650 | CA32: =+CC32+SUM(CA30:CA31) -> 162150 | CC32: =+CE32+SUM(CC30:CC31) -> 45150 | CE32: =+CG32+SUM(CE30:CE31) -> 585000 | CG32: =+CI32+SUM(CG30:CG31) -> 585000 | CI32: =+CK32+SUM(CI30:CI31) -> 585000 | CK32: =+CM32+SUM(CK30:CK31) -> 258000 | CM32: =+CO32+SUM(CM30:CM31) -> 213000 | CO32: =+CQ32+SUM(CO30:CO31) -> 88000 | CQ32: =+CS32+SUM(CQ30:CQ31) -> 41500 | CS32: =SUM(CS30:CS31) -> 30500
A33: DaviPLATA | C33: 0 | E33: 0 | G33: 11000 | I33: 0 | K33: 0 | M33: 0 | O33: 0 | Q33: 0 | S33: 0 | U33: 0 | W33: 0 | Y33: 0 | AA33: 0 | AC33: 0 | AE33: 0 | AG33: 0 | AI33: 0 | AK33: 11000 | AM33: 27000 | AO33: 0 | AQ33: 0 | AS33: 0 | AU33: 0 | AW33: 11000 | AY33: 0 | BA33: =15000+8000 -> 23000 | BC33: 0 | BE33: 0 | BG33: =23000 -> 23000 | BI33: 0 | BK33: 82000 | BM33: =22000+1000 -> 23000 | BO33: 0 | BQ33: 0 | BS33: =3000 -> 3000 | BU33: 0 | BW33: 0 | BY33: 0 | CA33: 0 | CC33: 11000 | CE33: 0 | CG33: 0 | CI33: 0 | CK33: 11000 | CM33: 0 | CO33: 16000 | CQ33: 0 | CS33: 0
A34: NEQUI - transfer/egreso | BA34: 0 | BC34: 0 | BM34: 0 | BO34: -90000 | BQ34: 76000 | BS34: 0 | CA34: 0 | CC34: -27000 | CE34: 0 | CG34: 0 | CI34: 0 | CK34: 0 | CM34: 0 | CO34: 0 | CQ34: 0 | CS34: 0
A35: DaviPLATA Acum. | C35: =+C33+E35 -> 211000 | E35: =+E33+G35 -> 211000 | G35: =+G33+I35 -> 211000 | I35: =+I33+K35 -> 200000 | K35: =+K33+M35 -> 200000 | M35: =+M33+O35 -> 200000 | O35: =+O33+Q35 -> 200000 | Q35: =+Q33+S35 -> 200000 | S35: =+S33+U35 -> 200000 | U35: =+U33+W35 -> 200000 | W35: =+W33+Y35 -> 200000 | Y35: =+Y33+AA35 -> 200000 | AA35: =+AA33+AC35 -> 200000 | AC35: =+AC33+AE35 -> 200000 | AE35: =+AE33+AG35 -> 200000 | AG35: =+AG33+AI35 -> 200000 | AI35: =+AI33+AK35 -> 200000 | AK35: =+AK33+AM35 -> 200000 | AM35: =+AM33+AO35 -> 189000 | AO35: =+AO33+AS35 -> 162000 | AQ35: =+AQ33+AS35 -> 162000 | AS35: =+AS33+AU35 -> 162000 | AU35: =+AU33+AW35 -> 162000 | AW35: =+AW33+AY35 -> 162000 | AY35: =+AY33+BA35 -> 151000 | BA35: =+BA33+BC35 -> 151000 | BC35: =+BC33+BE35 -> 128000 | BE35: =+BE33+BG35 -> 128000 | BG35: =+BG33+BI35 -> 128000 | BI35: =+BI33+BK35 -> 105000 | BK35: =+BK33+BM35 -> 105000 | BM35: =+BM33 -> 23000 | BO35: =+BQ35+SUM(BO33:BO34) -> 0 | BQ35: =+BS35+SUM(BQ33:BQ34) -> 90000 | BS35: =+BU35+SUM(BS33:BS34) -> 14000 | BU35: =+BW35+SUM(BU33:BU34) -> 11000 | BW35: =+BY35+SUM(BW33:BW34) -> 11000 | BY35: =+CA35+SUM(BY33:BY34) -> 11000 | CA35: =+CC35+SUM(CA33:CA34) -> 11000 | CC35: =+CE35+SUM(CC33:CC34) -> 11000 | CE35: =+CE33+CG35 -> 27000 | CG35: =+CG33+CI35 -> 27000 | CI35: =+CI33+CK35 -> 27000 | CK35: =+CK33+CM35 -> 27000 | CM35: =+CM33+CO35 -> 16000 | CO35: =+CO33+CQ35 -> 16000 | CQ35: =+CQ33+CS35 -> 0 | CS35: =+CS33 -> 0
A36: CXC | C36: =+E36 -> 34000 | E36: =+G36 -> 34000 | G36: =+I36 -> 34000 | I36: =+K36 -> 34000 | K36: =+M36 -> 34000 | M36: =+O36 -> 34000 | O36: =+Q36 -> 34000 | Q36: =+S36 -> 34000 | S36: =+U36 -> 34000 | U36: =+W36 -> 34000 | W36: =+Y36 -> 34000 | Y36: =+AA36 -> 34000 | AA36: =+AC36 -> 34000 | AC36: =+AE36 -> 34000 | AE36: =+TICO!F19 -> 34000
A38: Venta | C38: =+C20+C30+C33 -> 301000 | E38: =+E20+E30+E33 -> 257000 | G38: =+G20+G30+G33 -> 87000 | I38: =+I20+I30+I33 -> 161000 | K38: =+K20+K30+K33 -> 266000 | M38: =+M20+M30+M33 -> 0 | O38: =+O20+O30+O33 -> 0 | Q38: =+Q20+Q30+Q33 -> 0 | S38: =+S20+S30+S33 -> 0 | U38: =+U20+U30+U33 -> 0 | W38: =+W20+W30+W33 -> 93500 | Y38: =+Y20+Y30+Y33 -> 76000 | AA38: =+AA20+AA30+AA33 -> 115500 | AC38: =+AC20+AC30+AC33 -> 211000 | AE38: =+AE20+AE30+AE33+AE36 -> 259000 | AG38: =+AG20+AG30+AG33 -> 0 | AI38: =+AI20+AI30+AI33 -> 128000 | AK38: =+AK20+AK30+AK33 -> 117500 | AM38: =+AM20+AM30+AM33 -> 292700 | AO38: =+AO20+AO30+AO33 -> 0 | AQ38: =+AQ20+AQ30+AQ33 -> 0 | AS38: =+AS20+AS30+AS33 -> 137500 | AU38: =+AU20+AU30+AU33 -> 172700 | AW38: =+AW20+AW30+AW33 -> 388500 | AY38: =+AY20+AY30+AY33 -> 148250 | BA38: =+BA20+BA30+BA33 -> 309500 | BC38: =+BC20+BC30+BC33 -> 120000 | BE38: =+BE20+BE30+BE33 -> 154000 | BG38: =+BG20+BG30+BG33 -> 387000 | BI38: =+BI20+BI30+BI33 -> 132500 | BK38: =+BK20+BK30+BK33 -> 243000 | BM38: =+BM20+BM30+BM33 -> 474500 | BO38: =+BO20+BO30+BO33 -> 92000 | BQ38: =+BQ20+BQ30+BQ33 -> 172500 | BS38: =+BS20+BS30+BS33 -> 264500 | BU38: =+BU20+BU30+BU33 -> 296500 | BW38: =+BW20+BW30+BW33 -> 0 | BY38: =+BY20+BY30+BY33 -> 275000 | CA38: =+CA20+CA30+CA33 -> 351000 | CC38: =+CC20+CC30+CC33 -> 196000 | CE38: =+CE20+CE30+CE33 -> 60000 | CG38: =+CG20+CG30+CG33 -> 0 | CI38: =+CI20+CI30+CI33 -> 503500 | CK38: =+CK20+CK30+CK33 -> 242000 | CM38: =+CM20+CM30+CM33 -> 209000 | CO38: =+CO20+CO30+CO33 -> 406500 | CQ38: =+CQ20+CQ30+CQ33 -> 224000 | CS38: =+CS20+CS30+CS33 -> 222400
A39: Acumulado | C39: =+C23+C32+C35 -> 1552597 | E39: =+E23+E32+E35 -> 1265997 | G39: =+G23+G32+G35 -> 1032997 | I39: =+I23+I32+I35 -> 1369247 | K39: =+K23+K32+K35 -> 1252997 | M39: =+M23+M32+M35 -> 1049997 | O39: =+O23+O32+O35 -> 1049997 | Q39: =+Q23+Q32+Q35 -> 1049997 | S39: =+S23+S32+S35 -> 1049997 | U39: =+U23+U32+U35 -> 1049997 | W39: =+W23+W32+W35 -> 1109997 | Y39: =+Y23+Y32+Y35 -> 1366497 | AA39: =+AA23+AA32+AA35 -> 1490497 | AC39: =+AC23+AC32+AC35 -> 1394997 | AE39: =+AE23+AE32+AE35 -> 1547850 | AG39: =+AG23+AG32+AG35 -> 1340450 | AI39: =+AI23+AI32+AI35 -> 1360450 | AK39: =+AK23+AK32+AK35 -> 1252450 | AM39: =+AM23+AM32+AM35 -> 1311800 | AO39: =+AO23+AO32+AO35 -> 1087300 | AQ39: =+AQ23+AQ32+AQ35 -> 1087300 | AS39: =+AS23+AS32+AS35 -> 1087300 | AU39: =+AU23+AU32+AU35 -> 1039800 | AW39: =+AW23+AW32+AW35 -> 988100 | AY39: =+AY23+AY32+AY35 -> 1102850 | BA39: =+BA23+BA32+BA35 -> 870150 | BC39: =+BC23+BC32+BC35 -> 873650 | BE39: =+BE23+BE32+BE35 -> 768650 | BG39: =+BG23+BG32+BG35 -> 775600 | BI39: =+BI23+BI32+BI35 -> 740100 | BK39: =+BK23+BK32+BK35 -> 607600 | BM39: =+BM23+BM32+BM35 -> 446050 | BO39: =+BO23+BO32+BO35 -> 372650 | BQ39: =+BQ23+BQ32+BQ35 -> 692650 | BS39: =+BS23+BS32+BS35 -> 626850 | BU39: =+BU23+BU32+BU35 -> 519200 | BW39: =+BY39 -> 436000 | BY39: =+BY23+BY32+BY35 -> 436000 | CA39: =+CA23+CA32+CA35 -> 246400 | CC39: =+CC23+CC32+CC35 -> 303850 | CE39: =+CE23+CE32+CE35 -> 813400 | CG39: =+CI39 -> 753400 | CI39: =+CI23+CI32+CI35 -> 753400 | CK39: =+CK23+CK32+CK35 -> 328100 | CM39: =+CM23+CM32+CM35 -> 634000 | CO39: =+CO23+CO32+CO35 -> 516900 | CQ39: =+CQ23+CQ32+CQ35 -> 357100 | CS39: =+CS23+CS32+CS35 -> 236100
A41: CXP | C41: 77612 | E41: 77612 | G41: =+I41 -> 423300 | I41: =+K41 -> 423300 | K41: =+M41 -> 423300 | M41: =+O41 -> 423300 | O41: =+Q41 -> 423300 | Q41: =+S41 -> 423300 | S41: =+U41 -> 423300 | U41: =+W41 -> 423300 | W41: =+Y41 -> 423300 | Y41: =+AA41 -> 423300 | AA41: =+AC41 -> 423300 | AC41: =+AE41 -> 423300 | AE41: =+AG41 -> 423300 | AG41: =+AI41 -> 423300 | AI41: =+AK41 -> 423300 | AK41: =+AM41 -> 423300 | AM41: =+AQ41 -> 423300 | AO41: =+AS41 -> 423300 | AQ41: =+AS41 -> 423300 | AS41: =+AU41 -> 423300 | AU41: 423300
AU42: dairoc
AU43: cepeda

Sheet Extracto
C1: Nequi | D1: =+SUMIF($H$7:$H$1048576,C1,$D$7:$D$1048576) -> 932247
C2: DaviPlata | D2: =+SUMIF($H$7:$H$1048576,C2,$D$7:$D$1048576) -> 211000
D3: =+SUM(D7:D1048576) -> 1143247 | H3: Total
D5: =+SUBTOTAL(9,D7:D1048576) -> 1143247
A6: fecha | B6: dia_sem | C6: hora | D6: valor | E6: Sopor. | F6: fact | G6: Estado | H6: cuenta | I6: nombre_cliente | J6: telefono
A7: 46076 | B7: =+TEXT(A7,"ddd") -> lun | C7: 0.72986111 | D7: 6500 | E7: fact | H7: Nequi | I7: Papá | J7: Error
A8: 46076 | B8: =+TEXT(A8,"ddd") -> lun | D8: 24000 | E8: fact | H8: Nequi | I8: Diana Carolina Colorado Penagos
A9: 46077 | B9: =+TEXT(A9,"ddd") -> mar | C9: 0.79375 | D9: 3000 | E9: fact | F9: 00024 | H9: Nequi | I9: Lucelyz Pelaez
A10: 46077 | B10: =+TEXT(A10,"ddd") -> mar | C10: 0.82777778 | D10: 8000 | E10: fact | F10: 00024 | H10: Nequi | I10: Jeisson Gutierrez
A11: 46078 | B11: =+TEXT(A11,"ddd") -> mié | C11: 0.69444444 | D11: 8000 | E11: fact | H11: Nequi | I11: María Torres
A12: 46078 | B12: =+TEXT(A12,"ddd") -> mié | C12: 0.79444444 | D12: 8000 | E12: fact | H12: Nequi | I12: Ori****Rod*****Ma | J12: Breb-B
A13: 46078 | B13: =+TEXT(A13,"ddd") -> mié | C13: 0.80694444 | D13: 22500 | E13: fact | H13: Nequi | I13: Papá | J13: Error
A14: 46078 | B14: =+TEXT(A14,"ddd") -> mié | C14: 0.83958333 | D14: 8000 | E14: fact | H14: Nequi | I14: Juan Heredia
A15: 46078 | B15: =+TEXT(A15,"ddd") -> mié | C15: 0.79375 | D15: 16000 | E15: fact | H15: DaviPlata | I15: ND | J15: DaviPlata
A16: 46079 | B16: =+TEXT(A16,"ddd") -> jue | C16: 0.56458333 | D16: 25000 | E16: fact | H16: Nequi | I16: Claudia Arevalo | J16: 322 381 0697
A17: 46079 | B17: =+TEXT(A17,"ddd") -> jue | C17: 0.84513889 | D17: 51000 | E17: fact | H17: Nequi | I17: Papá | J17: Error
A18: 46079 | B18: =+TEXT(A18,"ddd") -> jue | C18: 0.72777778 | D18: 49000 | E18: fact | H18: Nequi | I18: Darwin Casallas
A19: 46080 | B19: =+TEXT(A19,"ddd") -> vie | C19: 0.82291667 | D19: 11000 | E19: fact | H19: DaviPlata | I19: ND | J19: DaviPlata
A20: 46080 | B20: =+TEXT(A20,"ddd") -> vie | C20: 0.84236111 | D20: 10000 | E20: fact | H20: Nequi | I20: David Aparicio
A21: 46080 | B21: =+TEXT(A21,"ddd") -> vie | C21: 0.76319444 | D21: 24000 | E21: fact | H21: Nequi | I21: Natalia Bolivar
A22: 46080 | B22: =+TEXT(A22,"ddd") -> vie | C22: 0.75972222 | D22: 11000 | E22: fact | H22: Nequi | I22: Carlos Gonzalez
A23: 46081 | B23: =+TEXT(A23,"ddd") -> sáb | D23: 280000 | E23: fact | H23: Nequi | I23: Consignación a Edwin | J23: Consignación
A24: 46081 | B24: =+TEXT(A24,"ddd") -> sáb | C24: 0.79305556 | D24: 18000 | E24: fact | H24: Nequi | I24: Mel**** ***Alb Vil*** | J24: Breb-B
A25: 46081 | B25: =+TEXT(A25,"ddd") -> sáb | C25: 0.65208333 | D25: 16000 | E25: fact | H25: Nequi | I25: María Barrios | J25: 315 826 7681
A26: 46081 | B26: =+TEXT(A26,"ddd") -> sáb | C26: 0.65138889 | D26: 13000 | E26: fact | H26: Nequi | I26: David Aparicio | J26: 321 923 1130
A27: 46084 | B27: =+TEXT(A27,"ddd") -> mar | D27: =-(D19+D15) -> -27000 | E27: Nd-Nc | H27: DaviPlata | I27: Transferencia interbancos
A28: 46084 | B28: =+TEXT(A28,"ddd") -> mar | D28: 27000 | E28: fact | H28: Nequi | I28: Transferencia interbancos -papá
A29: 46084 | B29: =+TEXT(A29,"ddd") -> mar | D29: =5000*4 -> 20000 | E29: fact | H29: Nequi | I29: NO NEQUI - Hamburguesas para la casa
A30: 46084 | B30: =+TEXT(A30,"ddd") -> mar | D30: 33000 | E30: fact | H30: Nequi | I30: José Isidro Pinzòn Corredor
A31: 46084 | B31: =+TEXT(A31,"ddd") -> mar | D31: -619850 | E31: Nd-Nc | H31: Nequi | I31: Pago factura del cerdo
A32: 46085 | B32: =+TEXT(A32,"ddd") -> mié | D32: 19000 | E32: fact | H32: Nequi | I32: Edu***loz***Boh**
A33: 46085 | B33: =+TEXT(A33,"ddd") -> mié | D33: 8000 | E33: fact | H33: Nequi | I33: Gre***Leo***Cor**
A34: 46085 | B34: =+TEXT(A34,"ddd") -> mié | D34: 18000 | E34: fact | H34: Nequi | I34: Recarga desde Bancolomba
A35: 46085 | B35: =+TEXT(A35,"ddd") -> mié | D35: 8000 | E35: fact | H35: Nequi | I35: Willian Gutierrez
A36: 46085 | B36: =+TEXT(A36,"ddd") -> mié | D36: 64000 | E36: fact | H36: Nequi | I36: Sergio Alarcón | M36: =+SUM(D32:D36) -> 117000
A37: 46086 | B37: =+TEXT(A37,"ddd") -> jue | D37: 30000 | E37: fact | H37: Nequi | I37: Henry Aguirre | M37: =#REF!+8000 -> #REF!
A38: 46086 | B38: =+TEXT(A38,"ddd") -> jue | D38: 11000 | E38: fact | H38: Nequi | I38: Miguel Rodriguez
A39: 46086 | B39: =+TEXT(A39,"ddd") -> jue | D39: 16000 | E39: fact | H39: Nequi | I39: Diego Tijaro
A40: 46086 | B40: =+TEXT(A40,"ddd") -> jue | D40: 39500 | E40: fact | H40: Nequi | I40: Leidy Camacho | M40: =+#REF! -> #REF!
A41: 46086 | B41: =+TEXT(A41,"ddd") -> jue | D41: 35000 | E41: fact | H41: Nequi | I41: Manuel Fernando Ramirez | M41: =+SUM(D37:D41) -> 131500
...

Sheet Inv-2abr
A1: materia_prima | B1: TIPO | C1: stock real 2 de abril | D1: ENTRADAS 7 y 8 abril | E1: SALIDAS 7 y 8 abril | F1: stock actual | G1: stock real 8 de abril | H1: Ajuste | I1: comentarios | K1: =+SUM(K12:K1048576) -> -245080 | L1: =24*4 -> 96
A2: CHORIZO | B2: | | C2: =(100*2)+8 -> 208 | D2: 20 | E2: 41 | F2: 210 | G2: =+C2+D2-E2 -> 187 | H2: =+G2-F2 -> -23 | I2: DEGUSTACIÓN | J2: 3500 | K2: =+J2*H2 -> -80500
A3: PAPA | B3: | | C3: =+(50000/(150*3))*1.5 -> 166.66667 | E3: 39 | F3: -53 | G3: =+C3-E3 -> 127.66667 | H3: =+G3-F3 -> 180.66667 | I3: AJUSTE | J3: 750 | K3: =+J3*H3 -> 135500
A4: HAMBURGUESA | B4: | | C4: 39 | E4: 2 | F4: 38 | G4: =+C4-E4 -> 37 | H4: =+G4-F4 -> -1 | I4: DEGUSTACIÓN | J4: 5000 | K4: =+J4*H4 -> -5000
A5: Costillas BBQ | B5: | | C5: 9 | G5: =+C5-E5 -> 9 | H5: =+G5-F5 -> 9 | I5: AJUSTE | J5: 15000 | K5: =+J5*H5 -> 135000
A6: Carne 400 gramos | B6: | | C6: 5 | E6: 1 | F6: -30 | G6: =+C6-E6 -> 4 | H6: =+G6-F6 -> 34 | I6: AJUSTE | J6: 19000 | K6: =+J6*H6 -> 646000
A7: Carne 250 gramos | B7: | | F7: -21 | G7: =+C7-E7 -> 0 | H7: =+G7-F7 -> 21 | I7: AJUSTE | J7: 10000 | K7: =+J7*H7 -> 210000
A8: Lomo de cerdo | B8: | | C8: 3 | F8: 0 | G8: =+C8-E8 -> 3 | H8: =+G8-F8 -> 3 | I8: AJUSTE | J8: 10000 | K8: =+J8*H8 -> 30000
A9: Pechuga | B9: | | F9: -1 | G9: 0 | H9: 1 | I9: AJUSTE | J9: 17000 | K9: =+J9*H9 -> 17000
A10: Churrasco | B10: | | C10: 4 | F10: 0 | G10: =+C10-E10 -> 4 | H10: =+G10-F10 -> 4 | I10: AJUSTE | J10: 17000 | K10: =+J10*H10 -> 68000
A11: mojarra | B11: | | C11: 5 | E11: 5 | F11: 0 | G11: =+C11-E11 -> 0 | H11: =+G11-F11 -> 0 | I11: NOMINA + CASINO
A12: BEBIDA - AGUA 600 ML | B12: ||| | C12: 17 | F12: 34 | G12: =+C12-E12 -> 17 | H12: =+G12-F12 -> -17 | I12: PÉRDIDA | J12: 1417 | K12: =+J12*H12 -> -24089
A13: BEBIDA - Aguila | B13: ||| | C13: 0 | F13: 3 | G13: =+C13-E13 -> 0 | H13: =+G13-F13 -> -3 | I13: PÉRDIDA | J13: 3000 | K13: =+J13*H13 -> -9000
A14: BEBIDA - Cerveza Central | B14: ||| | C14: =8+48 -> 56 | E14: 9 | F14: 80 | G14: =+C14-E14 -> 47 | H14: =+G14-F14 -> -33 | I14: PÉRDIDA | J14: 1188 | K14: =+J14*H14 -> -39204
A15: BEBIDA - Cerveza Club Colombia | B15: ||| | C15: 0 | F15: 5 | G15: =+C15-E15 -> 0 | H15: =+G15-F15 -> -5 | I15: PÉRDIDA | J15: 3300 | K15: =+J15*H15 -> -16500
A16: BEBIDA - COCA COLA 237ML | B16: ||| | C16: 126 | E16: 16 | F16: 146 | G16: =+C16-E16 -> 110 | H16: =+G16-F16 -> -36 | I16: PÉRDIDA | J16: 1200 | K16: =+J16*H16 -> -43200 | M16: =+K16+K17 -> -107781
A17: BEBIDA - POSTOBON 250ML | B17: ||| | C17: 88 | F17: 145 | G17: =+C17-E17 -> 88 | H17: =+G17-F17 -> -57 | I17: PÉRDIDA | J17: 1133 | K17: =+J17*H17 -> -64581
A18: GASEOSA | B18: ||| | C18: =+C16+C17 -> 214 | F18: =+F16+F17 -> 291 | G18: =+G16+G17 -> 198 | H18: =+H16+H17 -> -93 | L18: =+SUM(K16:K17)/SUM(H16:H17) -> 1158.9355 | M18: =+L18*H18 -> -107781
A19: BEBIDA - COCA COLA ZERO | B19: ||| | C19: 16 | F19: 20 | G19: =+C19-E19 -> 16 | H19: =+G19-F19 -> -4 | I19: PÉRDIDA | J19: 1250 | K19: =+J19*H19 -> -5000
A20: BEBIDA - HIT 237ML | B20: ||| | C20: 13 | E20: 4 | F20: 27 | G20: =+C20-E20 -> 9 | H20: =+G20-F20 -> -18 | I20: PÉRDIDA | J20: 2417 | K20: =+J20*H20 -> -43506
A21: Arepa | B21: || | C21: 25 | E21: 303 | F21: -25 | G21: 30 | H21: =+G21-F21 -> 55 | I21: VENCIDO
A22: Pan Perro | B22: || | C22: 4 | E22: 4 | F22: 0 | G22: =+C22-E22 -> 0 | H22: =+G22-F22 -> 0 | I22: VENCIDO
A23: Pan Hamburguesa | B23: || | C23: =4*3 -> 12 | F23: 22 | G23: =+C23-E23 -> 12 | H23: =+G23-F23 -> -10 | I23: VENCIDO
A25: bolsa grande de cerdo | C25: 1 | G25: =+C25-E25 -> 1
A26: bolsa de cerdo varios kilos | C26: 1 | G26: =+C26-E26 -> 1
A27: Papa francesa grande | C27: 3 | G27: =+C27-E27 -> 3
A28: Papa francesa pequeña | C28: 8 | G28: =+C28-E28 -> 8
D30: =3500*187 -> 654500

Sheet Carta

Sheet DevOps
B1: DevOps
B2: fecha | C2: Detalle | D2: Backlog | E2: Código | F2: Nombre commit
B3: 46090 | C3: Como usuario general requiero abrir la caja para ágilizar el proceso de devolución de vueltas | D3: Done | E3: HU38 | F3: HU38: Botón de emergencia
B4: 46090 | C4: El título de la sección de efectivo no corresponde: "Registro Base" ---> "Registro de entradas y retiros de efectivo" | D4: Done | E4: BU001 | F4: BU001: El título de la sección no corresponde
B5: 46093 | C5: Se agrega botón "Abrir Caja", se mejora el dashboard de "Transacciones" para facilitar la consistencia de los datos" | D5: Done | E5: BU002 | F5: BU002: "Usabilidad y consistecia de la información"
B6: 46093 | C6: Se mejora la ordenación del orden de las facturar para validarlas mejor, se agrega el botón "Abrir Caja" en la sección de factura, y se omite desde dashboard para facilitar la seguridad del sistema. | D6: Done | E6: BU003 | F6: BU003: "Usabilidad para el cajero y seguridad"
B7: 46093 | C7: Cambiar a item por producto y materia prima. Cambiar el título de "Entradas" por "MP" de materias primas | D7: Done | E7: BU004 | F7: BU004: "Usabilidad el admon y cajero"
B8: 46093 | C8: Crea un warning que diga "No ha guardado los registros, ¿estas seguro que quiere salir? | D8: Done | E8: BU005 | F8: BU005: "Usabilidad cajero - warning"
B9: 46093 | C9: No hay diferencia entre las entradas y salidas el efectivo con los egresos en el dashboard "ADMON: "Consignación" | D9: Done | E9: BU006 | F9: BU006: "Usabilidad y consistencia de la información"
B10: 46093 | C10: Nequi y DaviPlata deben estar en filas diferentes | D10: Done | E10: BU007 | F10: BU007: "Usabilidad y consistencia de la información"
B11: 46093 | C11: Como cajero, quiero filtrar el medio de pago de las facturas y egresos para facilizar la conciliación bancaria | D11: Done | E11: HU39 | F11: HU39: Filtrar Medio de pago
B12: 46099 | C12: Como cajero, quiero poder hacer un descuento a un producto para agilizar el proceso y ser consistente con la información | D12: Done | E12: BU008 | F12: BU008: "Usabilidad y consistencia de la información"
B13: 46099 | C13: al finalizar el dia la venta del dia suma el acumulado del dia siguiente para Nequi y Daviplata | D13: Done | E13: BU009 | F13: BU009: "Usabilidad y consistencia de la información"
B14: 46100 | C14: Como usuaio quiero ver estilo de colores en el dashboard para diferenciar más las transacciones. | D14: Done | E14: BU010 | F14: BU010: "UX-Design"
... B37: 46121 | C37: Como Usuario admin, quiero ver adicionar la información del inventario | D37: Done | E37: BU26 | F37: BU026: " Disponibilidad y Usabilidad"
C38: Omitir abrir caja para transacciones de nequi y daviplata | F38: }
C39: abrir solo cuando hay efectivo
C40: clasificar entrada y salida no es claro
C41: SUMARSE EL VALOR DE INVENTARIO
C42: NO SE PUEDE agregar nuevos items al ingresar o retirar inventarios
C43: Visor para domicilios | D43: Backlog
C45: Filtrar mejor las transacciones, nequi, suma gastos
C46: se abre multiples ventanas | D46: Backlog | F46: se abre multiples ventanas
C47: imprimir informe | D47: Backlog | F47: imprimir informe
D48: Backlog | F48: el caja se abre cada rato
C49: picadas, no hay manera de digitar picadas | D49: Backlog | F49: picadas, no hay manera de digitar picadas
C50: el visor no es muy pràctico | D50: Backlog | F50: el visor no es muy pràctico
C51: no hay ruta rapida de chorizo | D51: Backlog | F51: no hay ruta rapida de chorizo
C52: correir informaciòn del inventario | D52: Backlog | F52: correir informaciòn del inventario

Sheet precio_mp

Sheet MP
D1: tipo_unidad
D2: 10 un | J2: 3400
B5: fecha | C5: Categoria | D5: nombre_producto | E5: tipo_unidad | F5: precio_embalaje | G5: unidades_embalaje | H5: unidades_x_embalaje | I5: total | J5: unidades | K5: precio_unidad | L5: total
B6: 46076 | C6: MATERIA PRIMA | D6: Chorizo | E6: unidad | I6: =+F6*G6 -> 0 | J6: 365 | K6: 3500 | L6: =+J6*K6 -> 1277500
B7: 46089 | C7: MATERIA PRIMA | D7: Chorizo | E7: bolsa | F7: =3500*100 -> 350000 | G7: 5 | H7: 100 | I7: =+F7*G7 -> 1750000 | J7: =+G7*H7 -> 500 | K7: 3500 | L7: =+K7*J7 -> 1750000
B8: 46106 | C8: MATERIA PRIMA | D8: Chorizo | E8: unidad | I8: =+F8*G8 -> 0 | J8: 230 | K8: 3500 | L8: =+K8*J8 -> 805000
B9: 46072 | C9: MATERIA PRIMA | D9: papa salada | E9: Bulto | F9: 70000 | G9: 2 | H9: =50000/(150*3) -> 111.11111 | I9: =+F9*G9 -> 140000 | J9: =+G9*H9 -> 222.22222 | K9: =+I9/J9 -> 630 | L9: =+K9*J9 -> 140000
B10: 46112 | C10: MATERIA PRIMA | D10: papa salada | E10: Bulto | F10: 70000 | G10: 2 | H10: =50000/(150*3) -> 111.11111 | I10: =+F10*G10 -> 140000 | J10: =+G10*H10 -> 222.22222 | K10: =+I10/J10 -> 630 | L10: =+K10*J10 -> 140000
B11: 46109 | C11: MATERIA PRIMA | D11: papa salada | E11: Bulto | F11: 80000 | G11: 1 | H11: =50000/(150*3) -> 111.11111 | I11: =+F11*G11 -> 80000 | J11: =+G11*H11 -> 111.11111 | K11: =+I11/J11 -> 720 | L11: =+K11*J11 -> 80000
B12: 46089 | C12: MATERIA PRIMA | D12: arepa | E12: unidad | F12: 3800 | G12: 10 | H12: 10 | I12: =+F12*G12 -> 38000 | J12: 100 | K12: 380 | L12: =+J12*K12 -> 38000
B13: 46077 | C13: MATERIA PRIMA | D13: Hamburguesa | E13: unidad | I13: =+F13*G13 -> 0 | J13: 50 | K13: 5000 | L13: =+J13*K13 -> 250000
B14: 46073 | C14: BEBIDA | D14: Coca Cola -237ML | E14: canasta | F14: 36000 | G14: 6 | H14: 30 | I14: =+F14*G14 -> 216000 | J14: =+H14*G14 -> 180 | K14: =+I14/(G14*H14) -> 1200 | L14: =+K14*J14 -> 216000
B15: 46073 | C15: BEBIDA | D15: Postobon -250ML | E15: canasta | F15: 35000 | G15: 3 | H15: 30 | I15: =+F15*G15 -> 105000 | J15: =+H15*G15 -> 90 | K15: =+I15/(G15*H15) -> 1166.6667 | L15: =+K15*J15 -> 105000
B16: 46073 | C16: BEBIDA | D16: Hit-500ML | E16: doce un. | F16: 29000 | G16: 2 | H16: 12 | I16: =+F16*G16 -> 58000 | J16: =+H16*G16 -> 24 | K16: =+I16/(G16*H16) -> 2416.6667 | L16: =+K16*J16 -> 58000
B17: 46073 | C17: BEBIDA | D17: Agua -600ML | E17: 2 docenas | F17: 33000 | G17: 1 | H17: 24 | I17: =+F17*G17 -> 33000 | J17: =+H17*G17 -> 24 | K17: =+I17/(G17*H17) -> 1375 | L17: =+K17*J17 -> 33000
B18: 46100 | C18: BEBIDA | D18: Coca Cola -237ML | E18: canasta | F18: 36000 | G18: 5 | H18: 30 | I18: =+F18*G18 -> 180000 | J18: 30 | K18: =+I18/(G18*H18) -> 1200 | L18: =+F18*G18 -> 180000
B19: 46100 | C19: BEBIDA | D19: Postobon -250ML | E19: canasta | F19: 34000 | G19: 3 | H19: 30 | I19: =+F19*G19 -> 102000 | J19: 30 | K19: =+I19/(G19*H19) -> 1133.3333 | L19: =+F19*G19 -> 102000
B20: 46100 | C20: BEBIDA | D20: Coca Cola Zero -250ML | E20: six pack | F20: 15000 | G20: 2 | H20: 12 | I20: =+F20*G20 -> 30000 | J20: 12 | K20: =+I20/(G20*H20) -> 1250 | L20: =+F20*G20 -> 30000
B21: 46100 | C21: BEBIDA | D21: Hit-500ML | E21: docena | F21: 29000 | G21: 2 | H21: 12 | I21: =+F21*G21 -> 58000 | J21: 12 | K21: =+I21/(G21*H21) -> 2416.6667 | L21: =+F21*G21 -> 58000
B22: 46100 | C22: BEBIDA | D22: Agua -600ML | E22: 2 docenas | F22: 34000 | G22: 1 | H22: 24 | I22: =+F22*G22 -> 34000 | J22: 24 | K22: =+I22/(G22*H22) -> 1416.6667 | L22: =+F22*G22 -> 34000
B23: 46102 | C23: BEBIDA | D23: CERVEZA CENTRAL | E23: Paca | F23: 28500 | G23: 4 | H23: =6*4 -> 24 | I23: =+F23*G23 -> 114000 | J23: =+G23*H23 -> 96 | K23: =+I23/(G23*H23) -> 1187.5 | L23: =+J23*K23 -> 114000
B24: 46091 | C24: BEBIDA | D24: CLUB COLOMBIA | E24: six pack | F24: 19800 | G24: 1 | H24: 6 | I24: =+F24*G24 -> 19800 | J24: =+G24*H24 -> 6 | K24: =+I24/(G24*H24) -> 3300 | L24: =+F24*G24 -> 19800
B25: 46091 | C25: BEBIDA | D25: CLUB AGUILA | E25: six pack | F25: 18000 | G25: 2 | H25: 6 | I25: =+F25*G25 -> 36000 | J25: =+G25*H25 -> 12 | K25: =+I25/(G25*H25) -> 3000 | L25: =+F25*G25 -> 36000
B26: 46085 | C26: MATERIA PRIMA | D26: Filete de pechuga | E26: kilo | F26: 11700 | G26: 2.56 | H26: 2 | I26: =+F26*G26 -> 29952 | J26: =+G26*H26 -> 5.12 | K26: =+I26/(G26*H26) -> 5850 | L26: =+F26*G26 -> 29952
B29: 46073 | C29: BEBIDA | D29: Coca Cola -237ML | E29: canasta | F29: 36000 | G29: 4 | H29: 30 | I29: =+F29*G29 -> 144000 | J29: =+H29*G29 -> 120 | K29: =+I29/(G29*H29) -> 1200 | L29: =+K29*J29 -> 144000
