Workbook
Name Costo_MP: #REF!
Name Cuentas_x_pagar: Pasivos[]
Name Cuentas_x_pagar: Pasivos[]
Name Cuentas_x_pagar: Pasivos[]
Name Efectivo: #REF!
Name SegmentaciónDeDatos_Tipo_día: #N/A
Name Stock_Inventario: #REF!

Sheet Inicio
AA1: 0

Sheet OPEX_SALES
L1: 8 | N1: 24 | O1: 13 | P1: 15 | Q1: 22
A2: Fecha | B2: No. Semana de operación | C2: dia | D2: Tipo día | E2: Tipo día2 | F2: Venta | G2: MG | H2: Rentabilidad | I2: Tipo | J2: Venta PE | K2: Opex | L2: Arriendo | M2: Servicios publicos | N2: Internet | O2: Gas | P2: Agua | Q2: Electricidad | R2: Nomina | S2: Cajero | T2: Parrillero | U2: Domiciliario
A3: 46068 | B3: 0 | C3: =+TEXT(Opex_VE[[#This Row],[Fecha]],"ddd") -> dom | D3: cerrado | E3: D) Domingo | F3: 0 | G3: 0 | H3: =+Opex_VE[[#This Row],[MG]]-Opex_VE[[#This Row],[Opex]] -> 0 | I3: Histórico | J3: =+Opex_VE[[#This Row],[Opex]] -> 0 | K3: 0 | L3: =+VLOOKUP(Opex_VE[[#This Row],[Fecha]],Opex!$B:$Y,OPEX_SALES!L$1,1) -> 61111.111 | M3: =+SUM(Opex_VE[[#This Row],[Internet]:[Electricidad]]) -> 0 | N3: =+VLOOKUP(Opex_VE[[#This Row],[Fecha]],Opex!$B:$Y,OPEX_SALES!N$1,1) -> 0 | O3: =+VLOOKUP(Opex_VE[[#This Row],[Fecha]],Opex!$B:$Y,OPEX_SALES!O$1,1) -> 0 | P3: =+VLOOKUP(Opex_VE[[#This Row],[Fecha]],Opex!$B:$Y,OPEX_SALES!P$1,1) -> 0 | Q3: =+VLOOKUP(Opex_VE[[#This Row],[Fecha]],Opex!$B:$Y,OPEX_SALES!Q$1,1) -> 0 | R3: =+SUM(Opex_VE[[#This Row],[Cajero]:[Domiciliario]]) -> 0 | S3: 0 | T3: 0 | U3: 0
A4: 46069 | B4: 1 | C4: =+TEXT(Opex_VE[[#This Row],[Fecha]],"ddd") -> lun | D4: cerrado | E4: A) Día hábil | F4: 0 | G4: 0 | H4: =+Opex_VE[[#This Row],[MG]]-Opex_VE[[#This Row],[Opex]] -> 0 | I4: Histórico | J4: =+Opex_VE[[#This Row],[Opex]] -> 0 | K4: 0 | L4: =+VLOOKUP(Opex_VE[[#This Row],[Fecha]],Opex!$B:$Y,OPEX_SALES!L$1,1) -> 61111.111 | M4: =+SUM(Opex_VE[[#This Row],[Internet]:[Electricidad]]) -> 0 | N4: =+VLOOKUP(Opex_VE[[#This Row],[Fecha]],Opex!$B:$Y,OPEX_SALES!N$1,1) -> 0 | O4: =+VLOOKUP(Opex_VE[[#This Row],[Fecha]],Opex!$B:$Y,OPEX_SALES!O$1,1) -> 0 | P4: =+VLOOKUP(Opex_VE[[#This Row],[Fecha]],Opex!$B:$Y,OPEX_SALES!P$1,1) -> 0 | Q4: =+VLOOKUP(Opex_VE[[#This Row],[Fecha]],Opex!$B:$Y,OPEX_SALES!Q$1,1) -> 0 | R4: =+SUM(Opex_VE[[#This Row],[Cajero]:[Domiciliario]]) -> 0 | S4: 0 | T4: 0 | U4: 0
A5: 46070 | B5: 1 | C5: =+TEXT(Opex_VE[[#This Row],[Fecha]],"ddd") -> mar | D5: cerrado | E5: A) Día hábil | F5: 0 | G5: 0 | H5: =+Opex_VE[[#This Row],[MG]]-Opex_VE[[#This Row],[Opex]] -> 0 | I5: Histórico | J5: =+Opex_VE[[#This Row],[Opex]] -> 0 | K5: 0 | L5: =+VLOOKUP(Opex_VE[[#This Row],[Fecha]],Opex!$B:$Y,OPEX_SALES!L$1,1) -> 61111.111 | M5: =+SUM(Opex_VE[[#This Row],[Internet]:[Electricidad]]) -> 0 | N5: =+VLOOKUP(Opex_VE[[#This Row],[Fecha]],Opex!$B:$Y,OPEX_SALES!N$1,1) -> 0 | O5: =+VLOOKUP(Opex_VE[[#This Row],[Fecha]],Opex!$B:$Y,OPEX_SALES!O$1,1) -> 0 | P5: =+VLOOKUP(Opex_VE[[#This Row],[Fecha]],Opex!$B:$Y,OPEX_SALES!P$1,1) -> 0 | Q5: =+VLOOKUP(Opex_VE[[#This Row],[Fecha]],Opex!$B:$Y,OPEX_SALES!Q$1,1) -> 0 | R5: =+SUM(Opex_VE[[#This Row],[Cajero]:[Domiciliario]]) -> 0 | S5: 0 | T5: 0 | U5: 0
A6: 46071 | B6: 1 | C6: =+TEXT(Opex_VE[[#This Row],[Fecha]],"ddd") -> mié | D6: cerrado | E6: A) Día hábil | F6: 0 | G6: 0 | H6: =+Opex_VE[[#This Row],[MG]]-Opex_VE[[#This Row],[Opex]] -> 0 | I6: Histórico | J6: =+Opex_VE[[#This Row],[Opex]] -> 0 | K6: 0 | L6: =+VLOOKUP(Opex_VE[[#This Row],[Fecha]],Opex!$B:$Y,OPEX_SALES!L$1,1) -> 61111.111 | M6: =+SUM(Opex_VE[[#This Row],[Internet]:[Electricidad]]) -> 0 | N6: =+VLOOKUP(Opex_VE[[#This Row],[Fecha]],Opex!$B:$Y,OPEX_SALES!N$1,1) -> 0 | O6: =+VLOOKUP(Opex_VE[[#This Row],[Fecha]],Opex!$B:$Y,OPEX_SALES!O$1,1) -> 0 | P6: =+VLOOKUP(Opex_VE[[#This Row],[Fecha]],Opex!$B:$Y,OPEX_SALES!P$1,1) -> 0 | Q6: =+VLOOKUP(Opex_VE[[#This Row],[Fecha]],Opex!$B:$Y,OPEX_SALES!Q$1,1) -> 0 | R6: =+SUM(Opex_VE[[#This Row],[Cajero]:[Domiciliario]]) -> 0 | S6: 0 | T6: 0 | U6: 0
A7: 46072 | B7: 1 | C7: =+TEXT(Opex_VE[[#This Row],[Fecha]],"ddd") -> jue | D7: cerrado | E7: A) Día hábil | F7: 0 | G7: 0 | H7: =+Opex_VE[[#This Row],[MG]]-Opex_VE[[#This Row],[Opex]] -> 0 | I7: Histórico | J7: =+Opex_VE[[#This Row],[Opex]] -> 0 | K7: 0 | L7: =+VLOOKUP(Opex_VE[[#This Row],[Fecha]],Opex!$B:$Y,OPEX_SALES!L$1,1) -> 61111.111 | M7: =+SUM(Opex_VE[[#This Row],[Internet]:[Electricidad]]) -> 0 | N7: =+VLOOKUP(Opex_VE[[#This Row],[Fecha]],Opex!$B:$Y,OPEX_SALES!N$1,1) -> 0 | O7: =+VLOOKUP(Opex_VE[[#This Row],[Fecha]],Opex!$B:$Y,OPEX_SALES!O$1,1) -> 0 | P7: =+VLOOKUP(Opex_VE[[#This Row],[Fecha]],Opex!$B:$Y,OPEX_SALES!P$1,1) -> 0 | Q7: =+VLOOKUP(Opex_VE[[#This Row],[Fecha]],Opex!$B:$Y,OPEX_SALES!Q$1,1) -> 0 | R7: =+SUM(Opex_VE[[#This Row],[Cajero]:[Domiciliario]]) -> 0 | S7: 0 | T7: 0 | U7: 0
A8: 46073 | B8: 1 | C8: =+TEXT(Opex_VE[[#This Row],[Fecha]],"ddd") -> vie | D8: cerrado | E8: B) Viernes | F8: 0 | G8: 0 | H8: =+Opex_VE[[#This Row],[MG]]-Opex_VE[[#This Row],[Opex]] -> 0 | I8: Histórico | J8: =+Opex_VE[[#This Row],[Opex]] -> 0 | K8: 0 | L8: =+VLOOKUP(Opex_VE[[#This Row],[Fecha]],Opex!$B:$Y,OPEX_SALES!L$1,1) -> 61111.111 | M8: =+SUM(Opex_VE[[#This Row],[Internet]:[Electricidad]]) -> 0 | N8: =+VLOOKUP(Opex_VE[[#This Row],[Fecha]],Opex!$B:$Y,OPEX_SALES!N$1,1) -> 0 | O8: =+VLOOKUP(Opex_VE[[#This Row],[Fecha]],Opex!$B:$Y,OPEX_SALES!O$1,1) -> 0 | P8: =+VLOOKUP(Opex_VE[[#This Row],[Fecha]],Opex!$B:$Y,OPEX_SALES!P$1,1) -> 0 | Q8: =+VLOOKUP(Opex_VE[[#This Row],[Fecha]],Opex!$B:$Y,OPEX_SALES!Q$1,1) -> 0 | R8: =+SUM(Opex_VE[[#This Row],[Cajero]:[Domiciliario]]) -> 0 | S8: 0 | T8: 0 | U8: 0
A9: 46074 | B9: 1 | C9: =+TEXT(Opex_VE[[#This Row],[Fecha]],"ddd") -> sáb | D9: cerrado | E9: C) Sábado | F9: 0 | G9: 0 | H9: =+Opex_VE[[#This Row],[MG]]-Opex_VE[[#This Row],[Opex]] -> 0 | I9: Histórico | J9: =+Opex_VE[[#This Row],[Opex]] -> 0 | K9: 0 | L9: =+VLOOKUP(Opex_VE[[#This Row],[Fecha]],Opex!$B:$Y,OPEX_SALES!L$1,1) -> 61111.111 | M9: =+SUM(Opex_VE[[#This Row],[Internet]:[Electricidad]]) -> 0 | N9: =+VLOOKUP(Opex_VE[[#This Row],[Fecha]],Opex!$B:$Y,OPEX_SALES!N$1,1) -> 0 | O9: =+VLOOKUP(Opex_VE[[#This Row],[Fecha]],Opex!$B:$Y,OPEX_SALES!O$1,1) -> 0 | P9: =+VLOOKUP(Opex_VE[[#This Row],[Fecha]],Opex!$B:$Y,OPEX_SALES!P$1,1) -> 0 | Q9: =+VLOOKUP(Opex_VE[[#This Row],[Fecha]],Opex!$B:$Y,OPEX_SALES!Q$1,1) -> 0 | R9: =+SUM(Opex_VE[[#This Row],[Cajero]:[Domiciliario]]) -> 0 | S9: 0 | T9: 0 | U9: 0
A10: 46075 | B10: 1 | C10: =+TEXT(Opex_VE[[#This Row],[Fecha]],"ddd") -> dom | D10: cerrado | E10: D) Domingo | F10: 0 | G10: 0 | H10: =+Opex_VE[[#This Row],[MG]]-Opex_VE[[#This Row],[Opex]] -> 0 | I10: Histórico | J10: =+Opex_VE[[#This Row],[Opex]] -> 0 | K10: 0 | L10: =+VLOOKUP(Opex_VE[[#This Row],[Fecha]],Opex!$B:$Y,OPEX_SALES!L$1,1) -> 61111.111 | M10: =+SUM(Opex_VE[[#This Row],[Internet]:[Electricidad]]) -> 0 | N10: =+VLOOKUP(Opex_VE[[#This Row],[Fecha]],Opex!$B:$Y,OPEX_SALES!N$1,1) -> 0 | O10: =+VLOOKUP(Opex_VE[[#This Row],[Fecha]],Opex!$B:$Y,OPEX_SALES!O$1,1) -> 0 | P10: =+VLOOKUP(Opex_VE[[#This Row],[Fecha]],Opex!$B:$Y,OPEX_SALES!P$1,1) -> 0 | Q10: =+VLOOKUP(Opex_VE[[#This Row],[Fecha]],Opex!$B:$Y,OPEX_SALES!Q$1,1) -> 0 | R10: =+SUM(Opex_VE[[#This Row],[Cajero]:[Domiciliario]]) -> 0 | S10: 0 | T10: 0 | U10: 0
A11: 46082 | B11: 1 | C11: =+TEXT(Opex_VE[[#This Row],[Fecha]],"ddd") -> dom | D11: cerrado | E11: D) Domingo | F11: 0 | G11: 0 | H11: =+Opex_VE[[#This Row],[MG]]-Opex_VE[[#This Row],[Opex]] -> 0 | I11: Histórico | J11: =+Opex_VE[[#This Row],[Opex]] -> 0 | K11: 0 | L11: =+VLOOKUP(Opex_VE[[#This Row],[Fecha]],Opex!$B:$Y,OPEX_SALES!L$1,1) -> 61111.111 | M11: =+SUM(Opex_VE[[#This Row],[Internet]:[Electricidad]]) -> 0 | N11: =+VLOOKUP(Opex_VE[[#This Row],[Fecha]],Opex!$B:$Y,OPEX_SALES!N$1,1) -> 0 | O11: =+VLOOKUP(Opex_VE[[#This Row],[Fecha]],Opex!$B:$Y,OPEX_SALES!O$1,1) -> 0 | P11: =+VLOOKUP(Opex_VE[[#This Row],[Fecha]],Opex!$B:$Y,OPEX_SALES!P$1,1) -> 0 | Q11: =+VLOOKUP(Opex_VE[[#This Row],[Fecha]],Opex!$B:$Y,OPEX_SALES!Q$1,1) -> 0 | R11: =+SUM(Opex_VE[[#This Row],[Cajero]:[Domiciliario]]) -> 0 | S11: 0 | T11: 0 | U11: 0
A12: 46087 | B12: 1 | C12: =+TEXT(Opex_VE[[#This Row],[Fecha]],"ddd") -> vie | D12: cerrado | E12: B) Viernes | F12: 0 | G12: 0 | H12: =+Opex_VE[[#This Row],[MG]]-Opex_VE[[#This Row],[Opex]] -> 0 | I12: Histórico | J12: =+Opex_VE[[#This Row],[Opex]] -> 0 | K12: 0 | L12: =+VLOOKUP(Opex_VE[[#This Row],[Fecha]],Opex!$B:$Y,OPEX_SALES!L$1,1) -> 61111.111 | M12: =+SUM(Opex_VE[[#This Row],[Internet]:[Electricidad]]) -> 0 | N12: =+VLOOKUP(Opex_VE[[#This Row],[Fecha]],Opex!$B:$Y,OPEX_SALES!N$1,1) -> 0 | O12: =+VLOOKUP(Opex_VE[[#This Row],[Fecha]],Opex!$B:$Y,OPEX_SALES!O$1,1) -> 0 | P12: =+VLOOKUP(Opex_VE[[#This Row],[Fecha]],Opex!$B:$Y,OPEX_SALES!P$1,1) -> 0 | Q12: =+VLOOKUP(Opex_VE[[#This Row],[Fecha]],Opex!$B:$Y,OPEX_SALES!Q$1,1) -> 0 | R12: =+SUM(Opex_VE[[#This Row],[Cajero]:[Domiciliario]]) -> 0 | S12: 0 | T12: 0 | U12: 0
A13: 46076 | B13: 1 | C13: =+TEXT(Opex_VE[[#This Row],[Fecha]],"ddd") -> lun | D13: Normal | E13: A) Día hábil | F13: =IFERROR(VLOOKUP(Opex_VE[[#This Row],[Fecha]],Historia!A:B,2,0),_xlfn.XLOOKUP(Opex_VE[[#This Row],[dia]],Forecast!I:I,Forecast!J:J)) -> 225000 | G13: =IFERROR(VLOOKUP(Opex_VE[[#This Row],[Fecha]],Historia!A:C,3,0),_xlfn.XLOOKUP(Opex_VE[[#This Row],[dia]],Forecast!I:I,Forecast!K:K)) -> 90000 | H13: =+Opex_VE[[#This Row],[MG]]-Opex_VE[[#This Row],[Opex]] -> -21111.111 | I13: =IFERROR(VLOOKUP(Opex_VE[[#This Row],[Fecha]],Historia!A:D,4,0),"Forecast") -> Histórico | J13: =+K13/0.4 -> 277777.78 | K13: =+Opex_VE[[#This Row],[Arriendo]]+Opex_VE[[#This Row],[Servicios publicos]]+Opex_VE[[#This Row],[Nomina]] -> 111111.11 | L13: =+VLOOKUP(Opex_VE[[#This Row],[Fecha]],Opex!$B:$Y,OPEX_SALES!L$1,1) -> 61111.111 | M13: =+SUM(Opex_VE[[#This Row],[Internet]:[Electricidad]]) -> 0 | N13: =+VLOOKUP(Opex_VE[[#This Row],[Fecha]],Opex!$B:$Y,OPEX_SALES!N$1,1) -> 0 | O13: =+VLOOKUP(Opex_VE[[#This Row],[Fecha]],Opex!$B:$Y,OPEX_SALES!O$1,1) -> 0 | P13: =+VLOOKUP(Opex_VE[[#This Row],[Fecha]],Opex!$B:$Y,OPEX_SALES!P$1,1) -> 0 | Q13: =+VLOOKUP(Opex_VE[[#This Row],[Fecha]],Opex!$B:$Y,OPEX_SALES!Q$1,1) -> 0 | R13: =+SUM(Opex_VE[[#This Row],[Cajero]:[Domiciliario]]) -> 50000 | S13: 50000 | T13: 0 | U13: 0
A14: 46077 | B14: 1 | C14: =+TEXT(Opex_VE[[#This Row],[Fecha]],"ddd") -> mar | D14: Normal | E14: A) Día hábil | F14: =IFERROR(VLOOKUP(Opex_VE[[#This Row],[Fecha]],Historia!A:B,2,0),_xlfn.XLOOKUP(Opex_VE[[#This Row],[dia]],Forecast!I:I,Forecast!J:J)) -> 221500 | G14: =IFERROR(VLOOKUP(Opex_VE[[#This Row],[Fecha]],Historia!A:C,3,0),_xlfn.XLOOKUP(Opex_VE[[#This Row],[dia]],Forecast!I:I,Forecast!K:K)) -> 88600 | H14: =+Opex_VE[[#This Row],[MG]]-Opex_VE[[#This Row],[Opex]] -> -42511.111 | I14: =IFERROR(VLOOKUP(Opex_VE[[#This Row],[Fecha]],Historia!A:D,4,0),"Forecast") -> Histórico | J14: =+K14/0.4 -> 327777.78 | K14: =+Opex_VE[[#This Row],[Arriendo]]+Opex_VE[[#This Row],[Servicios publicos]]+Opex_VE[[#This Row],[Nomina]] -> 131111.11 | L14: =+VLOOKUP(Opex_VE[[#This Row],[Fecha]],Opex!$B:$Y,OPEX_SALES!L$1,1) -> 61111.111 | M14: =+SUM(Opex_VE[[#This Row],[Internet]:[Electricidad]]) -> 0 | N14: =+VLOOKUP(Opex_VE[[#This Row],[Fecha]],Opex!$B:$Y,OPEX_SALES!N$1,1) -> 0 | O14: =+VLOOKUP(Opex_VE[[#This Row],[Fecha]],Opex!$B:$Y,OPEX_SALES!O$1,1) -> 0 | P14: =+VLOOKUP(Opex_VE[[#This Row],[Fecha]],Opex!$B:$Y,OPEX_SALES!P$1,1) -> 0 | Q14: =+VLOOKUP(Opex_VE[[#This Row],[Fecha]],Opex!$B:$Y,OPEX_SALES!Q$1,1) -> 0 | R14: =+SUM(Opex_VE[[#This Row],[Cajero]:[Domiciliario]]) -> 70000 | S14: 70000 | T14: 0 | U14: 0
A15: 46078 | B15: 1 | C15: =+TEXT(Opex_VE[[#This Row],[Fecha]],"ddd") -> mié | D15: Normal | E15: A) Día hábil | F15: =IFERROR(VLOOKUP(Opex_VE[[#This Row],[Fecha]],Historia!A:B,2,0),_xlfn.XLOOKUP(Opex_VE[[#This Row],[dia]],Forecast!I:I,Forecast!J:J)) -> 390500 | G15: =IFERROR(VLOOKUP(Opex_VE[[#This Row],[Fecha]],Historia!A:C,3,0),_xlfn.XLOOKUP(Opex_VE[[#This Row],[dia]],Forecast!I:I,Forecast!K:K)) -> 156200 | H15: =+Opex_VE[[#This Row],[MG]]-Opex_VE[[#This Row],[Opex]] -> 5088.8889 | I15: =IFERROR(VLOOKUP(Opex_VE[[#This Row],[Fecha]],Historia!A:D,4,0),"Forecast") -> Histórico | J15: =+K15/0.4 -> 377777.78 | K15: =+Opex_VE[[#This Row],[Arriendo]]+Opex_VE[[#This Row],[Servicios publicos]]+Opex_VE[[#This Row],[Nomina]] -> 151111.11 | L15: =+VLOOKUP(Opex_VE[[#This Row],[Fecha]],Opex!$B:$Y,OPEX_SALES!L$1,1) -> 61111.111 | M15: =+SUM(Opex_VE[[#This Row],[Internet]:[Electricidad]]) -> 0 | N15: =+VLOOKUP(Opex_VE[[#This Row],[Fecha]],Opex!$B:$Y,OPEX_SALES!N$1,1) -> 0 | O15: =+VLOOKUP(Opex_VE[[#This Row],[Fecha]],Opex!$B:$Y,OPEX_SALES!O$1,1) -> 0 | P15: =+VLOOKUP(Opex_VE[[#This Row],[Fecha]],Opex!$B:$Y,OPEX_SALES!P$1,1) -> 0 | Q15: =+VLOOKUP(Opex_VE[[#This Row],[Fecha]],Opex!$B:$Y,OPEX_SALES!Q$1,1) -> 0 | R15: =+SUM(Opex_VE[[#This Row],[Cajero]:[Domiciliario]]) -> 90000 | S15: 70000 | T15: 20000 | U15: 0
A16: 46079 | B16: 1 | C16: =+TEXT(Opex_VE[[#This Row],[Fecha]],"ddd") -> jue | E16: A) Día hábil | F16: =IFERROR(VLOOKUP(Opex_VE[[#This Row],[Fecha]],Historia!A:B,2,0),_xlfn.XLOOKUP(Opex_VE[[#This Row],[dia]],Forecast!I:I,Forecast!J:J)) -> 209000 | G16: =IFERROR(VLOOKUP(Opex_VE[[#This Row],[Fecha]],Historia!A:C,3,0),_xlfn.XLOOKUP(Opex_VE[[#This Row],[dia]],Forecast!I:I,Forecast!K:K)) -> 83600 | H16: =+Opex_VE[[#This Row],[MG]]-Opex_VE[[#This Row],[Opex]] -> -67511.111 | I16: =IFERROR(VLOOKUP(Opex_VE[[#This Row],[Fecha]],Historia!A:D,4,0),"Forecast") -> Histórico | J16: =+K16/0.4 -> 377777.78 | K16: =+Opex_VE[[#This Row],[Arriendo]]+Opex_VE[[#This Row],[Servicios publicos]]+Opex_VE[[#This Row],[Nomina]] -> 151111.11 | L16: =+VLOOKUP(Opex_VE[[#This Row],[Fecha]],Opex!$B:$Y,OPEX_SALES!L$1,1) -> 61111.111 | M16: =+SUM(Opex_VE[[#This Row],[Internet]:[Electricidad]]) -> 0 | N16: =+VLOOKUP(Opex_VE[[#This Row],[Fecha]],Opex!$B:$Y,OPEX_SALES!N$1,1) -> 0 | O16: =+VLOOKUP(Opex_VE[[#This Row],[Fecha]],Opex!$B:$Y,OPEX_SALES!O$1,1) -> 0 | P16: =+VLOOKUP(Opex_VE[[#This Row],[Fecha]],Opex!$B:$Y,OPEX_SALES!P$1,1) -> 0 | Q16: =+VLOOKUP(Opex_VE[[#This Row],[Fecha]],Opex!$B:$Y,OPEX_SALES!Q$1,1) -> 0 | R16: =+SUM(Opex_VE[[#This Row],[Cajero]:[Domiciliario]]) -> 90000 | S16: 70000 | T16: 20000 | U16: 0
A17: 46080 | B17: 1 | C17: =+TEXT(Opex_VE[[#This Row],[Fecha]],"ddd") -> vie | E17: B) Viernes | F17: =IFERROR(VLOOKUP(Opex_VE[[#This Row],[Fecha]],Historia!A:B,2,0),_xlfn.XLOOKUP(Opex_VE[[#This Row],[dia]],Forecast!I:I,Forecast!J:J)) -> 248500 | G17: =IFERROR(VLOOKUP(Opex_VE[[#This Row],[Fecha]],Historia!A:C,3,0),_xlfn.XLOOKUP(Opex_VE[[#This Row],[dia]],Forecast!I:I,Forecast!K:K)) -> 99400 | H17: =+Opex_VE[[#This Row],[MG]]-Opex_VE[[#This Row],[Opex]] -> -51711.111 | I17: =IFERROR(VLOOKUP(Opex_VE[[#This Row],[Fecha]],Historia!A:D,4,0),"Forecast") -> Histórico | J17: =+K17/0.4 -> 377777.78 | K17: =+Opex_VE[[#This Row],[Arriendo]]+Opex_VE[[#This Row],[Servicios publicos]]+Opex_VE[[#This Row],[Nomina]] -> 151111.11 | L17: =+VLOOKUP(Opex_VE[[#This Row],[Fecha]],Opex!$B:$Y,OPEX_SALES!L$1,1) -> 61111.111 | M17: =+SUM(Opex_VE[[#This Row],[Internet]:[Electricidad]]) -> 0 | N17: =+VLOOKUP(Opex_VE[[#This Row],[Fecha]],Opex!$B:$Y,OPEX_SALES!N$1,1) -> 0 | O17: =+VLOOKUP(Opex_VE[[#This Row],[Fecha]],Opex!$B:$Y,OPEX_SALES!O$1,1) -> 0 | P17: =+VLOOKUP(Opex_VE[[#This Row],[Fecha]],Opex!$B:$Y,OPEX_SALES!P$1,1) -> 0 | Q17: =+VLOOKUP(Opex_VE[[#This Row],[Fecha]],Opex!$B:$Y,OPEX_SALES!Q$1,1) -> 0 | R17: =+SUM(Opex_VE[[#This Row],[Cajero]:[Domiciliario]]) -> 90000 | S17: 70000 | T17: 20000 | U17: 0
A18: 46081 | B18: 1 | C18: =+TEXT(Opex_VE[[#This Row],[Fecha]],"ddd") -> sáb | E18: C) Sábado | F18: =IFERROR(VLOOKUP(Opex_VE[[#This Row],[Fecha]],Historia!A:B,2,0),_xlfn.XLOOKUP(Opex_VE[[#This Row],[dia]],Forecast!I:I,Forecast!J:J)) -> 504000 | G18: =IFERROR(VLOOKUP(Opex_VE[[#This Row],[Fecha]],Historia!A:C,3,0),_xlfn.XLOOKUP(Opex_VE[[#This Row],[dia]],Forecast!I:I,Forecast!K:K)) -> 201600 | H18: =+Opex_VE[[#This Row],[MG]]-Opex_VE[[#This Row],[Opex]] -> 50488.889 | I18: =IFERROR(VLOOKUP(Opex_VE[[#This Row],[Fecha]],Historia!A:D,4,0),"Forecast") -> Histórico | J18: =+K18/0.4 -> 377777.78 | K18: =+Opex_VE[[#This Row],[Arriendo]]+Opex_VE[[#This Row],[Servicios publicos]]+Opex_VE[[#This Row],[Nomina]] -> 151111.11 | L18: =+VLOOKUP(Opex_VE[[#This Row],[Fecha]],Opex!$B:$Y,OPEX_SALES!L$1,1) -> 61111.111 | M18: =+SUM(Opex_VE[[#This Row],[Internet]:[Electricidad]]) -> 0 | N18: =+VLOOKUP(Opex_VE[[#This Row],[Fecha]],Opex!$B:$Y,OPEX_SALES!N$1,1) -> 0 | O18: =+VLOOKUP(Opex_VE[[#This Row],[Fecha]],Opex!$B:$Y,OPEX_SALES!O$1,1) -> 0 | P18: =+VLOOKUP(Opex_VE[[#This Row],[Fecha]],Opex!$B:$Y,OPEX_SALES!P$1,1) -> 0 | Q18: =+VLOOKUP(Opex_VE[[#This Row],[Fecha]],Opex!$B:$Y,OPEX_SALES!Q$1,1) -> 0 | R18: =+SUM(Opex_VE[[#This Row],[Cajero]:[Domiciliario]]) -> 90000 | S18: 70000 | T18: 20000 | U18: 0
A19: 46082 | B19: 1 | C19: =+TEXT(Opex_VE[[#This Row],[Fecha]],"ddd") -> dom | E19: D) Domingo | F19: =IFERROR(VLOOKUP(Opex_VE[[#This Row],[Fecha]],Historia!A:B,2,0),_xlfn.XLOOKUP(Opex_VE[[#This Row],[dia]],Forecast!I:I,Forecast!J:J)) -> 168750 | G19: =IFERROR(VLOOKUP(Opex_VE[[#This Row],[Fecha]],Historia!A:C,3,0),_xlfn.XLOOKUP(Opex_VE[[#This Row],[dia]],Forecast!I:I,Forecast!K:K)) -> 67500 | H19: =+Opex_VE[[#This Row],[MG]]-Opex_VE[[#This Row],[Opex]] -> 6388.8889 | I19: Histórico | J19: =+K19/0.4 -> 152777.78 | K19: =+Opex_VE[[#This Row],[Arriendo]]+Opex_VE[[#This Row],[Servicios publicos]]+Opex_VE[[#This Row],[Nomina]] -> 61111.111 | L19: =+VLOOKUP(Opex_VE[[#This Row],[Fecha]],Opex!$B:$Y,OPEX_SALES!L$1,1) -> 61111.111 | M19: =+SUM(Opex_VE[[#This Row],[Internet]:[Electricidad]]) -> 0 | N19: =+VLOOKUP(Opex_VE[[#This Row],[Fecha]],Opex!$B:$Y,OPEX_SALES!N$1,1) -> 0 | O19: =+VLOOKUP(Opex_VE[[#This Row],[Fecha]],Opex!$B:$Y,OPEX_SALES!O$1,1) -> 0 | P19: =+VLOOKUP(Opex_VE[[#This Row],[Fecha]],Opex!$B:$Y,OPEX_SALES!P$1,1) -> 0 | Q19: =+VLOOKUP(Opex_VE[[#This Row],[Fecha]],Opex!$B:$Y,OPEX_SALES!Q$1,1) -> 0 | R19: =+SUM(Opex_VE[[#This Row],[Cajero]:[Domiciliario]]) -> 0 | S19: 0 | T19: 0 | U19: 0
A20: 46083 | B20: =+B13+1 -> 2 | C20: =+TEXT(Opex_VE[[#This Row],[Fecha]],"ddd") -> lun | E20: A) Día hábil | F20: =IFERROR(VLOOKUP(Opex_VE[[#This Row],[Fecha]],Historia!A:B,2,0),_xlfn.XLOOKUP(Opex_VE[[#This Row],[dia]],Forecast!I:I,Forecast!J:J)) -> 60000 | G20: =IFERROR(VLOOKUP(Opex_VE[[#This Row],[Fecha]],Historia!A:C,3,0),_xlfn.XLOOKUP(Opex_VE[[#This Row],[dia]],Forecast!I:I,Forecast!K:K)) -> 24000 | H20: =+Opex_VE[[#This Row],[MG]]-Opex_VE[[#This Row],[Opex]] -> -57111.111 | I20: =IFERROR(VLOOKUP(Opex_VE[[#This Row],[Fecha]],Historia!A:D,4,0),"Forecast") -> Histórico | J20: =+K20/0.4 -> 202777.78 | K20: =+Opex_VE[[#This Row],[Arriendo]]+Opex_VE[[#This Row],[Servicios publicos]]+Opex_VE[[#This Row],[Nomina]] -> 81111.111 | L20: =+VLOOKUP(Opex_VE[[#This Row],[Fecha]],Opex!$B:$Y,OPEX_SALES!L$1,1) -> 61111.111 | M20: =+SUM(Opex_VE[[#This Row],[Internet]:[Electricidad]]) -> 0 | N20: =+VLOOKUP(Opex_VE[[#This Row],[Fecha]],Opex!$B:$Y,OPEX_SALES!N$1,1) -> 0 | O20: =+VLOOKUP(Opex_VE[[#This Row],[Fecha]],Opex!$B:$Y,OPEX_SALES!O$1,1) -> 0 | P20: =+VLOOKUP(Opex_VE[[#This Row],[Fecha]],Opex!$B:$Y,OPEX_SALES!P$1,1) -> 0 | Q20: =+VLOOKUP(Opex_VE[[#This Row],[Fecha]],Opex!$B:$Y,OPEX_SALES!Q$1,1) -> 0 | R20: =+SUM(Opex_VE[[#This Row],[Cajero]:[Domiciliario]]) -> 20000 | S20: 0 | T20: 20000 | U20: 0
A21: 46084 | B21: =+B14+1 -> 2 | C21: =+TEXT(Opex_VE[[#This Row],[Fecha]],"ddd") -> mar | E21: A) Día hábil | F21: =IFERROR(VLOOKUP(Opex_VE[[#This Row],[Fecha]],Historia!A:B,2,0),_xlfn.XLOOKUP(Opex_VE[[#This Row],[dia]],Forecast!I:I,Forecast!J:J)) -> 169000 | G21: =IFERROR(VLOOKUP(Opex_VE[[#This Row],[Fecha]],Historia!A:C,3,0),_xlfn.XLOOKUP(Opex_VE[[#This Row],[dia]],Forecast!I:I,Forecast!K:K)) -> 67600 | H21: =+Opex_VE[[#This Row],[MG]]-Opex_VE[[#This Row],[Opex]] -> -13511.111 | I21: =IFERROR(VLOOKUP(Opex_VE[[#This Row],[Fecha]],Historia!A:D,4,0),"Forecast") -> Histórico | J21: =+K21/0.4 -> 202777.78 | K21: =+Opex_VE[[#This Row],[Arriendo]]+Opex_VE[[#This Row],[Servicios publicos]]+Opex_VE[[#This Row],[Nomina]] -> 81111.111 | L21: =+VLOOKUP(Opex_VE[[#This Row],[Fecha]],Opex!$B:$Y,OPEX_SALES!L$1,1) -> 61111.111 | M21: =+SUM(Opex_VE[[#This Row],[Internet]:[Electricidad]]) -> 0 | N21: =+VLOOKUP(Opex_VE[[#This Row],[Fecha]],Opex!$B:$Y,OPEX_SALES!N$1,1) -> 0 | O21: =+VLOOKUP(Opex_VE[[#This Row],[Fecha]],Opex!$B:$Y,OPEX_SALES!O$1,1) -> 0 | P21: =+VLOOKUP(Opex_VE[[#This Row],[Fecha]],Opex!$B:$Y,OPEX_SALES!P$1,1) -> 0 | Q21: =+VLOOKUP(Opex_VE[[#This Row],[Fecha]],Opex!$B:$Y,OPEX_SALES!Q$1,1) -> 0 | R21: =+SUM(Opex_VE[[#This Row],[Cajero]:[Domiciliario]]) -> 20000 | S21: 0 | T21: 20000 | U21: 0
A22: 46085 | B22: =+B15+1 -> 2 | C22: =+TEXT(Opex_VE[[#This Row],[Fecha]],"ddd") -> mié | E22: A) Día hábil | F22: =IFERROR(VLOOKUP(Opex_VE[[#This Row],[Fecha]],Historia!A:B,2,0),_xlfn.XLOOKUP(Opex_VE[[#This Row],[dia]],Forecast!I:I,Forecast!J:J)) -> 344000 | G22: =IFERROR(VLOOKUP(Opex_VE[[#This Row],[Fecha]],Historia!A:C,3,0),_xlfn.XLOOKUP(Opex_VE[[#This Row],[dia]],Forecast!I:I,Forecast!K:K)) -> 137600 | H22: =+Opex_VE[[#This Row],[MG]]-Opex_VE[[#This Row],[Opex]] -> 56488.889 | I22: =IFERROR(VLOOKUP(Opex_VE[[#This Row],[Fecha]],Historia!A:D,4,0),"Forecast") -> Histórico | J22: =+K22/0.4 -> 202777.78 | K22: =+Opex_VE[[#This Row],[Arriendo]]+Opex_VE[[#This Row],[Servicios publicos]]+Opex_VE[[#This Row],[Nomina]] -> 81111.111 | L22: =+VLOOKUP(Opex_VE[[#This Row],[Fecha]],Opex!$B:$Y,OPEX_SALES!L$1,1) -> 61111.111 | M22: =+SUM(Opex_VE[[#This Row],[Internet]:[Electricidad]]) -> 0 | N22: =+VLOOKUP(Opex_VE[[#This Row],[Fecha]],Opex!$B:$Y,OPEX_SALES!N$1,1) -> 0 | O22: =+VLOOKUP(Opex_VE[[#This Row],[Fecha]],Opex!$B:$Y,OPEX_SALES!O$1,1) -> 0 | P22: =+VLOOKUP(Opex_VE[[#This Row],[Fecha]],Opex!$B:$Y,OPEX_SALES!P$1,1) -> 0 | Q22: =+VLOOKUP(Opex_VE[[#This Row],[Fecha]],Opex!$B:$Y,OPEX_SALES!Q$1,1) -> 0 | R22: =+SUM(Opex_VE[[#This Row],[Cajero]:[Domiciliario]]) -> 20000 | S22: 0 | T22: 20000 | U22: 0
A23: 46086 | B23: =+B16+1 -> 2 | C23: =+TEXT(Opex_VE[[#This Row],[Fecha]],"ddd") -> jue | E23: A) Día hábil | F23: =IFERROR(VLOOKUP(Opex_VE[[#This Row],[Fecha]],Historia!A:B,2,0),_xlfn.XLOOKUP(Opex_VE[[#This Row],[dia]],Forecast!I:I,Forecast!J:J)) -> 259000 | G23: =IFERROR(VLOOKUP(Opex_VE[[#This Row],[Fecha]],Historia!A:C,3,0),_xlfn.XLOOKUP(Opex_VE[[#This Row],[dia]],Forecast!I:I,Forecast!K:K)) -> 103600 | H23: =+Opex_VE[[#This Row],[MG]]-Opex_VE[[#This Row],[Opex]] -> 22488.889 | I23: =IFERROR(VLOOKUP(Opex_VE[[#This Row],[Fecha]],Historia!A:D,4,0),"Forecast") -> Histórico | J23: =+K23/0.4 -> 202777.78 | K23: =+Opex_VE[[#This Row],[Arriendo]]+Opex_VE[[#This Row],[Servicios publicos]]+Opex_VE[[#This Row],[Nomina]] -> 81111.111 | L23: =+VLOOKUP(Opex_VE[[#This Row],[Fecha]],Opex!$B:$Y,OPEX_SALES!L$1,1) -> 61111.111 | M23: =+SUM(Opex_VE[[#This Row],[Internet]:[Electricidad]]) -> 0 | N23: =+VLOOKUP(Opex_VE[[#This Row],[Fecha]],Opex!$B:$Y,OPEX_SALES!N$1,1) -> 0 | O23: =+VLOOKUP(Opex_VE[[#This Row],[Fecha]],Opex!$B:$Y,OPEX_SALES!O$1,1) -> 0 | P23: =+VLOOKUP(Opex_VE[[#This Row],[Fecha]],Opex!$B:$Y,OPEX_SALES!P$1,1) -> 0 | Q23: =+VLOOKUP(Opex_VE[[#This Row],[Fecha]],Opex!$B:$Y,OPEX_SALES!Q$1,1) -> 0 | R23: =+SUM(Opex_VE[[#This Row],[Cajero]:[Domiciliario]]) -> 20000 | S23: 0 | T23: 20000 | U23: 0
A24: 46087 | B24: =+B17+1 -> 2 | C24: =+TEXT(Opex_VE[[#This Row],[Fecha]],"ddd") -> vie | E24: E) Festivo | F24: =IFERROR(VLOOKUP(Opex_VE[[#This Row],[Fecha]],Historia!A:B,2,0),_xlfn.XLOOKUP(Opex_VE[[#This Row],[dia]],Forecast!I:I,Forecast!J:J)) -> 184566.67 | G24: =IFERROR(VLOOKUP(Opex_VE[[#This Row],[Fecha]],Historia!A:C,3,0),_xlfn.XLOOKUP(Opex_VE[[#This Row],[dia]],Forecast!I:I,Forecast!K:K)) -> 73826.667 | H24: =+Opex_VE[[#This Row],[MG]]-Opex_VE[[#This Row],[Opex]] -> 12715.556 | I24: =IFERROR(VLOOKUP(Opex_VE[[#This Row],[Fecha]],Historia!A:D,4,0),"Forecast") -> Forecast | J24: =+K24/0.4 -> 152777.78 | K24: =+Opex_VE[[#This Row],[Arriendo]]+Opex_VE[[#This Row],[Servicios publicos]]+Opex_VE[[#This Row],[Nomina]] -> 61111.111 | L24: =+VLOOKUP(Opex_VE[[#This Row],[Fecha]],Opex!$B:$Y,OPEX_SALES!L$1,1) -> 61111.111 | M24: =+SUM(Opex_VE[[#This Row],[Internet]:[Electricidad]]) -> 0 | N24: =+VLOOKUP(Opex_VE[[#This Row],[Fecha]],Opex!$B:$Y,OPEX_SALES!N$1,1) -> 0 | O24: =+VLOOKUP(Opex_VE[[#This Row],[Fecha]],Opex!$B:$Y,OPEX_SALES!O$1,1) -> 0 | P24: =+VLOOKUP(Opex_VE[[#This Row],[Fecha]],Opex!$B:$Y,OPEX_SALES!P$1,1) -> 0 | Q24: =+VLOOKUP(Opex_VE[[#This Row],[Fecha]],Opex!$B:$Y,OPEX_SALES!Q$1,1) -> 0 | R24: =+SUM(Opex_VE[[#This Row],[Cajero]:[Domiciliario]]) -> 0 | S24: 0 | T24: 0 | U24: 0
A25: 46088 | B25: =+B18+1 -> 2 | C25: =+TEXT(Opex_VE[[#This Row],[Fecha]],"ddd") -> sáb | E25: C) Sábado | F25: =IFERROR(VLOOKUP(Opex_VE[[#This Row],[Fecha]],Historia!A:B,2,0),_xlfn.XLOOKUP(Opex_VE[[#This Row],[dia]],Forecast!I:I,Forecast!J:J)) -> 298500 | G25: =IFERROR(VLOOKUP(Opex_VE[[#This Row],[Fecha]],Historia!A:C,3,0),_xlfn.XLOOKUP(Opex_VE[[#This Row],[dia]],Forecast!I:I,Forecast!K:K)) -> 119400 | H25: =+Opex_VE[[#This Row],[MG]]-Opex_VE[[#This Row],[Opex]] -> -33711.111 | I25: Histórico | J25: =+K25/0.4 -> 382777.78 | K25: =+Opex_VE[[#This Row],[Arriendo]]+Opex_VE[[#This Row],[Servicios publicos]]+Opex_VE[[#This Row],[Nomina]] -> 153111.11 | L25: =+VLOOKUP(Opex_VE[[#This Row],[Fecha]],Opex!$B:$Y,OPEX_SALES!L$1,1) -> 61111.111 | M25: =+SUM(Opex_VE[[#This Row],[Internet]:[Electricidad]]) -> 0 | N25: =+VLOOKUP(Opex_VE[[#This Row],[Fecha]],Opex!$B:$Y,OPEX_SALES!N$1,1) -> 0 | O25: =+VLOOKUP(Opex_VE[[#This Row],[Fecha]],Opex!$B:$Y,OPEX_SALES!O$1,1) -> 0 | P25: =+VLOOKUP(Opex_VE[[#This Row],[Fecha]],Opex!$B:$Y,OPEX_SALES!P$1,1) -> 0 | Q25: =+VLOOKUP(Opex_VE[[#This Row],[Fecha]],Opex!$B:$Y,OPEX_SALES!Q$1,1) -> 0 | R25: =+SUM(Opex_VE[[#This Row],[Cajero]:[Domiciliario]]) -> 92000 | S25: 70000 | T25: 22000 | U25: 0
A26: 46089 | B26: =+B19+1 -> 2 | C26: =+TEXT(Opex_VE[[#This Row],[Fecha]],"ddd") -> dom | E26: D) Domingo | F26: =IFERROR(VLOOKUP(Opex_VE[[#This Row],[Fecha]],Historia!A:B,2,0),_xlfn.XLOOKUP(Opex_VE[[#This Row],[dia]],Forecast!I:I,Forecast!J:J)) -> 219500 | G26: =IFERROR(VLOOKUP(Opex_VE[[#This Row],[Fecha]],Historia!A:C,3,0),_xlfn.XLOOKUP(Opex_VE[[#This Row],[dia]],Forecast!I:I,Forecast!K:K)) -> 87800 | H26: =+Opex_VE[[#This Row],[MG]]-Opex_VE[[#This Row],[Opex]] -> -3311.1111 | I26: =IFERROR(VLOOKUP(Opex_VE[[#This Row],[Fecha]],Historia!A:D,4,0),"Forecast") -> Histórico | J26: =+K26/0.4 -> 227777.78 | K26: =+Opex_VE[[#This Row],[Arriendo]]+Opex_VE[[#This Row],[Servicios publicos]]+Opex_VE[[#This Row],[Nomina]] -> 91111.111 | L26: =+VLOOKUP(Opex_VE[[#This Row],[Fecha]],Opex!$B:$Y,OPEX_SALES!L$1,1) -> 61111.111 | M26: =+SUM(Opex_VE[[#This Row],[Internet]:[Electricidad]]) -> 0 | N26: =+VLOOKUP(Opex_VE[[#This Row],[Fecha]],Opex!$B:$Y,OPEX_SALES!N$1,1) -> 0 | O26: =+VLOOKUP(Opex_VE[[#This Row],[Fecha]],Opex!$B:$Y,OPEX_SALES!O$1,1) -> 0 | P26: =+VLOOKUP(Opex_VE[[#This Row],[Fecha]],Opex!$B:$Y,OPEX_SALES!P$1,1) -> 0 | Q26: =+VLOOKUP(Opex_VE[[#This Row],[Fecha]],Opex!$B:$Y,OPEX_SALES!Q$1,1) -> 0 | R26: =+SUM(Opex_VE[[#This Row],[Cajero]:[Domiciliario]]) -> 30000 | S26: 20000 | T26: 10000 | U26: 0
A27: 46090 | B27: =+B20+1 -> 3 | C27: =+TEXT(Opex_VE[[#This Row],[Fecha]],"ddd") -> lun | E27: A) Día hábil | F27: =IFERROR(VLOOKUP(Opex_VE[[#This Row],[Fecha]],Historia!A:B,2,0),_xlfn.XLOOKUP(Opex_VE[[#This Row],[dia]],Forecast!I:I,Forecast!J:J)) -> 248500 | G27: =IFERROR(VLOOKUP(Opex_VE[[#This Row],[Fecha]],Historia!A:C,3,0),_xlfn.XLOOKUP(Opex_VE[[#This Row],[dia]],Forecast!I:I,Forecast!K:K)) -> 99400 | H27: =+Opex_VE[[#This Row],[MG]]-Opex_VE[[#This Row],[Opex]] -> -11711.111 | I27: =IFERROR(VLOOKUP(Opex_VE[[#This Row],[Fecha]],Historia!A:D,4,0),"Forecast") -> Histórico | J27: =+K27/0.4 -> 277777.78 | K27: =+Opex_VE[[#This Row],[Arriendo]]+Opex_VE[[#This Row],[Servicios publicos]]+Opex_VE[[#This Row],[Nomina]] -> 111111.11 | L27: =+VLOOKUP(Opex_VE[[#This Row],[Fecha]],Opex!$B:$Y,OPEX_SALES!L$1,1) -> 61111.111 | M27: =+SUM(Opex_VE[[#This Row],[Internet]:[Electricidad]]) -> 0 | N27: =+VLOOKUP(Opex_VE[[#This Row],[Fecha]],Opex!$B:$Y,OPEX_SALES!N$1,1) -> 0 | O27: =+VLOOKUP(Opex_VE[[#This Row],[Fecha]],Opex!$B:$Y,OPEX_SALES!O$1,1) -> 0 | P27: =+VLOOKUP(Opex_VE[[#This Row],[Fecha]],Opex!$B:$Y,OPEX_SALES!P$1,1) -> 0 | Q27: =+VLOOKUP(Opex_VE[[#This Row],[Fecha]],Opex!$B:$Y,OPEX_SALES!Q$1,1) -> 0 | R27: =+SUM(Opex_VE[[#This Row],[Cajero]:[Domiciliario]]) -> 50000 | S27: 30000 | T27: 20000 | U27: 0
A28: 46091 | B28: =+B21+1 -> 3 | C28: =+TEXT(Opex_VE[[#This Row],[Fecha]],"ddd") -> mar | E28: A) Día hábil | F28: =IFERROR(VLOOKUP(Opex_VE[[#This Row],[Fecha]],Historia!A:B,2,0),_xlfn.XLOOKUP(Opex_VE[[#This Row],[dia]],Forecast!I:I,Forecast!J:J)) -> 94000 | G28: =IFERROR(VLOOKUP(Opex_VE[[#This Row],[Fecha]],Historia!A:C,3,0),_xlfn.XLOOKUP(Opex_VE[[#This Row],[dia]],Forecast!I:I,Forecast!K:K)) -> 37600 | H28: =+Opex_VE[[#This Row],[MG]]-Opex_VE[[#This Row],[Opex]] -> -73511.111 | I28: =IFERROR(VLOOKUP(Opex_VE[[#This Row],[Fecha]],Historia!A:D,4,0),"Forecast") -> Histórico | J28: =+K28/0.4 -> 277777.78 | K28: =+Opex_VE[[#This Row],[Arriendo]]+Opex_VE[[#This Row],[Servicios publicos]]+Opex_VE[[#This Row],[Nomina]] -> 111111.11 | L28: =+VLOOKUP(Opex_VE[[#This Row],[Fecha]],Opex!$B:$Y,OPEX_SALES!L$1,1) -> 61111.111 | M28: =+SUM(Opex_VE[[#This Row],[Internet]:[Electricidad]]) -> 0 | N28: =+VLOOKUP(Opex_VE[[#This Row],[Fecha]],Opex!$B:$Y,OPEX_SALES!N$1,1) -> 0 | O28: =+VLOOKUP(Opex_VE[[#This Row],[Fecha]],Opex!$B:$Y,OPEX_SALES!O$1,1) -> 0 | P28: =+VLOOKUP(Opex_VE[[#This Row],[Fecha]],Opex!$B:$Y,OPEX_SALES!P$1,1) -> 0 | Q28: =+VLOOKUP(Opex_VE[[#This Row],[Fecha]],Opex!$B:$Y,OPEX_SALES!Q$1,1) -> 0 | R28: =+SUM(Opex_VE[[#This Row],[Cajero]:[Domiciliario]]) -> 50000 | S28: 30000 | T28: 20000 | U28: 0
A29: 46092 | B29: =+B22+1 -> 3 | C29: =+TEXT(Opex_VE[[#This Row],[Fecha]],"ddd") -> mié | E29: A) Día hábil | F29: =IFERROR(VLOOKUP(Opex_VE[[#This Row],[Fecha]],Historia!A:B,2,0),_xlfn.XLOOKUP(Opex_VE[[#This Row],[dia]],Forecast!I:I,Forecast!J:J)) -> 473500 | G29: =IFERROR(VLOOKUP(Opex_VE[[#This Row],[Fecha]],Historia!A:C,3,0),_xlfn.XLOOKUP(Opex_VE[[#This Row],[dia]],Forecast!I:I,Forecast!K:K)) -> 189400 | H29: =+Opex_VE[[#This Row],[MG]]-Opex_VE[[#This Row],[Opex]] -> 88288.889 | I29: =IFERROR(VLOOKUP(Opex_VE[[#This Row],[Fecha]],Historia!A:D,4,0),"Forecast") -> Histórico | J29: =+K29/0.4 -> 252777.78 | K29: =+Opex_VE[[#This Row],[Arriendo]]+Opex_VE[[#This Row],[Servicios publicos]]+Opex_VE[[#This Row],[Nomina]] -> 101111.11 | L29: =+VLOOKUP(Opex_VE[[#This Row],[Fecha]],Opex!$B:$Y,OPEX_SALES!L$1,1) -> 61111.111 | M29: =+SUM(Opex_VE[[#This Row],[Internet]:[Electricidad]]) -> 0 | N29: =+VLOOKUP(Opex_VE[[#This Row],[Fecha]],Opex!$B:$Y,OPEX_SALES!N$1,1) -> 0 | O29: =+VLOOKUP(Opex_VE[[#This Row],[Fecha]],Opex!$B:$Y,OPEX_SALES!O$1,1) -> 0 | P29: =+VLOOKUP(Opex_VE[[#This Row],[Fecha]],Opex!$B:$Y,OPEX_SALES!P$1,1) -> 0 | Q29: =+VLOOKUP(Opex_VE[[#This Row],[Fecha]],Opex!$B:$Y,OPEX_SALES!Q$1,1) -> 0 | R29: =+SUM(Opex_VE[[#This Row],[Cajero]:[Domiciliario]]) -> 40000 | S29: 20000 | T29: 20000 | U29: 0
A30: 46093 | B30: =+B23+1 -> 3 | C30: =+TEXT(Opex_VE[[#This Row],[Fecha]],"ddd") -> jue | E30: A) Día hábil | F30: =IFERROR(VLOOKUP(Opex_VE[[#This Row],[Fecha]],Historia!A:B,2,0),_xlfn.XLOOKUP(Opex_VE[[#This Row],[dia]],Forecast!I:I,Forecast!J:J)) -> 243000 | G30: =IFERROR(VLOOKUP(Opex_VE[[#This Row],[Fecha]],Historia!A:C,3,0),_xlfn.XLOOKUP(Opex_VE[[#This Row],[dia]],Forecast!I:I,Forecast!K:K)) -> 97200 | H30: =+Opex_VE[[#This Row],[MG]]-Opex_VE[[#This Row],[Opex]] -> -13911.111 | I30: =IFERROR(VLOOKUP(Opex_VE[[#This Row],[Fecha]],Historia!A:D,4,0),"Forecast") -> Histórico | J30: =+K30/0.4 -> 277777.78 | K30: =+Opex_VE[[#This Row],[Arriendo]]+Opex_VE[[#This Row],[Servicios publicos]]+Opex_VE[[#This Row],[Nomina]] -> 111111.11 | L30: =+VLOOKUP(Opex_VE[[#This Row],[Fecha]],Opex!$B:$Y,OPEX_SALES!L$1,1) -> 61111.111 | M30: =+SUM(Opex_VE[[#This Row],[Internet]:[Electricidad]]) -> 0 | N30: =+VLOOKUP(Opex_VE[[#This Row],[Fecha]],Opex!$B:$Y,OPEX_SALES!N$1,1) -> 0 | O30: =+VLOOKUP(Opex_VE[[#This Row],[Fecha]],Opex!$B:$Y,OPEX_SALES!O$1,1) -> 0 | P30: =+VLOOKUP(Opex_VE[[#This Row],[Fecha]],Opex!$B:$Y,OPEX_SALES!P$1,1) -> 0 | Q30: =+VLOOKUP(Opex_VE[[#This Row],[Fecha]],Opex!$B:$Y,OPEX_SALES!Q$1,1) -> 0 | R30: =+SUM(Opex_VE[[#This Row],[Cajero]:[Domiciliario]]) -> 50000 | S30: 30000 | T30: 20000 | U30: 0
A31: 46094 | B31: =+B24+1 -> 3 | C31: =+TEXT(Opex_VE[[#This Row],[Fecha]],"ddd") -> vie | E31: B) Viernes | F31: =IFERROR(VLOOKUP(Opex_VE[[#This Row],[Fecha]],Historia!A:B,2,0),_xlfn.XLOOKUP(Opex_VE[[#This Row],[dia]],Forecast!I:I,Forecast!J:J)) -> 132500 | G31: =IFERROR(VLOOKUP(Opex_VE[[#This Row],[Fecha]],Historia!A:C,3,0),_xlfn.XLOOKUP(Opex_VE[[#This Row],[dia]],Forecast!I:I,Forecast!K:K)) -> 53000 | H31: =+Opex_VE[[#This Row],[MG]]-Opex_VE[[#This Row],[Opex]] -> -58111.111 | I31: =IFERROR(VLOOKUP(Opex_VE[[#This Row],[Fecha]],Historia!A:D,4,0),"Forecast") -> Histórico | J31: =+K31/0.4 -> 277777.78 | K31: =+Opex_VE[[#This Row],[Arriendo]]+Opex_VE[[#This Row],[Servicios publicos]]+Opex_VE[[#This Row],[Nomina]] -> 111111.11 | L31: =+VLOOKUP(Opex_VE[[#This Row],[Fecha]],Opex!$B:$Y,OPEX_SALES!L$1,1) -> 61111.111 | M31: =+SUM(Opex_VE[[#This Row],[Internet]:[Electricidad]]) -> 0 | N31: =+VLOOKUP(Opex_VE[[#This Row],[Fecha]],Opex!$B:$Y,OPEX_SALES!N$1,1) -> 0 | O31: =+VLOOKUP(Opex_VE[[#This Row],[Fecha]],Opex!$B:$Y,OPEX_SALES!O$1,1) -> 0 | P31: =+VLOOKUP(Opex_VE[[#This Row],[Fecha]],Opex!$B:$Y,OPEX_SALES!P$1,1) -> 0 | Q31: =+VLOOKUP(Opex_VE[[#This Row],[Fecha]],Opex!$B:$Y,OPEX_SALES!Q$1,1) -> 0 | R31: =+SUM(Opex_VE[[#This Row],[Cajero]:[Domiciliario]]) -> 50000 | S31: 30000 | T31: 20000 | U31: 0
A32: 46095 | B32: =+B25+1 -> 3 | C32: =+TEXT(Opex_VE[[#This Row],[Fecha]],"ddd") -> sáb | E32: C) Sábado | F32: =IFERROR(VLOOKUP(Opex_VE[[#This Row],[Fecha]],Historia!A:B,2,0),_xlfn.XLOOKUP(Opex_VE[[#This Row],[dia]],Forecast!I:I,Forecast!J:J)) -> 392500 | G32: =IFERROR(VLOOKUP(Opex_VE[[#This Row],[Fecha]],Historia!A:C,3,0),_xlfn.XLOOKUP(Opex_VE[[#This Row],[dia]],Forecast!I:I,Forecast!K:K)) -> 157000 | H32: =+Opex_VE[[#This Row],[MG]]-Opex_VE[[#This Row],[Opex]] -> 45888.889 | I32: =IFERROR(VLOOKUP(Opex_VE[[#This Row],[Fecha]],Historia!A:D,4,0),"Forecast") -> Histórico | J32: =+K32/0.4 -> 277777.78 | K32: =+Opex_VE[[#This Row],[Arriendo]]+Opex_VE[[#This Row],[Servicios publicos]]+Opex_VE[[#This Row],[Nomina]] -> 111111.11 | L32: =+VLOOKUP(Opex_VE[[#This Row],[Fecha]],Opex!$B:$Y,OPEX_SALES!L$1,1) -> 61111.111 | M32: =+SUM(Opex_VE[[#This Row],[Internet]:[Electricidad]]) -> 0 | N32: =+VLOOKUP(Opex_VE[[#This Row],[Fecha]],Opex!$B:$Y,OPEX_SALES!N$1,1) -> 0 | O32: =+VLOOKUP(Opex_VE[[#This Row],[Fecha]],Opex!$B:$Y,OPEX_SALES!O$1,1) -> 0 | P32: =+VLOOKUP(Opex_VE[[#This Row],[Fecha]],Opex!$B:$Y,OPEX_SALES!P$1,1) -> 0 | Q32: =+VLOOKUP(Opex_VE[[#This Row],[Fecha]],Opex!$B:$Y,OPEX_SALES!Q$1,1) -> 0 | R32: =+SUM(Opex_VE[[#This Row],[Cajero]:[Domiciliario]]) -> 50000 | S32: 30000 | T32: 20000 | U32: 0
A33: 46096 | B33: =+B26+1 -> 3 | C33: =+TEXT(Opex_VE[[#This Row],[Fecha]],"ddd") -> dom | E33: D) Domingo | F33: =IFERROR(VLOOKUP(Opex_VE[[#This Row],[Fecha]],Historia!A:B,2,0),_xlfn.XLOOKUP(Opex_VE[[#This Row],[dia]],Forecast!I:I,Forecast!J:J)) -> 118000 | G33: =IFERROR(VLOOKUP(Opex_VE[[#This Row],[Fecha]],Historia!A:C,3,0),_xlfn.XLOOKUP(Opex_VE[[#This Row],[dia]],Forecast!I:I,Forecast!K:K)) -> 47200 | H33: =+Opex_VE[[#This Row],[MG]]-Opex_VE[[#This Row],[Opex]] -> -80678.967 | I33: =IFERROR(VLOOKUP(Opex_VE[[#This Row],[Fecha]],Historia!A:D,4,0),"Forecast") -> Histórico | J33: =+K33/0.4 -> 319697.42 | K33: =+Opex_VE[[#This Row],[Arriendo]]+Opex_VE[[#This Row],[Servicios publicos]]+Opex_VE[[#This Row],[Nomina]] -> 127878.97 | L33: =+VLOOKUP(Opex_VE[[#This Row],[Fecha]],Opex!$B:$Y,OPEX_SALES!L$1,1) -> 55000 | M33: =+SUM(Opex_VE[[#This Row],[Internet]:[Electricidad]]) -> 22878.967 | N33: =+VLOOKUP(Opex_VE[[#This Row],[Fecha]],Opex!$B:$Y,OPEX_SALES!N$1,1) -> 0 | O33: =+VLOOKUP(Opex_VE[[#This Row],[Fecha]],Opex!$B:$Y,OPEX_SALES!O$1,1) -> 8243.9667 | P33: =+VLOOKUP(Opex_VE[[#This Row],[Fecha]],Opex!$B:$Y,OPEX_SALES!P$1,1) -> 4000 | Q33: =+VLOOKUP(Opex_VE[[#This Row],[Fecha]],Opex!$B:$Y,OPEX_SALES!Q$1,1) -> 10635 | R33: =+SUM(Opex_VE[[#This Row],[Cajero]:[Domiciliario]]) -> 50000 | S33: 30000 | T33: 20000 | U33: 0
A34: 46097 | B34: =+B27+1 -> 4 | C34: =+TEXT(Opex_VE[[#This Row],[Fecha]],"ddd") -> lun | E34: A) Día hábil | F34: =IFERROR(VLOOKUP(Opex_VE[[#This Row],[Fecha]],Historia!A:B,2,0),_xlfn.XLOOKUP(Opex_VE[[#This Row],[dia]],Forecast!I:I,Forecast!J:J)) -> 124000 | G34: =IFERROR(VLOOKUP(Opex_VE[[#This Row],[Fecha]],Historia!A:C,3,0),_xlfn.XLOOKUP(Opex_VE[[#This Row],[dia]],Forecast!I:I,Forecast!K:K)) -> 49600 | H34: =+Opex_VE[[#This Row],[MG]]-Opex_VE[[#This Row],[Opex]] -> -78278.967 | I34: =IFERROR(VLOOKUP(Opex_VE[[#This Row],[Fecha]],Historia!A:D,4,0),"Forecast") -> Histórico | J34: =+K34/0.4 -> 319697.42 | K34: =+Opex_VE[[#This Row],[Arriendo]]+Opex_VE[[#This Row],[Servicios publicos]]+Opex_VE[[#This Row],[Nomina]] -> 127878.97 | L34: =+VLOOKUP(Opex_VE[[#This Row],[Fecha]],Opex!$B:$Y,OPEX_SALES!L$1,1) -> 55000 | M34: =+SUM(Opex_VE[[#This Row],[Internet]:[Electricidad]]) -> 22878.967 | N34: =+VLOOKUP(Opex_VE[[#This Row],[Fecha]],Opex!$B:$Y,OPEX_SALES!N$1,1) -> 0 | O34: =+VLOOKUP(Opex_VE[[#This Row],[Fecha]],Opex!$B:$Y,OPEX_SALES!O$1,1) -> 8243.9667 | P34: =+VLOOKUP(Opex_VE[[#This Row],[Fecha]],Opex!$B:$Y,OPEX_SALES!P$1,1) -> 4000 | Q34: =+VLOOKUP(Opex_VE[[#This Row],[Fecha]],Opex!$B:$Y,OPEX_SALES!Q$1,1) -> 10635 | R34: =+SUM(Opex_VE[[#This Row],[Cajero]:[Domiciliario]]) -> 50000 | S34: 30000 | T34: 20000 | U34: 0
A35: 46098 | B35: =+B28+1 -> 4 | C35: =+TEXT(Opex_VE[[#This Row],[Fecha]],"ddd") -> mar | E35: A) Día hábil | F35: =IFERROR(VLOOKUP(Opex_VE[[#This Row],[Fecha]],Historia!A:B,2,0),_xlfn.XLOOKUP(Opex_VE[[#This Row],[dia]],Forecast!I:I,Forecast!J:J)) -> 314000 | G35: =IFERROR(VLOOKUP(Opex_VE[[#This Row],[Fecha]],Historia!A:C,3,0),_xlfn.XLOOKUP(Opex_VE[[#This Row],[dia]],Forecast!I:I,Forecast!K:K)) -> 125600 | H35: =+Opex_VE[[#This Row],[MG]]-Opex_VE[[#This Row],[Opex]] -> -2278.9667 | I35: =IFERROR(VLOOKUP(Opex_VE[[#This Row],[Fecha]],Historia!A:D,4,0),"Forecast") -> Histórico | J35: =+K35/0.4 -> 319697.42 | K35: =+Opex_VE[[#This Row],[Arriendo]]+Opex_VE[[#This Row],[Servicios publicos]]+Opex_VE[[#This Row],[Nomina]] -> 127878.97 | L35: =+VLOOKUP(Opex_VE[[#This Row],[Fecha]],Opex!$B:$Y,OPEX_SALES!L$1,1) -> 55000 | M35: =+SUM(Opex_VE[[#This Row],[Internet]:[Electricidad]]) -> 22878.967 | N35: =+VLOOKUP(Opex_VE[[#This Row],[Fecha]],Opex!$B:$Y,OPEX_SALES!N$1,1) -> 0 | O35: =+VLOOKUP(Opex_VE[[#This Row],[Fecha]],Opex!$B:$Y,OPEX_SALES!O$1,1) -> 8243.9667 | P35: =+VLOOKUP(Opex_VE[[#This Row],[Fecha]],Opex!$B:$Y,OPEX_SALES!P$1,1) -> 4000 | Q35: =+VLOOKUP(Opex_VE[[#This Row],[Fecha]],Opex!$B:$Y,OPEX_SALES!Q$1,1) -> 10635 | R35: =+SUM(Opex_VE[[#This Row],[Cajero]:[Domiciliario]]) -> 50000 | S35: 30000 | T35: 20000 | U35: 0
A36: 46099 | B36: =+B29+1 -> 4 | C36: =+TEXT(Opex_VE[[#This Row],[Fecha]],"ddd") -> mié | E36: A) Día hábil | F36: =IFERROR(VLOOKUP(Opex_VE[[#This Row],[Fecha]],Historia!A:B,2,0),_xlfn.XLOOKUP(Opex_VE[[#This Row],[dia]],Forecast!I:I,Forecast!J:J)) -> 149000 | G36: =IFERROR(VLOOKUP(Opex_VE[[#This Row],[Fecha]],Historia!A:C,3,0),_xlfn.XLOOKUP(Opex_VE[[#This Row],[dia]],Forecast!I:I,Forecast!K:K)) -> 59600 | H36: =+Opex_VE[[#This Row],[MG]]-Opex_VE[[#This Row],[Opex]] -> -68278.967 | I36: =IFERROR(VLOOKUP(Opex_VE[[#This Row],[Fecha]],Historia!A:D,4,0),"Forecast") -> Histórico | J36: =+K36/0.4 -> 319697.42 | K36: =+Opex_VE[[#This Row],[Arriendo]]+Opex_VE[[#This Row],[Servicios publicos]]+Opex_VE[[#This Row],[Nomina]] -> 127878.97 | L36: =+VLOOKUP(Opex_VE[[#This Row],[Fecha]],Opex!$B:$Y,OPEX_SALES!L$1,1) -> 55000 | M36: =+SUM(Opex_VE[[#This Row],[Internet]:[Electricidad]]) -> 22878.967 | N36: =+VLOOKUP(Opex_VE[[#This Row],[Fecha]],Opex!$B:$Y,OPEX_SALES!N$1,1) -> 0 | O36: =+VLOOKUP(Opex_VE[[#This Row],[Fecha]],Opex!$B:$Y,OPEX_SALES!O$1,1) -> 8243.9667 | P36: =+VLOOKUP(Opex_VE[[#This Row],[Fecha]],Opex!$B:$Y,OPEX_SALES!P$1,1) -> 4000 | Q36: =+VLOOKUP(Opex_VE[[#This Row],[Fecha]],Opex!$B:$Y,OPEX_SALES!Q$1,1) -> 10635 | R36: =+SUM(Opex_VE[[#This Row],[Cajero]:[Domiciliario]]) -> 50000 | S36: 30000 | T36: 20000 | U36: 0
A37: 46100 | B37: =+B30+1 -> 4 | C37: =+TEXT(Opex_VE[[#This Row],[Fecha]],"ddd") -> jue | E37: A) Día hábil | F37: =IFERROR(VLOOKUP(Opex_VE[[#This Row],[Fecha]],Historia!A:B,2,0),_xlfn.XLOOKUP(Opex_VE[[#This Row],[dia]],Forecast!I:I,Forecast!J:J)) -> 388900 | G37: =IFERROR(VLOOKUP(Opex_VE[[#This Row],[Fecha]],Historia!A:C,3,0),_xlfn.XLOOKUP(Opex_VE[[#This Row],[dia]],Forecast!I:I,Forecast!K:K)) -> 155560 | H37: =+Opex_VE[[#This Row],[MG]]-Opex_VE[[#This Row],[Opex]] -> 27681.033 | I37: =IFERROR(VLOOKUP(Opex_VE[[#This Row],[Fecha]],Historia!A:D,4,0),"Forecast") -> Histórico | J37: =+K37/0.4 -> 319697.42 | K37: =+Opex_VE[[#This Row],[Arriendo]]+Opex_VE[[#This Row],[Servicios publicos]]+Opex_VE[[#This Row],[Nomina]] -> 127878.97 | L37: =+VLOOKUP(Opex_VE[[#This Row],[Fecha]],Opex!$B:$Y,OPEX_SALES!L$1,1) -> 55000 | M37: =+SUM(Opex_VE[[#This Row],[Internet]:[Electricidad]]) -> 22878.967 | N37: =+VLOOKUP(Opex_VE[[#This Row],[Fecha]],Opex!$B:$Y,OPEX_SALES!N$1,1) -> 0 | O37: =+VLOOKUP(Opex_VE[[#This Row],[Fecha]],Opex!$B:$Y,OPEX_SALES!O$1,1) -> 8243.9667 | P37: =+VLOOKUP(Opex_VE[[#This Row],[Fecha]],Opex!$B:$Y,OPEX_SALES!P$1,1) -> 4000 | Q37: =+VLOOKUP(Opex_VE[[#This Row],[Fecha]],Opex!$B:$Y,OPEX_SALES!Q$1,1) -> 10635 | R37: =+SUM(Opex_VE[[#This Row],[Cajero]:[Domiciliario]]) -> 50000 | S37: 30000 | T37: 20000 | U37: 0
... A369: 46432 | B369: =+B362+1 -> 51 | C369: =+TEXT(Opex_VE[[#This Row],[Fecha]],"ddd") -> dom | E369: D) Domingo | F369: =IFERROR(VLOOKUP(Opex_VE[[#This Row],[Fecha]],Historia!A:B,2,0),_xlfn.XLOOKUP(Opex_VE[[#This Row],[dia]],Forecast!I:I,Forecast!J:J)) -> 168750 | G369: =IFERROR(VLOOKUP(Opex_VE[[#This Row],[Fecha]],Historia!A:C,3,0),_xlfn.XLOOKUP(Opex_VE[[#This Row],[dia]],Forecast!I:I,Forecast!K:K)) -> 67500 | H369: =+Opex_VE[[#This Row],[MG]]-Opex_VE[[#This Row],[Opex]] -> -153878.97 | I369: =IFERROR(VLOOKUP(Opex_VE[[#This Row],[Fecha]],Historia!A:D,4,0),"Forecast") -> Forecast | J369: =+K369/0.4 -> 553447.42 | K369: =+Opex_VE[[#This Row],[Arriendo]]+Opex_VE[[#This Row],[Servicios publicos]]+Opex_VE[[#This Row],[Nomina]] -> 221378.97 | L369: =+VLOOKUP(Opex_VE[[#This Row],[Fecha]],Opex!$B:$Y,OPEX_SALES!L$1,1) -> 55000 | M369: =+SUM(Opex_VE[[#This Row],[Internet]:[Electricidad]]) -> 26378.967 | N369: =+VLOOKUP(Opex_VE[[#This Row],[Fecha]],Opex!$B:$Y,OPEX_SALES!N$1,1) -> 3500 | O369: =+VLOOKUP(Opex_VE[[#This Row],[Fecha]],Opex!$B:$Y,OPEX_SALES!O$1,1) -> 8243.9667 | P369: =+VLOOKUP(Opex_VE[[#This Row],[Fecha]],Opex!$B:$Y,OPEX_SALES!P$1,1) -> 4000 | Q369: =+VLOOKUP(Opex_VE[[#This Row],[Fecha]],Opex!$B:$Y,OPEX_SALES!Q$1,1) -> 10635 | R369: =+SUM(Opex_VE[[#This Row],[Cajero]:[Domiciliario]]) -> 140000 | S369: 70000 | T369: 70000 | U369: 0

Sheet Opex
B1: 1 | C1: =+B1+1 -> 2 | D1: =+C1+1 -> 3 | E1: =+D1+1 -> 4 | F1: =+E1+1 -> 5 | G1: =+F1+1 -> 6 | H1: =+G1+1 -> 7 | I1: =+H1+1 -> 8 | J1: =+I1+1 -> 9 | ... W1: =+V1+1 -> 22 | X1: 23 | Y1: 24
A2: Tipo | B2: Fecha | C2: fecha_fin | D2: Mes | E2: Cuentas x Pagar | F2: Día C x P | G2: Arriendo | H2: No. Días Arriendo | I2: Día Arriendo | J2: Gas | K2: No. Días Gas | L2: Consumo (m3) | M2: Costo prom. Gas | N2: Día Gas | O2: Agua | P2: Dìa Agua | Q2: Energia | R2: Financiació Energia | S2: No. Días Energia | T2: Consumo (KhW | U2: Costo prom. Energia | V2: Fecha corte enega | W2: Día Energia | X2: Internet | Y2: Día internet
A3: Histórico | B3: 46068 | C3: 46095 | D3: =+TEXT(B3,"mmmm") -> febrero | F3: =+Opex[[#This Row],[Cuentas x Pagar]]/31 -> 0 | G3: 1650000 | H3: =+Opex[[#This Row],[fecha_fin]]-Opex[[#This Row],[Fecha]] -> 27 | I3: =IFERROR(Opex[[#This Row],[Arriendo]]/Opex[[#This Row],[No. Días Arriendo]],0) -> 61111.111 | J3: 0 | K3: 0 | L3: 0 | M3: =IFERROR(Opex[[#This Row],[Gas]]/Opex[[#This Row],[Consumo (m3)]],0) -> 0 | N3: =IFERROR(Opex[[#This Row],[Gas]]/Opex[[#This Row],[No. Días Arriendo]],0) -> 0 | P3: =IFERROR(Opex[[#This Row],[Agua]]/Opex[[#This Row],[No. Días Arriendo]],0) -> 0 | S3: =+Z3 -> 0 | U3: =IFERROR(Opex[[#This Row],[Energia]]/Opex[[#This Row],[Consumo (KhW]],0) -> 0 | W3: =IFERROR(Opex[[#This Row],[Energia]]/Opex[[#This Row],[No. Días Arriendo]],0) -> 0 | X3: 0 | Y3: =+Opex[[#This Row],[Internet]]/Opex[[#This Row],[No. Días Arriendo]] -> 0
A4: Forecast | B4: =+C3+1 -> 46096 | C4: 46126 | D4: =+TEXT(B4,"mmmm") -> marzo | F4: =+Opex[[#This Row],[Cuentas x Pagar]]/31 -> 0 | G4: 1650000 | H4: =+Opex[[#This Row],[fecha_fin]]-Opex[[#This Row],[Fecha]] -> 30 | I4: =IFERROR(Opex[[#This Row],[Arriendo]]/Opex[[#This Row],[No. Días Arriendo]],0) -> 55000 | J4: 247319 | K4: =+#REF! -> #REF! | L4: =+AVERAGE(#REF!/#REF!,#REF!/#REF!,#REF!/#REF!)*Opex[[#This Row],[No. Días Gas]] -> #REF! | M4: =+AVERAGE(#REF!) -> #REF! | N4: =IFERROR(Opex[[#This Row],[Gas]]/Opex[[#This Row],[No. Días Arriendo]],0) -> 8243.9667 | O4: 120000 | P4: =IFERROR(Opex[[#This Row],[Agua]]/Opex[[#This Row],[No. Días Arriendo]],0) -> 4000 | Q4: 319050 | R4: 264247 | S4: =+#REF! -> #REF! | T4: =+AVERAGE(#REF!/#REF!,#REF!/#REF!) -> #REF! | U4: =+AVERAGE(#REF!) -> #REF! | V4: Nd | W4: =IFERROR(Opex[[#This Row],[Energia]]/Opex[[#This Row],[No. Días Arriendo]],0) -> 10635 | X4: 0 | Y4: =+Opex[[#This Row],[Internet]]/Opex[[#This Row],[No. Días Arriendo]] -> 0
A5: Forecast | B5: =+C4+1 -> 46127 | C5: 46156 | D5: =+TEXT(B5,"mmmm") -> abril | F5: =+Opex[[#This Row],[Cuentas x Pagar]]/31 -> 0 | G5: 1650000 | H5: =+Opex[[#This Row],[fecha_fin]]-Opex[[#This Row],[Fecha]] -> 29 | I5: =IFERROR(Opex[[#This Row],[Arriendo]]/Opex[[#This Row],[No. Días Arriendo]],0) -> 56896.552 | J5: 247319 | K5: =+H4 -> 30 | L5: =+AVERAGE(#REF!/#REF!,#REF!/#REF!,L4/K4)*Opex[[#This Row],[No. Días Gas]] -> #REF! | M5: =+AVERAGE(M4:M4) -> #REF! | N5: =IFERROR(Opex[[#This Row],[Gas]]/Opex[[#This Row],[No. Días Arriendo]],0) -> 8528.2414 | O5: 120000 | P5: =IFERROR(Opex[[#This Row],[Agua]]/Opex[[#This Row],[No. Días Arriendo]],0) -> 4137.931 | Q5: =+AVERAGE(Q4:Q4) -> 319050 | R5: 264247 | S5: =+#REF! -> #REF! | T5: =+AVERAGE(#REF!/#REF!,#REF!/#REF!,#REF!/U4) -> #REF! | U5: =+AVERAGE(U4:U4) -> #REF! | V5: Nd | W5: =IFERROR(Opex[[#This Row],[Energia]]/Opex[[#This Row],[No. Días Arriendo]],0) -> 11001.724 | X5: 105000 | Y5: =+Opex[[#This Row],[Internet]]/Opex[[#This Row],[No. Días Arriendo]] -> 3620.6897
A6: Forecast | B6: =+C5+1 -> 46157 | C6: 46187 | D6: =+TEXT(B6,"mmmm") -> mayo | F6: =+Opex[[#This Row],[Cuentas x Pagar]]/31 -> 0 | G6: 1650000 | H6: =+Opex[[#This Row],[fecha_fin]]-Opex[[#This Row],[Fecha]] -> 30 | I6: =IFERROR(Opex[[#This Row],[Arriendo]]/Opex[[#This Row],[No. Días Arriendo]],0) -> 55000 | J6: 247319 | K6: =+H5 -> 29 | L6: =+AVERAGE(#REF!/#REF!,L4/K4,L5/K5)*Opex[[#This Row],[No. Días Gas]] -> #REF! | M6: =+AVERAGE(M4:M5) -> #REF! | N6: =IFERROR(Opex[[#This Row],[Gas]]/Opex[[#This Row],[No. Días Arriendo]],0) -> 8243.9667 | O6: 120000 | P6: =IFERROR(Opex[[#This Row],[Agua]]/Opex[[#This Row],[No. Días Arriendo]],0) -> 4000 | Q6: =+AVERAGE(Q4:Q5) -> 319050 | R6: 264247 | S6: =+#REF! -> #REF! | T6: =+AVERAGE(#REF!/#REF!,#REF!/U4,#REF!/U5) -> #REF! | U6: =+AVERAGE(U4:U5) -> #REF! | V6: Nd | W6: =IFERROR(Opex[[#This Row],[Energia]]/Opex[[#This Row],[No. Días Arriendo]],0) -> 10635 | X6: 105000 | Y6: =+Opex[[#This Row],[Internet]]/Opex[[#This Row],[No. Días Arriendo]] -> 3500
A7: Forecast | B7: =+C6+1 -> 46188 | C7: 46217 | D7: =+TEXT(B7,"mmmm") -> junio | F7: =+Opex[[#This Row],[Cuentas x Pagar]]/31 -> 0 | G7: 1650000 | H7: =+Opex[[#This Row],[fecha_fin]]-Opex[[#This Row],[Fecha]] -> 29 | I7: =IFERROR(Opex[[#This Row],[Arriendo]]/Opex[[#This Row],[No. Días Arriendo]],0) -> 56896.552 | J7: 247319 | K7: =+H6 -> 30 | L7: =+AVERAGE(L4/K4,L5/K5,L6/K6)*Opex[[#This Row],[No. Días Gas]] -> #REF! | M7: =+AVERAGE(M4:M6) -> #REF! | N7: =IFERROR(Opex[[#This Row],[Gas]]/Opex[[#This Row],[No. Días Arriendo]],0) -> 8528.2414 | O7: 120000 | P7: =IFERROR(Opex[[#This Row],[Agua]]/Opex[[#This Row],[No. Días Arriendo]],0) -> 4137.931 | Q7: =+AVERAGE(Q5:Q6) -> 319050 | R7: 264247 | S7: =+#REF! -> #REF! | T7: =+AVERAGE(#REF!/U4,#REF!/U5,#REF!/U6) -> #REF! | U7: =+AVERAGE(U4:U6) -> #REF! | V7: Nd | W7: =IFERROR(Opex[[#This Row],[Energia]]/Opex[[#This Row],[No. Días Arriendo]],0) -> 11001.724 | X7: 105000 | Y7: =+Opex[[#This Row],[Internet]]/Opex[[#This Row],[No. Días Arriendo]] -> 3620.6897
A8: Forecast | B8: =+C7+1 -> 46218 | C8: 46248 | D8: =+TEXT(B8,"mmmm") -> julio | F8: =+Opex[[#This Row],[Cuentas x Pagar]]/31 -> 0 | G8: 1650000 | H8: =+Opex[[#This Row],[fecha_fin]]-Opex[[#This Row],[Fecha]] -> 30 | I8: =IFERROR(Opex[[#This Row],[Arriendo]]/Opex[[#This Row],[No. Días Arriendo]],0) -> 55000 | J8: 247319 | K8: =+H7 -> 29 | L8: =+AVERAGE(L5/K5,L6/K6,L7/K7)*Opex[[#This Row],[No. Días Gas]] -> #REF! | M8: =+AVERAGE(M5:M7) -> #REF! | N8: =IFERROR(Opex[[#This Row],[Gas]]/Opex[[#This Row],[No. Días Arriendo]],0) -> 8243.9667 | O8: 120000 | P8: =IFERROR(Opex[[#This Row],[Agua]]/Opex[[#This Row],[No. Días Arriendo]],0) -> 4000 | Q8: =+AVERAGE(Q6:Q7) -> 319050 | R8: 0 | S8: =+#REF! -> #REF! | T8: =+AVERAGE(#REF!/U5,#REF!/U6,#REF!/U7) -> #REF! | U8: =+AVERAGE(U5:U7) -> #REF! | V8: Nd | W8: =IFERROR(Opex[[#This Row],[Energia]]/Opex[[#This Row],[No. Días Arriendo]],0) -> 10635 | X8: 105000 | Y8: =+Opex[[#This Row],[Internet]]/Opex[[#This Row],[No. Días Arriendo]] -> 3500
A9: Forecast | B9: =+C8+1 -> 46249 | C9: 46279 | D9: =+TEXT(B9,"mmmm") -> agosto | F9: =+Opex[[#This Row],[Cuentas x Pagar]]/31 -> 0 | G9: 1650000 | H9: =+Opex[[#This Row],[fecha_fin]]-Opex[[#This Row],[Fecha]] -> 30 | I9: =IFERROR(Opex[[#This Row],[Arriendo]]/Opex[[#This Row],[No. Días Arriendo]],0) -> 55000 | J9: 247319 | K9: =+H8 -> 30 | L9: =+AVERAGE(L6/K6,L7/K7,L8/K8)*Opex[[#This Row],[No. Días Gas]] -> #REF! | M9: =+AVERAGE(M6:M8) -> #REF! | N9: =IFERROR(Opex[[#This Row],[Gas]]/Opex[[#This Row],[No. Días Arriendo]],0) -> 8243.9667 | O9: 120000 | P9: =IFERROR(Opex[[#This Row],[Agua]]/Opex[[#This Row],[No. Días Arriendo]],0) -> 4000 | Q9: =+AVERAGE(Q7:Q8) -> 319050 | R9: 0 | S9: =+#REF! -> #REF! | T9: =+AVERAGE(#REF!/U6,#REF!/U7,#REF!/U8) -> #REF! | U9: =+AVERAGE(U6:U8) -> #REF! | V9: Nd | W9: =IFERROR(Opex[[#This Row],[Energia]]/Opex[[#This Row],[No. Días Arriendo]],0) -> 10635 | X9: 105000 | Y9: =+Opex[[#This Row],[Internet]]/Opex[[#This Row],[No. Días Arriendo]] -> 3500
A10: Forecast | B10: =+C9+1 -> 46280 | C10: 46309 | D10: =+TEXT(B10,"mmmm") -> septiembre | F10: =+Opex[[#This Row],[Cuentas x Pagar]]/31 -> 0 | G10: 1650000 | H10: =+Opex[[#This Row],[fecha_fin]]-Opex[[#This Row],[Fecha]] -> 29 | I10: =IFERROR(Opex[[#This Row],[Arriendo]]/Opex[[#This Row],[No. Días Arriendo]],0) -> 56896.552 | J10: 247319 | K10: =+H9 -> 30 | L10: =+AVERAGE(L7/K7,L8/K8,L9/K9)*Opex[[#This Row],[No. Días Gas]] -> #REF! | M10: =+AVERAGE(M7:M9) -> #REF! | N10: =IFERROR(Opex[[#This Row],[Gas]]/Opex[[#This Row],[No. Días Arriendo]],0) -> 8528.2414 | O10: 120000 | P10: =IFERROR(Opex[[#This Row],[Agua]]/Opex[[#This Row],[No. Días Arriendo]],0) -> 4137.931 | Q10: =+AVERAGE(Q8:Q9) -> 319050 | R10: 0 | S10: =+#REF! -> #REF! | T10: =+AVERAGE(#REF!/U7,#REF!/U8,#REF!/U9) -> #REF! | U10: =+AVERAGE(U7:U9) -> #REF! | V10: Nd | W10: =IFERROR(Opex[[#This Row],[Energia]]/Opex[[#This Row],[No. Días Arriendo]],0) -> 11001.724 | X10: 105000 | Y10: =+Opex[[#This Row],[Internet]]/Opex[[#This Row],[No. Días Arriendo]] -> 3620.6897
A11: Forecast | B11: =+C10+1 -> 46310 | C11: 46340 | D11: =+TEXT(B11,"mmmm") -> octubre | F11: =+Opex[[#This Row],[Cuentas x Pagar]]/31 -> 0 | G11: 1650000 | H11: =+Opex[[#This Row],[fecha_fin]]-Opex[[#This Row],[Fecha]] -> 30 | I11: =IFERROR(Opex[[#This Row],[Arriendo]]/Opex[[#This Row],[No. Días Arriendo]],0) -> 55000 | J11: 247319 | K11: =+H10 -> 29 | L11: =+AVERAGE(L8/K8,L9/K9,L10/K10)*Opex[[#This Row],[No. Días Gas]] -> #REF! | M11: =+AVERAGE(M8:M10) -> #REF! | N11: =IFERROR(Opex[[#This Row],[Gas]]/Opex[[#This Row],[No. Días Arriendo]],0) -> 8243.9667 | O11: 120000 | P11: =IFERROR(Opex[[#This Row],[Agua]]/Opex[[#This Row],[No. Días Arriendo]],0) -> 4000 | Q11: =+AVERAGE(Q9:Q10) -> 319050 | R11: 0 | S11: =+#REF! -> #REF! | T11: =+AVERAGE(#REF!/U8,#REF!/U9,#REF!/U10) -> #REF! | U11: =+AVERAGE(U8:U10) -> #REF! | V11: Nd | W11: =IFERROR(Opex[[#This Row],[Energia]]/Opex[[#This Row],[No. Días Arriendo]],0) -> 10635 | X11: 105000 | Y11: =+Opex[[#This Row],[Internet]]/Opex[[#This Row],[No. Días Arriendo]] -> 3500
A12: Forecast | B12: =+C11+1 -> 46341 | C12: 46370 | D12: =+TEXT(B12,"mmmm") -> noviembre | F12: =+Opex[[#This Row],[Cuentas x Pagar]]/31 -> 0 | G12: 1650000 | H12: =+Opex[[#This Row],[fecha_fin]]-Opex[[#This Row],[Fecha]] -> 29 | I12: =IFERROR(Opex[[#This Row],[Arriendo]]/Opex[[#This Row],[No. Días Arriendo]],0) -> 56896.552 | J12: 247319 | K12: =+H11 -> 30 | L12: =+AVERAGE(L9/K9,L10/K10,L11/K11)*Opex[[#This Row],[No. Días Gas]] -> #REF! | M12: =+AVERAGE(M9:M11) -> #REF! | N12: =IFERROR(Opex[[#This Row],[Gas]]/Opex[[#This Row],[No. Días Arriendo]],0) -> 8528.2414 | O12: 120000 | P12: =IFERROR(Opex[[#This Row],[Agua]]/Opex[[#This Row],[No. Días Arriendo]],0) -> 4137.931 | Q12: =+AVERAGE(Q10:Q11) -> 319050 | R12: 0 | S12: =+#REF! -> #REF! | T12: =+AVERAGE(#REF!/U9,#REF!/U10,#REF!/U11) -> #REF! | U12: =+AVERAGE(U9:U11) -> #REF! | V12: Nd | W12: =IFERROR(Opex[[#This Row],[Energia]]/Opex[[#This Row],[No. Días Arriendo]],0) -> 11001.724 | X12: 105000 | Y12: =+Opex[[#This Row],[Internet]]/Opex[[#This Row],[No. Días Arriendo]] -> 3620.6897
A13: Forecast | B13: =+C12+1 -> 46371 | C13: 46401 | D13: =+TEXT(B13,"mmmm") -> diciembre | F13: =+Opex[[#This Row],[Cuentas x Pagar]]/31 -> 0 | G13: 1650000 | H13: =+Opex[[#This Row],[fecha_fin]]-Opex[[#This Row],[Fecha]] -> 30 | I13: =IFERROR(Opex[[#This Row],[Arriendo]]/Opex[[#This Row],[No. Días Arriendo]],0) -> 55000 | J13: 247319 | K13: =+H12 -> 29 | L13: =+AVERAGE(L10/K10,L11/K11,L12/K12)*Opex[[#This Row],[No. Días Gas]] -> #REF! | M13: =+AVERAGE(M10:M12) -> #REF! | N13: =IFERROR(Opex[[#This Row],[Gas]]/Opex[[#This Row],[No. Días Arriendo]],0) -> 8243.9667 | O13: 120000 | P13: =IFERROR(Opex[[#This Row],[Agua]]/Opex[[#This Row],[No. Días Arriendo]],0) -> 4000 | Q13: =+AVERAGE(Q11:Q12) -> 319050 | R13: 0 | S13: =+#REF! -> #REF! | T13: =+AVERAGE(#REF!/U10,#REF!/U11,#REF!/U12) -> #REF! | U13: =+AVERAGE(U10:U12) -> #REF! | V13: Nd | W13: =IFERROR(Opex[[#This Row],[Energia]]/Opex[[#This Row],[No. Días Arriendo]],0) -> 10635 | X13: 105000 | Y13: =+Opex[[#This Row],[Internet]]/Opex[[#This Row],[No. Días Arriendo]] -> 3500
A14: Forecast | B14: =+C13+1 -> 46402 | C14: 46432 | D14: =+TEXT(B14,"mmmm") -> enero | F14: =+Opex[[#This Row],[Cuentas x Pagar]]/31 -> 0 | G14: 1650000 | H14: =+Opex[[#This Row],[fecha_fin]]-Opex[[#This Row],[Fecha]] -> 30 | I14: =IFERROR(Opex[[#This Row],[Arriendo]]/Opex[[#This Row],[No. Días Arriendo]],0) -> 55000 | J14: 247319 | K14: =+H13 -> 30 | L14: =+AVERAGE(L11/K11,L12/K12,L13/K13)*Opex[[#This Row],[No. Días Gas]] -> #REF! | M14: =+AVERAGE(M11:M13) -> #REF! | N14: =IFERROR(Opex[[#This Row],[Gas]]/Opex[[#This Row],[No. Días Arriendo]],0) -> 8243.9667 | O14: 120000 | P14: =IFERROR(Opex[[#This Row],[Agua]]/Opex[[#This Row],[No. Días Arriendo]],0) -> 4000 | Q14: =+AVERAGE(Q12:Q13) -> 319050 | R14: 0 | S14: =+#REF! -> #REF! | T14: =+AVERAGE(#REF!/U11,#REF!/U12,#REF!/U13) -> #REF! | U14: =+AVERAGE(U11:U13) -> #REF! | V14: Nd | W14: =IFERROR(Opex[[#This Row],[Energia]]/Opex[[#This Row],[No. Días Arriendo]],0) -> 10635 | X14: 105000 | Y14: =+Opex[[#This Row],[Internet]]/Opex[[#This Row],[No. Días Arriendo]] -> 3500

Sheet sales
A1: Fecha | B1: Hora | C1: Tipo día | D1: nombre_producto | E1: cantidad | F1: No. Semana de operación | G1: Tipo día2 | H1: Día | I1: MG | J1: Venta | K1: Caja | L1: Bancos | M1: costo_venta | N1: %MG
A2: =[1]sales!A7 -> 46076 | B2: =[1]sales!B7 -> 0.69208333 | C2: Normal | D2: =[1]sales!D7 -> Chorizo con papa/arepa | E2: =+[1]sales!G7 -> 2 | F2: =+_xlfn.XLOOKUP(sales[[#This Row],[Fecha]],OPEX_SALES!A:A,OPEX_SALES!B:B) -> 1 | G2: =+_xlfn.XLOOKUP(sales[[#This Row],[Fecha]],OPEX_SALES!A:A,OPEX_SALES!E:E) -> A) Día hábil | H2: =+TEXT(sales[[#This Row],[Fecha]],"ddd") -> lun | I2: =+sales[[#This Row],[Venta]]-sales[[#This Row],[costo_venta]] -> 7320 | J2: =[1]sales!K7 -> 16000 | K2: =[1]sales!I7 -> 16000 | L2: =[1]sales!J7 -> 0 | M2: =[1]sales!L7*sales[[#This Row],[cantidad]] -> 8680 | N2: =+(sales[[#This Row],[Venta]]-sales[[#This Row],[costo_venta]])/sales[[#This Row],[Venta]] -> 0.4575
A3: =[1]sales!A8 -> 46076 | B3: =[1]sales!B8 -> 0.70967593 | C3: Normal | D3: =[1]sales!D8 -> Chorizo con papa/arepa | E3: =+[1]sales!G8 -> 1 | F3: =+_xlfn.XLOOKUP(sales[[#This Row],[Fecha]],OPEX_SALES!A:A,OPEX_SALES!B:B) -> 1 | G3: =+_xlfn.XLOOKUP(sales[[#This Row],[Fecha]],OPEX_SALES!A:A,OPEX_SALES!E:E) -> A) Día hábil | H3: =+TEXT(sales[[#This Row],[Fecha]],"ddd") -> lun | I3: =+sales[[#This Row],[Venta]]-sales[[#This Row],[costo_venta]] -> 3660 | J3: =[1]sales!K8 -> 8000 | K3: =[1]sales!I8 -> 0 | M3: =[1]sales!L8*sales[[#This Row],[cantidad]] -> 4340 | N3: =+(sales[[#This Row],[Venta]]-sales[[#This Row],[costo_venta]])/sales[[#This Row],[Venta]] -> 0.4575
A4: =[1]sales!A9 -> 46076 | B4: =[1]sales!B9 -> 0.71737269 | C4: Normal | D4: =[1]sales!D9 -> Chorizo con papa/arepa | E4: =+[1]sales!G9 -> 2 | F4: =+_xlfn.XLOOKUP(sales[[#This Row],[Fecha]],OPEX_SALES!A:A,OPEX_SALES!B:B) -> 1 | G4: =+_xlfn.XLOOKUP(sales[[#This Row],[Fecha]],OPEX_SALES!A:A,OPEX_SALES!E:E) -> A) Día hábil | H4: =+TEXT(sales[[#This Row],[Fecha]],"ddd") -> lun | I4: =+sales[[#This Row],[Venta]]-sales[[#This Row],[costo_venta]] -> 7320 | J4: =[1]sales!K9 -> 16000 | K4: =[1]sales!I9 -> 16000 | L4: =[1]sales!J9 -> 0 | M4: =[1]sales!L9*sales[[#This Row],[cantidad]] -> 8680 | N4: =+(sales[[#This Row],[Venta]]-sales[[#This Row],[costo_venta]])/sales[[#This Row],[Venta]] -> 0.4575
A5: =[1]sales!A10 -> 46076 | B5: =[1]sales!B10 -> 0.71737269 | C5: Normal | D5: =[1]sales!D10 -> BEBIDA - Coca Cola | E5: =+[1]sales!G10 -> 2 | F5: =+_xlfn.XLOOKUP(sales[[#This Row],[Fecha]],OPEX_SALES!A:A,OPEX_SALES!B:B) -> 1 | G5: =+_xlfn.XLOOKUP(sales[[#This Row],[Fecha]],OPEX_SALES!A:A,OPEX_SALES!E:E) -> A) Día hábil | H5: =+TEXT(sales[[#This Row],[Fecha]],"ddd") -> lun | I5: =+sales[[#This Row],[Venta]]-sales[[#This Row],[costo_venta]] -> 3600 | J5: =[1]sales!K10 -> 6000 | K5: =[1]sales!I10 -> 6000 | L5: =[1]sales!J10 -> 0 | M5: =[1]sales!L10*sales[[#This Row],[cantidad]] -> 2400 | N5: =+(sales[[#This Row],[Venta]]-sales[[#This Row],[costo_venta]])/sales[[#This Row],[Venta]] -> 0.6
A6: =[1]sales!A11 -> 46076 | B6: =[1]sales!B11 -> 0.72047454 | C6: Normal | D6: =[1]sales!D11 -> Chorizo con papa/arepa | E6: =+[1]sales!G11 -> 3 | F6: =+_xlfn.XLOOKUP(sales[[#This Row],[Fecha]],OPEX_SALES!A:A,OPEX_SALES!B:B) -> 1 | G6: =+_xlfn.XLOOKUP(sales[[#This Row],[Fecha]],OPEX_SALES!A:A,OPEX_SALES!E:E) -> A) Día hábil | H6: =+TEXT(sales[[#This Row],[Fecha]],"ddd") -> lun | I6: =+sales[[#This Row],[Venta]]-sales[[#This Row],[costo_venta]] -> 10980 | J6: =[1]sales!K11 -> 24000 | K6: =[1]sales!I11 -> 0 | L6: =[1]sales!J11 -> 24000 | M6: =[1]sales!L11*sales[[#This Row],[cantidad]] -> 13020 | N6: =+(sales[[#This Row],[Venta]]-sales[[#This Row],[costo_venta]])/sales[[#This Row],[Venta]] -> 0.4575
A7: =[1]sales!A12 -> 46076 | B7: =[1]sales!B12 -> 0.75028935 | C7: Normal | D7: =[1]sales!D12 -> Chorizo con papa/arepa | E7: =+[1]sales!G12 -> 2 | F7: =+_xlfn.XLOOKUP(sales[[#This Row],[Fecha]],OPEX_SALES!A:A,OPEX_SALES!B:B) -> 1 | G7: =+_xlfn.XLOOKUP(sales[[#This Row],[Fecha]],OPEX_SALES!A:A,OPEX_SALES!E:E) -> A) Día hábil | H7: =+TEXT(sales[[#This Row],[Fecha]],"ddd") -> lun | I7: =+sales[[#This Row],[Venta]]-sales[[#This Row],[costo_venta]] -> 7320 | J7: =[1]sales!K12 -> 16000 | K7: =[1]sales!I12 -> 16000 | L7: =[1]sales!J12 -> 0 | M7: =[1]sales!L12*sales[[#This Row],[cantidad]] -> 8680 | N7: =+(sales[[#This Row],[Venta]]-sales[[#This Row],[costo_venta]])/sales[[#This Row],[Venta]] -> 0.4575
