Workbook
Name Costo_MP: [1]!Inventario6[#Data]
Name Cuentas_x_pagar: Pasivos[]
Name Cuentas_x_pagar: Pasivos8[]
Name Cuentas_x_pagar: Pasivos[]
Name Cuentas_x_pagar: Pasivos[]
Name Cuentas_x_pagar: Pasivos[]
Name Efectivo: [1]!Pérdidas_Ganancias[#Data]
Name SegmentaciónDeDatos_Mes: #N/A
Name SegmentaciónDeDatos_Tipo_día: #N/A
Name Stock_Inventario: [1]!Inventario_SICOV2[#Data]

Sheet maestro
A1: Fecha | B1: dia_semana | C1: No. Semana de operación | D1: Tipo día2
A2: 46076 | B2: =+TEXT(A2,"dddd") -> lunes | C2: 1 | D2: A) Día hábil
A3: 46076 | B3: =+TEXT(A3,"dddd") -> lunes | C3: 1 | D3: A) Día hábil
A4: 46077 | B4: =+TEXT(A4,"dddd") -> martes | C4: 1 | D4: A) Día hábil
A5: 46078 | B5: =+TEXT(A5,"dddd") -> miércoles | C5: 1 | D5: A) Día hábil
A6: 46079 | B6: =+TEXT(A6,"dddd") -> jueves | C6: 1 | D6: A) Día hábil
A7: 46080 | B7: =+TEXT(A7,"dddd") -> viernes | C7: 1 | D7: C) Viernes
A8: 46081 | B8: =+TEXT(A8,"dddd") -> sábado | C8: 1 | D8: C) Sábado
A9: 46082 | B9: =+TEXT(A9,"dddd") -> domingo | C9: 1 | D9: D) Domingo
A10: 46083 | B10: =+TEXT(A10,"dddd") -> lunes | C10: 2 | D10: A) Día hábil
A11: 46084 | B11: =+TEXT(A11,"dddd") -> martes | C11: 2 | D11: A) Día hábil
A12: 46085 | B12: =+TEXT(A12,"dddd") -> miércoles | C12: 2 | D12: A) Día hábil
A13: 46086 | B13: =+TEXT(A13,"dddd") -> jueves | C13: 2 | D13: A) Día hábil
... A16: 46089 | B16: =+TEXT(A16,"dddd") -> domingo | C16: 2 | D16: D) Domingo
A17: 46090 | B17: =+TEXT(A17,"dddd") -> lunes | C17: =+C10+1 -> 3 | D17: A) Día hábil
A18: 46091 | B18: =+TEXT(A18,"dddd") -> martes | C18: =+C11+1 -> 3 | D18: A) Día hábil
A19: 46092 | B19: =+TEXT(A19,"dddd") -> miércoles | C19: =+C12+1 -> 3 | D19: A) Día hábil
A20: 46093 | B20: =+TEXT(A20,"dddd") -> jueves | C20: =+C13+1 -> 3 | D20: A) Día hábil
A21: 46094 | B21: =+TEXT(A21,"dddd") -> viernes | C21: =+C14+1 -> 3 | D21: C) Viernes
A22: 46095 | B22: =+TEXT(A22,"dddd") -> sábado | C22: =+C15+1 -> 3 | D22: C) Sábado
A23: 46096 | B23: =+TEXT(A23,"dddd") -> domingo | C23: =+C16+1 -> 3 | D23: D) Domingo
A24: 46097 | B24: =+TEXT(A24,"dddd") -> lunes | C24: =+C17+1 -> 4 | D24: A) Día hábil
A25: 46098 | B25: =+TEXT(A25,"dddd") -> martes | C25: =+C18+1 -> 4 | D25: A) Día hábil
A26: 46099 | B26: =+TEXT(A26,"dddd") -> miércoles | C26: =+C19+1 -> 4 | D26: A) Día hábil
A27: 46100 | B27: =+TEXT(A27,"dddd") -> jueves | C27: =+C20+1 -> 4 | D27: A) Día hábil
A28: 46101 | B28: =+TEXT(A28,"dddd") -> viernes | C28: =+C21+1 -> 4 | D28: C) Viernes
... A314: 46387 | B314: =+TEXT(A314,"dddd") -> jueves | C314: =+C307+1 -> 45 | D314: A) Día hábil

Sheet sales
M1: =+VLOOKUP(sales[[#This Row],[Día]],Forecast!AK:AM,2,0) -> #VALUE!
B2: Fecha | C2: Hora | D2: Tipo día | E2: nombre_producto | F2: No. Semana de operación | G2: Gastos | H2: Tipo día2 | I2: Día | J2: Mes | K2: Margen de contribución | L2: Venta | M2: Caja | N2: Bancos
B3: =[2]sales_BI!J2 -> 46076 | C3: =[2]sales_BI!$K$2 -> 04:36 p. m. | D3: Normal | E3: =[2]sales!C5 -> Chorizo | F3: =+VLOOKUP(sales[[#This Row],[Fecha]],maestro!A:C,3,0) -> 1 | H3: =+VLOOKUP(sales[[#This Row],[Fecha]],maestro!A:D,4,0) -> A) Día hábil | I3: =+TEXT(B3,"ddd") -> lun | J3: =+TEXT(B3,"mmmm") -> febrero | K3: =+M3*0.4 -> 6400 | L3: =[2]sales_BI!H2 -> 16000 | M3: =[2]sales_BI!L2 -> 16000 | N3: =[2]sales_BI!M2 -> 0
B4: =[2]sales_BI!J3 -> 46076 | C4: =[2]sales_BI!$K$2 -> 04:36 p. m. | D4: Normal | E4: =[2]sales!C6 -> Chorizo | F4: =+VLOOKUP(sales[[#This Row],[Fecha]],maestro!A:C,3,0) -> 1 | H4: =+VLOOKUP(sales[[#This Row],[Fecha]],maestro!A:D,4,0) -> A) Día hábil | I4: =+TEXT(B4,"ddd") -> lun | J4: =+TEXT(B4,"mmmm") -> febrero | K4: =+M4*0.4 -> 0 | L4: =[2]sales_BI!H3 -> 8000 | M4: =[2]sales_BI!L3 -> 0 | N4: 0
B5: =[2]sales_BI!J4 -> 46076 | C5: =[2]sales_BI!$K$2 -> 04:36 p. m. | D5: Normal | E5: =[2]sales!C7 -> Chorizo | F5: =+VLOOKUP(sales[[#This Row],[Fecha]],maestro!A:C,3,0) -> 1 | H5: =+VLOOKUP(sales[[#This Row],[Fecha]],maestro!A:D,4,0) -> A) Día hábil | I5: =+TEXT(B5,"ddd") -> lun | J5: =+TEXT(B5,"mmmm") -> febrero | K5: =+M5*0.4 -> 6400 | L5: =[2]sales_BI!H4 -> 16000 | M5: =[2]sales_BI!L4 -> 16000 | N5: 0
B6: =[2]sales_BI!J5 -> 46076 | C6: =[2]sales_BI!$K$2 -> 04:36 p. m. | D6: Normal | E6: =[2]sales!C8 -> Coca cola | F6: =+VLOOKUP(sales[[#This Row],[Fecha]],maestro!A:C,3,0) -> 1 | H6: =+VLOOKUP(sales[[#This Row],[Fecha]],maestro!A:D,4,0) -> A) Día hábil | I6: =+TEXT(B6,"ddd") -> lun | J6: =+TEXT(B6,"mmmm") -> febrero | K6: =+M6*0.4 -> 2400 | L6: =[2]sales_BI!H5 -> 6000 | M6: =[2]sales_BI!L5 -> 6000 | N6: 0
B7: =[2]sales_BI!J6 -> 46076 | C7: =[2]sales_BI!$K$2 -> 04:36 p. m. | D7: Normal | E7: =[2]sales!C9 -> Chorizo | F7: =+VLOOKUP(sales[[#This Row],[Fecha]],maestro!A:C,3,0) -> 1 | H7: =+VLOOKUP(sales[[#This Row],[Fecha]],maestro!A:D,4,0) -> A) Día hábil | I7: =+TEXT(B7,"ddd") -> lun | J7: =+TEXT(B7,"mmmm") -> febrero | K7: =+M7*0.4 -> 0 | L7: =[2]sales_BI!H6 -> 24000 | M7: =[2]sales_BI!L6 -> 0 | N7: 0
B8: =[2]sales_BI!J7 -> 46076 | C8: =[2]sales_BI!$K$2 -> 04:36 p. m. | D8: Normal | E8: =[2]sales!C10 -> Agua | F8: =+VLOOKUP(sales[[#This Row],[Fecha]],maestro!A:C,3,0) -> 1 | H8: =+VLOOKUP(sales[[#This Row],[Fecha]],maestro!A:D,4,0) -> A) Día hábil | I8: =+TEXT(B8,"ddd") -> lun | J8: =+TEXT(B8,"mmmm") -> febrero | K8: =+M8*0.4 -> 2400 | L8: =[2]sales_BI!H7 -> 6000 | M8: =[2]sales_BI!L7 -> 6000 | N8: 0
B9: =[2]sales_BI!J8 -> 46076 | C9: =[2]sales_BI!$K$2 -> 04:36 p. m. | D9: Normal | E9: =[2]sales!C11 -> Chorizo | F9: =+VLOOKUP(sales[[#This Row],[Fecha]],maestro!A:C,3,0) -> 1 | H9: =+VLOOKUP(sales[[#This Row],[Fecha]],maestro!A:D,4,0) -> A) Día hábil | I9: =+TEXT(B9,"ddd") -> lun | J9: =+TEXT(B9,"mmmm") -> febrero | K9: =+M9*0.4 -> 6400 | L9: =[2]sales_BI!H8 -> 16000 | M9: =[2]sales_BI!L8 -> 16000 | N9: 0
B10: =[2]sales_BI!J9 -> 46076 | C10: =[2]sales_BI!$K$2 -> 04:36 p. m. | D10: Normal | E10: =[2]sales!C12 -> Chorizo | F10: =+VLOOKUP(sales[[#This Row],[Fecha]],maestro!A:C,3,0) -> 1 | H10: =+VLOOKUP(sales[[#This Row],[Fecha]],maestro!A:D,4,0) -> A) Día hábil | I10: =+TEXT(B10,"ddd") -> lun | J10: =+TEXT(B10,"mmmm") -> febrero | K10: =+M10*0.4 -> 6400 | L10: =[2]sales_BI!H9 -> 16000 | M10: =[2]sales_BI!L9 -> 16000 | N10: 0
B11: =[2]sales_BI!J10 -> 46076 | C11: =[2]sales_BI!$K$2 -> 04:36 p. m. | D11: Normal | E11: =[2]sales!C13 -> Postobon | F11: =+VLOOKUP(sales[[#This Row],[Fecha]],maestro!A:C,3,0) -> 1 | H11: =+VLOOKUP(sales[[#This Row],[Fecha]],maestro!A:D,4,0) -> A) Día hábil | I11: =+TEXT(B11,"ddd") -> lun | J11: =+TEXT(B11,"mmmm") -> febrero | K11: =+M11*0.4 -> 1200 | L11: =[2]sales_BI!H10 -> 3000 | M11: =[2]sales_BI!L10 -> 3000 | N11: 0
B12: =[2]sales_BI!J11 -> 46076 | C12: =[2]sales_BI!$K$2 -> 04:36 p. m. | D12: Normal | E12: =[2]sales!C14 -> Chorizo | F12: =+VLOOKUP(sales[[#This Row],[Fecha]],maestro!A:C,3,0) -> 1 | H12: =+VLOOKUP(sales[[#This Row],[Fecha]],maestro!A:D,4,0) -> A) Día hábil | I12: =+TEXT(B12,"ddd") -> lun | J12: =+TEXT(B12,"mmmm") -> febrero | K12: =+M12*0.4 -> 3200 | L12: =[2]sales_BI!H11 -> 8000 | M12: =[2]sales_BI!L11 -> 8000 | N12: 0
B13: =[2]sales_BI!J12 -> 46076 | C13: =[2]sales_BI!$K$2 -> 04:36 p. m. | D13: Normal | E13: =[2]sales!C15 -> Chorizo | F13: =+VLOOKUP(sales[[#This Row],[Fecha]],maestro!A:C,3,0) -> 1 | H13: =+VLOOKUP(sales[[#This Row],[Fecha]],maestro!A:D,4,0) -> A) Día hábil | I13: =+TEXT(B13,"ddd") -> lun | J13: =+TEXT(B13,"mmmm") -> febrero | K13: =+M13*0.4 -> 6400 | L13: =[2]sales_BI!H12 -> 16000 | M13: =[2]sales_BI!L12 -> 16000 | N13: 0
B14: =[2]sales_BI!J13 -> 46076 | C14: =[2]sales_BI!$K$2 -> 04:36 p. m. | D14: Normal | E14: =[2]sales!C16 -> Coca cola | F14: =+VLOOKUP(sales[[#This Row],[Fecha]],maestro!A:C,3,0) -> 1 | H14: =+VLOOKUP(sales[[#This Row],[Fecha]],maestro!A:D,4,0) -> A) Día hábil | I14: =+TEXT(B14,"ddd") -> lun | J14: =+TEXT(B14,"mmmm") -> febrero | K14: =+M14*0.4 -> 2400 | L14: =[2]sales_BI!H13 -> 6000 | M14: =[2]sales_BI!L13 -> 6000 | N14: 0
B15: =[2]sales_BI!J14 -> 46076 | C15: =[2]sales_BI!$K$2 -> 04:36 p. m. | D15: Normal | E15: =[2]sales!C17 -> Chorizo | F15: =+VLOOKUP(sales[[#This Row],[Fecha]],maestro!A:C,3,0) -> 1 | H15: =+VLOOKUP(sales[[#This Row],[Fecha]],maestro!A:D,4,0) -> A) Día hábil | I15: =+TEXT(B15,"ddd") -> lun | J15: =+TEXT(B15,"mmmm") -> febrero | K15: =+M15*0.4 -> 9600 | L15: =[2]sales_BI!H14 -> 24000 | M15: =[2]sales_BI!L14 -> 24000 | N15: 0
... B24: =[2]sales_BI!J23 -> 46077 | C24: =[2]sales_BI!$K$2 -> 04:36 p. m. | D24: Normal | E24: =[2]sales!C26 -> Chorizo | F24: =+VLOOKUP(sales[[#This Row],[Fecha]],maestro!A:C,3,0) -> 1 | H24: =+VLOOKUP(sales[[#This Row],[Fecha]],maestro!A:D,4,0) -> A) Día hábil | I24: =+TEXT(B24,"ddd") -> mar | J24: =+TEXT(B24,"mmmm") -> febrero | K24: =+M24*0.4 -> 3200 | L24: =[2]sales_BI!H23 -> 8000 | M24: =[2]sales_BI!L23 -> 8000 | N24: 0
B25: =[2]sales_BI!J24 -> 46077 | C25: =[2]sales_BI!$K$2 -> 04:36 p. m. | D25: Normal | E25: =[2]sales!C27 -> Chorizo | F25: =+VLOOKUP(sales[[#This Row],[Fecha]],maestro!A:C,3,0) -> 1 | H25: =+VLOOKUP(sales[[#This Row],[Fecha]],maestro!A:D,4,0) -> A) Día hábil | I25: =+TEXT(B25,"ddd") -> mar | J25: =+TEXT(B25,"mmmm") -> febrero | K25: =+M25*0.35 -> 2800 | L25: =[2]sales_BI!H24 -> 8000 | M25: =[2]sales_BI!L24 -> 8000 | N25: 0
B26: =[2]sales_BI!J25 -> 46077 | C26: =[2]sales_BI!$K$2 -> 04:36 p. m. | D26: Normal | E26: =[2]sales!C28 -> Chorizo | F26: =+VLOOKUP(sales[[#This Row],[Fecha]],maestro!A:C,3,0) -> 1 | H26: =+VLOOKUP(sales[[#This Row],[Fecha]],maestro!A:D,4,0) -> A) Día hábil | I26: =+TEXT(B26,"ddd") -> mar | J26: =+TEXT(B26,"mmmm") -> febrero | K26: =+M26*0.35 -> 5600 | L26: =[2]sales_BI!H25 -> 16000 | M26: =[2]sales_BI!L25 -> 16000 | N26: 0
B27: =[2]sales_BI!J26 -> 46077 | C27: =[2]sales_BI!$K$2 -> 04:36 p. m. | D27: Normal | E27: =[2]sales!C29 -> Chorizo | F27: =+VLOOKUP(sales[[#This Row],[Fecha]],maestro!A:C,3,0) -> 1 | H27: =+VLOOKUP(sales[[#This Row],[Fecha]],maestro!A:D,4,0) -> A) Día hábil | I27: =+TEXT(B27,"ddd") -> mar | J27: =+TEXT(B27,"mmmm") -> febrero | K27: =+M27*0.35 -> 2800 | L27: =[2]sales_BI!H26 -> 8000 | M27: =[2]sales_BI!L26 -> 8000 | N27: 0
B28: =[2]sales_BI!J27 -> 46077 | C28: =[2]sales_BI!$K$2 -> 04:36 p. m. | D28: Normal | E28: =[2]sales!C30 -> Chori- CRUDO | F28: =+VLOOKUP(sales[[#This Row],[Fecha]],maestro!A:C,3,0) -> 1 | H28: =+VLOOKUP(sales[[#This Row],[Fecha]],maestro!A:D,4,0) -> A) Día hábil | I28: =+TEXT(B28,"ddd") -> mar | J28: =+TEXT(B28,"mmmm") -> febrero | K28: =+M28*0.35 -> 3150 | L28: =[2]sales_BI!H27 -> 9000 | M28: =[2]sales_BI!L27 -> 9000 | N28: 0
B29: =[2]sales_BI!J28 -> 46077 | C29: =[2]sales_BI!$K$2 -> 04:36 p. m. | D29: Normal | E29: =[2]sales!C31 -> Chorizo | F29: =+VLOOKUP(sales[[#This Row],[Fecha]],maestro!A:C,3,0) -> 1 | H29: =+VLOOKUP(sales[[#This Row],[Fecha]],maestro!A:D,4,0) -> A) Día hábil | I29: =+TEXT(B29,"ddd") -> mar | J29: =+TEXT(B29,"mmmm") -> febrero | K29: =+M29*0.35 -> 2800 | L29: =[2]sales_BI!H28 -> 8000 | M29: =[2]sales_BI!L28 -> 8000 | N29: 0
B30: =[2]sales_BI!J29 -> 46077 | C30: =[2]sales_BI!$K$2 -> 04:36 p. m. | D30: Normal | E30: =[2]sales!C32 -> Chorizo | F30: =+VLOOKUP(sales[[#This Row],[Fecha]],maestro!A:C,3,0) -> 1 | H30: =+VLOOKUP(sales[[#This Row],[Fecha]],maestro!A:D,4,0) -> A) Día hábil | I30: =+TEXT(B30,"ddd") -> mar | J30: =+TEXT(B30,"mmmm") -> febrero | K30: =+M30*0.35 -> 2800 | L30: =[2]sales_BI!H29 -> 8000 | M30: =[2]sales_BI!L29 -> 8000 | N30: 0
B31: =[2]sales_BI!J30 -> 46077 | C31: =[2]sales_BI!$K$2 -> 04:36 p. m. | D31: Normal | E31: =[2]sales!C33 -> Chorizo | F31: =+VLOOKUP(sales[[#This Row],[Fecha]],maestro!A:C,3,0) -> 1 | H31: =+VLOOKUP(sales[[#This Row],[Fecha]],maestro!A:D,4,0) -> A) Día hábil | I31: =+TEXT(B31,"ddd") -> mar | J31: =+TEXT(B31,"mmmm") -> febrero | K31: =+M31*0.35 -> 0 | L31: =[2]sales_BI!H30 -> 8000 | M31: =[2]sales_BI!L30 -> 0 | N31: 0
B32: =[2]sales_BI!J31 -> 46077 | C32: =[2]sales_BI!$K$2 -> 04:36 p. m. | D32: Normal | E32: =[2]sales!C34 -> Chorizo | F32: =+VLOOKUP(sales[[#This Row],[Fecha]],maestro!A:C,3,0) -> 1 | H32: =+VLOOKUP(sales[[#This Row],[Fecha]],maestro!A:D,4,0) -> A) Día hábil | I32: =+TEXT(B32,"ddd") -> mar | J32: =+TEXT(B32,"mmmm") -> febrero | K32: =+M32*0.35 -> 2800 | L32: =[2]sales_BI!H31 -> 8000 | M32: =[2]sales_BI!L31 -> 8000 | N32: 0
B33: =[2]sales_BI!J32 -> 46077 | C33: =[2]sales_BI!$K$2 -> 04:36 p. m. | D33: Normal | E33: =[2]sales!C35 -> Agua | F33: =+VLOOKUP(sales[[#This Row],[Fecha]],maestro!A:C,3,0) -> 1 | H33: =+VLOOKUP(sales[[#This Row],[Fecha]],maestro!A:D,4,0) -> A) Día hábil | I33: =+TEXT(B33,"ddd") -> mar | J33: =+TEXT(B33,"mmmm") -> febrero | K33: =+M33*0.35 -> 1050 | L33: =[2]sales_BI!H32 -> 3000 | M33: =[2]sales_BI!L32 -> 3000 | N33: 0
B34: =[2]sales_BI!J33 -> 46077 | C34: =[2]sales_BI!$K$2 -> 04:36 p. m. | D34: Normal | E34: =[2]sales!C36 -> Chorizo | F34: =+VLOOKUP(sales[[#This Row],[Fecha]],maestro!A:C,3,0) -> 1 | H34: =+VLOOKUP(sales[[#This Row],[Fecha]],maestro!A:D,4,0) -> A) Día hábil | I34: =+TEXT(B34,"ddd") -> mar | J34: =+TEXT(B34,"mmmm") -> febrero | K34: =+M34*0.35 -> 8400 | L34: =[2]sales_BI!H33 -> 24000 | M34: =[2]sales_BI!L33 -> 24000 | N34: 0
B35: =[2]sales_BI!J34 -> 46077 | C35: =[2]sales_BI!$K$2 -> 04:36 p. m. | D35: Normal | E35: =[2]sales!C37 -> Postobon | F35: =+VLOOKUP(sales[[#This Row],[Fecha]],maestro!A:C,3,0) -> 1 | H35: =+VLOOKUP(sales[[#This Row],[Fecha]],maestro!A:D,4,0) -> A) Día hábil | I35: =+TEXT(B35,"ddd") -> mar | J35: =+TEXT(B35,"mmmm") -> febrero | K35: =+M35*0.35 -> 1050 | L35: =[2]sales_BI!H34 -> 3000 | M35: =[2]sales_BI!L34 -> 3000 | N35: 0
B36: =[2]sales_BI!J35 -> 46077 | C36: =[2]sales_BI!$K$2 -> 04:36 p. m. | D36: Normal | E36: =[2]sales!C38 -> Chorizo | F36: =+VLOOKUP(sales[[#This Row],[Fecha]],maestro!A:C,3,0) -> 1 | H36: =+VLOOKUP(sales[[#This Row],[Fecha]],maestro!A:D,4,0) -> A) Día hábil | I36: =+TEXT(B36,"ddd") -> mar | J36: =+TEXT(B36,"mmmm") -> febrero | K36: =+M36*0.35 -> 11200 | L36: =[2]sales_BI!H35 -> 32000 | M36: =[2]sales_BI!L35 -> 32000 | N36: 0
... B94: =[2]sales_BI!J93 -> 46080 | C94: =[2]sales_BI!$K$2 -> 04:36 p. m. | D94: Normal | E94: =[2]sales!C96 -> Chorizo | F94: =+VLOOKUP(sales[[#This Row],[Fecha]],maestro!A:C,3,0) -> 1 | H94: =+VLOOKUP(sales[[#This Row],[Fecha]],maestro!A:D,4,0) -> C) Viernes | I94: =+TEXT(B94,"ddd") -> vie | J94: =+TEXT(B94,"mmmm") -> febrero | K94: =+M94*0.35 -> 0 | L94: =[2]sales_BI!H93 -> 24000 | M94: =[2]sales_BI!L93 -> 0 | N94: 0
B95: =[2]sales_BI!J94 -> 46080 | C95: =[2]sales_BI!$K$2 -> 04:36 p. m. | D95: Normal | E95: =[2]sales!C97 -> Agua | F95: =+VLOOKUP(sales[[#This Row],[Fecha]],maestro!A:C,3,0) -> 1 | H95: =+VLOOKUP(sales[[#This Row],[Fecha]],maestro!A:D,4,0) -> C) Viernes | I95: =+TEXT(B95,"ddd") -> vie | J95: =+TEXT(B95,"mmmm") -> febrero | K95: =+M95*0.35 -> 0 | L95: =[2]sales_BI!H94 -> 3000 | M95: =[2]sales_BI!L94 -> 0 | N95: 0 | O95: ='Cuentas x Pagar'!$L$26 -> 0
B96: =[2]sales_BI!J95 -> 46080 | C96: =[2]sales_BI!$K$2 -> 04:36 p. m. | D96: Normal | E96: =[2]sales!C98 -> Chorizo | F96: =+VLOOKUP(sales[[#This Row],[Fecha]],maestro!A:C,3,0) -> 1 | H96: =+VLOOKUP(sales[[#This Row],[Fecha]],maestro!A:D,4,0) -> C) Viernes | I96: =+TEXT(B96,"ddd") -> vie | J96: =+TEXT(B96,"mmmm") -> febrero | K96: =+M96*0.35 -> 0 | L96: =[2]sales_BI!H95 -> 8000 | M96: =[2]sales_BI!L95 -> 0 | N96: 0
B97: =[2]sales_BI!J96 -> 46080 | C97: =[2]sales_BI!$K$2 -> 04:36 p. m. | D97: Normal | E97: =[2]sales!C99 -> Chorizo | F97: =+VLOOKUP(sales[[#This Row],[Fecha]],maestro!A:C,3,0) -> 1 | H97: =+VLOOKUP(sales[[#This Row],[Fecha]],maestro!A:D,4,0) -> C) Viernes | I97: =+TEXT(B97,"ddd") -> vie | J97: =+TEXT(B97,"mmmm") -> febrero | K97: =+M97*0.35 -> 0 | L97: =[2]sales_BI!H96 -> 16000 | M97: =[2]sales_BI!L96 -> 0 | N97: 0
B98: =[2]sales_BI!J97 -> 46080 | C98: =[2]sales_BI!$K$2 -> 04:36 p. m. | D98: Normal | E98: =[2]sales!C100 -> Chorizo | F98: =+VLOOKUP(sales[[#This Row],[Fecha]],maestro!A:C,3,0) -> 1 | H98: =+VLOOKUP(sales[[#This Row],[Fecha]],maestro!A:D,4,0) -> C) Viernes | I98: =+TEXT(B98,"ddd") -> vie | J98: =+TEXT(B98,"mmmm") -> febrero | K98: =+M98*0.35 -> 11200 | L98: =[2]sales_BI!H97 -> 32000 | M98: =[2]sales_BI!L97 -> 32000 | N98: 0
B99: =[2]sales_BI!J98 -> 46080 | C99: =[2]sales_BI!$K$2 -> 04:36 p. m. | D99: Normal | E99: =[2]sales!C101 -> Coca cola | F99: =+VLOOKUP(sales[[#This Row],[Fecha]],maestro!A:C,3,0) -> 1 | H99: =+VLOOKUP(sales[[#This Row],[Fecha]],maestro!A:D,4,0) -> C) Viernes | I99: =+TEXT(B99,"ddd") -> vie | J99: =+TEXT(B99,"mmmm") -> febrero | K99: =+M99*0.35 -> 3150 | L99: =[2]sales_BI!H98 -> 9000 | M99: =[2]sales_BI!L98 -> 9000 | N99: 0
B100: =[2]sales_BI!J99 -> 46080 | C100: =[2]sales_BI!$K$2 -> 04:36 p. m. | D100: Normal | E100: =[2]sales!C102 -> Chorizo | F100: =+VLOOKUP(sales[[#This Row],[Fecha]],maestro!A:C,3,0) -> 1 | H100: =+VLOOKUP(sales[[#This Row],[Fecha]],maestro!A:D,4,0) -> C) Viernes | I100: =+TEXT(B100,"ddd") -> vie | J100: =+TEXT(B100,"mmmm") -> febrero | K100: =+M100*0.35 -> 2800 | L100: =[2]sales_BI!H99 -> 8000 | M100: =[2]sales_BI!L99 -> 8000 | N100: 0
B101: =[2]sales_BI!J100 -> 46081 | C101: =[2]sales_BI!$K$2 -> 04:36 p. m. | D101: Normal | E101: =[2]sales!C103 -> Chori- CRUDO | F101: =+VLOOKUP(sales[[#This Row],[Fecha]],maestro!A:C,3,0) -> 1 | H101: =+VLOOKUP(sales[[#This Row],[Fecha]],maestro!A:D,4,0) -> C) Sábado | I101: =+TEXT(B101,"ddd") -> sáb | J101: =+TEXT(B101,"mmmm") -> febrero | K101: =+M101*0.35 -> 9450 | L101: =[2]sales_BI!H100 -> 27000 | M101: =[2]sales_BI!L100 -> 27000 | N101: 0
B102: =[2]sales_BI!J101 -> 46081 | C102: =[2]sales_BI!$K$2 -> 04:36 p. m. | D102: Normal | E102: =[2]sales!C104 -> Chorizo | F102: =+VLOOKUP(sales[[#This Row],[Fecha]],maestro!A:C,3,0) -> 1 | H102: =+VLOOKUP(sales[[#This Row],[Fecha]],maestro!A:D,4,0) -> C) Sábado | I102: =+TEXT(B102,"ddd") -> sáb | J102: =+TEXT(B102,"mmmm") -> febrero | K102: =+M102*0.35 -> 0 | L102: =[2]sales_BI!H101 -> 16000 | M102: =[2]sales_BI!L101 -> 0 | N102: 0
B103: =[2]sales_BI!J102 -> 46081 | C103: =[2]sales_BI!$K$2 -> 04:36 p. m. | D103: Normal | E103: =[2]sales!C105 -> Agua | F103: =+VLOOKUP(sales[[#This Row],[Fecha]],maestro!A:C,3,0) -> 1 | H103: =+VLOOKUP(sales[[#This Row],[Fecha]],maestro!A:D,4,0) -> C) Sábado | I103: =+TEXT(B103,"ddd") -> sáb | J103: =+TEXT(B103,"mmmm") -> febrero | K103: =+M103*0.35 -> 0 | L103: =[2]sales_BI!H102 -> 3000 | M103: =[2]sales_BI!L102 -> 0 | N103: 0
B104: =[2]sales_BI!J103 -> 46081 | C104: =[2]sales_BI!$K$2 -> 04:36 p. m. | D104: Normal | E104: =[2]sales!C106 -> Chorizo | F104: =+VLOOKUP(sales[[#This Row],[Fecha]],maestro!A:C,3,0) -> 1 | H104: =+VLOOKUP(sales[[#This Row],[Fecha]],maestro!A:D,4,0) -> C) Sábado | I104: =+TEXT(B104,"ddd") -> sáb | J104: =+TEXT(B104,"mmmm") -> febrero | K104: =+M104*0.35 -> 0 | L104: =[2]sales_BI!H103 -> 8000 | M104: =[2]sales_BI!L103 -> 0 | N104: 0
B105: =[2]sales_BI!J104 -> 46081 | C105: =[2]sales_BI!$K$2 -> 04:36 p. m. | D105: Normal | E105: =[2]sales!C107 -> tinto | F105: =+VLOOKUP(sales[[#This Row],[Fecha]],maestro!A:C,3,0) -> 1 | H105: =+VLOOKUP(sales[[#This Row],[Fecha]],maestro!A:D,4,0) -> C) Sábado | I105: =+TEXT(B105,"ddd") -> sáb | J105: =+TEXT(B105,"mmmm") -> febrero | K105: =+M105*0.35 -> 0 | L105: =[2]sales_BI!H104 -> 2000 | M105: =[2]sales_BI!L104 -> 0 | N105: 0
...

Sheet products
A1: nombre_producto | B1: precio_producto | C1: costo_producto
A2: Chorizo | B2: 8000 | C2: =3500+8000 -> 11500
A3: Hit | B3: 4500 | C3: 2416.6667
A4: Coca cola | B4: 3000 | C4: 1200
A5: Agua | B5: 3000 | C5: 1200
A6: Postobon | B6: 3000 | C6: 1166.6667 | F6: agua | G6: 33000 | H6: 24 | I6: =+G6/H6 -> 1375
A7: Chori- CRUDO | B7: 4500 | C7: 3500 | F7: hit | G7: 29000 | H7: 12 | I7: =+G7/H7 -> 2416.6667
A8: parri tres carnes | B8: 35000 | C8: 25000 | F8: postobon | G8: 35000 | H8: 30 | I8: =+G8/H8 -> 1166.6667
A9: carne + chorizo | B9: 25000 | C9: 15000 | F9: coca cola | G9: 36000 | H9: 30 | I9: =+G9/H9 -> 1200
A10: tinto | B10: 2000 | C10: 800
A11: parri 48 | B11: 48000 | C11: 30000
A12: parri 70 | B12: 70000 | C12: 45000
A13: parri 40 | B13: 40000 | C13: 25000

Sheet egresos
B2: Fecha | C2: dia_sem | D2: Gastos | E2: Arriendo | F2: Servicios | G2: Gas | H2: Agua | I2: Internet | J2: Electricidad | K2: Nomina | L2: Cajero | M2: Parrillero | N2: Domiciliario
B3: 46068 | C3: =+TEXT(sales2[[#This Row],[Fecha]],"ddd") -> dom | D3: =+sales2[[#This Row],[Arriendo]]+sales2[[#This Row],[Gas]]+sales2[[#This Row],[Agua]]+sales2[[#This Row],[Electricidad]]+sales2[[#This Row],[Nomina]] -> 0 | E3: =+VLOOKUP(sales2[[#This Row],[Fecha]],Opex!C:J,8,1) -> 0 | F3: =+SUM(sales2[[#This Row],[Gas]:[Electricidad]]) -> 0 | K3: =+SUM(sales2[[#This Row],[Cajero]:[Domiciliario]]) -> 0 | L3: 0 | M3: 0 | N3: 0 | Q3: =+#REF! -> #REF!
B4: =+B3+1 -> 46069 | C4: =+TEXT(sales2[[#This Row],[Fecha]],"ddd") -> lun | D4: =+sales2[[#This Row],[Arriendo]]+sales2[[#This Row],[Gas]]+sales2[[#This Row],[Agua]]+sales2[[#This Row],[Electricidad]]+sales2[[#This Row],[Nomina]] -> 0 | E4: =+VLOOKUP(sales2[[#This Row],[Fecha]],Opex!C:J,8,1) -> 0 | F4: =+SUM(sales2[[#This Row],[Gas]:[Electricidad]]) -> 0 | K4: =+SUM(sales2[[#This Row],[Cajero]:[Domiciliario]]) -> 0 | L4: 0 | M4: 0 | N4: 0
B5: =+B4+1 -> 46070 | C5: =+TEXT(sales2[[#This Row],[Fecha]],"ddd") -> mar | D5: =+sales2[[#This Row],[Arriendo]]+sales2[[#This Row],[Gas]]+sales2[[#This Row],[Agua]]+sales2[[#This Row],[Electricidad]]+sales2[[#This Row],[Nomina]] -> 0 | E5: =+VLOOKUP(sales2[[#This Row],[Fecha]],Opex!C:J,8,1) -> 0 | F5: =+SUM(sales2[[#This Row],[Gas]:[Electricidad]]) -> 0 | K5: =+SUM(sales2[[#This Row],[Cajero]:[Domiciliario]]) -> 0 | L5: 0 | M5: 0 | N5: 0
B6: =+B5+1 -> 46071 | C6: =+TEXT(sales2[[#This Row],[Fecha]],"ddd") -> mié | D6: =+sales2[[#This Row],[Arriendo]]+sales2[[#This Row],[Gas]]+sales2[[#This Row],[Agua]]+sales2[[#This Row],[Electricidad]]+sales2[[#This Row],[Nomina]] -> 0 | E6: =+VLOOKUP(sales2[[#This Row],[Fecha]],Opex!C:J,8,1) -> 0 | F6: =+SUM(sales2[[#This Row],[Gas]:[Electricidad]]) -> 0 | K6: =+SUM(sales2[[#This Row],[Cajero]:[Domiciliario]]) -> 0 | L6: 0 | M6: 0 | N6: 0
B7: =+B6+1 -> 46072 | C7: =+TEXT(sales2[[#This Row],[Fecha]],"ddd") -> jue | D7: =+sales2[[#This Row],[Arriendo]]+sales2[[#This Row],[Gas]]+sales2[[#This Row],[Agua]]+sales2[[#This Row],[Electricidad]]+sales2[[#This Row],[Nomina]] -> 0 | E7: =+VLOOKUP(sales2[[#This Row],[Fecha]],Opex!C:J,8,1) -> 0 | F7: =+SUM(sales2[[#This Row],[Gas]:[Electricidad]]) -> 0 | K7: =+SUM(sales2[[#This Row],[Cajero]:[Domiciliario]]) -> 0 | L7: 0 | M7: 0 | N7: 0
B8: =+B7+1 -> 46073 | C8: =+TEXT(sales2[[#This Row],[Fecha]],"ddd") -> vie | D8: =+sales2[[#This Row],[Arriendo]]+sales2[[#This Row],[Gas]]+sales2[[#This Row],[Agua]]+sales2[[#This Row],[Electricidad]]+sales2[[#This Row],[Nomina]] -> 0 | E8: =+VLOOKUP(sales2[[#This Row],[Fecha]],Opex!C:J,8,1) -> 0 | F8: =+SUM(sales2[[#This Row],[Gas]:[Electricidad]]) -> 0 | K8: =+SUM(sales2[[#This Row],[Cajero]:[Domiciliario]]) -> 0 | L8: 0 | M8: 0 | N8: 0 | Q8: =25000*30 -> 750000
B9: =+B8+1 -> 46074 | C9: =+TEXT(sales2[[#This Row],[Fecha]],"ddd") -> sáb | D9: =+sales2[[#This Row],[Arriendo]]+sales2[[#This Row],[Gas]]+sales2[[#This Row],[Agua]]+sales2[[#This Row],[Electricidad]]+sales2[[#This Row],[Nomina]] -> 0 | E9: =+VLOOKUP(sales2[[#This Row],[Fecha]],Opex!C:J,8,1) -> 0 | F9: =+SUM(sales2[[#This Row],[Gas]:[Electricidad]]) -> 0 | K9: =+SUM(sales2[[#This Row],[Cajero]:[Domiciliario]]) -> 0 | L9: 0 | M9: 0 | N9: 0
B10: =+B9+1 -> 46075 | C10: =+TEXT(sales2[[#This Row],[Fecha]],"ddd") -> dom | D10: =+sales2[[#This Row],[Arriendo]]+sales2[[#This Row],[Gas]]+sales2[[#This Row],[Agua]]+sales2[[#This Row],[Electricidad]]+sales2[[#This Row],[Nomina]] -> 0 | E10: =+VLOOKUP(sales2[[#This Row],[Fecha]],Opex!C:J,8,1) -> 0 | F10: =+SUM(sales2[[#This Row],[Gas]:[Electricidad]]) -> 0 | K10: =+SUM(sales2[[#This Row],[Cajero]:[Domiciliario]]) -> 0 | L10: 0 | M10: 0 | N10: 0
B11: =+B10+1 -> 46076 | C11: =+TEXT(sales2[[#This Row],[Fecha]],"ddd") -> lun | D11: =+sales2[[#This Row],[Arriendo]]+sales2[[#This Row],[Gas]]+sales2[[#This Row],[Agua]]+sales2[[#This Row],[Electricidad]]+sales2[[#This Row],[Nomina]] -> 60000 | E11: =+VLOOKUP(sales2[[#This Row],[Fecha]],Opex!C:J,8,1) -> 0 | F11: =+SUM(sales2[[#This Row],[Gas]:[Electricidad]]) -> 0 | K11: =+SUM(sales2[[#This Row],[Cajero]:[Domiciliario]]) -> 60000 | L11: 60000 | M11: 0 | N11: 0
B12: =+B11+1 -> 46077 | C12: =+TEXT(sales2[[#This Row],[Fecha]],"ddd") -> mar | D12: =+sales2[[#This Row],[Arriendo]]+sales2[[#This Row],[Gas]]+sales2[[#This Row],[Agua]]+sales2[[#This Row],[Electricidad]]+sales2[[#This Row],[Nomina]] -> 70000 | E12: =+VLOOKUP(sales2[[#This Row],[Fecha]],Opex!C:J,8,1) -> 0 | F12: =+SUM(sales2[[#This Row],[Gas]:[Electricidad]]) -> 0 | K12: =+SUM(sales2[[#This Row],[Cajero]:[Domiciliario]]) -> 70000 | L12: 70000 | M12: 0 | N12: 0
B13: =+B12+1 -> 46078 | C13: =+TEXT(sales2[[#This Row],[Fecha]],"ddd") -> mié | D13: =+sales2[[#This Row],[Arriendo]]+sales2[[#This Row],[Gas]]+sales2[[#This Row],[Agua]]+sales2[[#This Row],[Electricidad]]+sales2[[#This Row],[Nomina]] -> 70000 | E13: =+VLOOKUP(sales2[[#This Row],[Fecha]],Opex!C:J,8,1) -> 0 | F13: =+SUM(sales2[[#This Row],[Gas]:[Electricidad]]) -> 0 | K13: =+SUM(sales2[[#This Row],[Cajero]:[Domiciliario]]) -> 70000 | L13: 70000 | M13: 0 | N13: 0
B14: =+B13+1 -> 46079 | C14: =+TEXT(sales2[[#This Row],[Fecha]],"ddd") -> jue | D14: =+sales2[[#This Row],[Arriendo]]+sales2[[#This Row],[Gas]]+sales2[[#This Row],[Agua]]+sales2[[#This Row],[Electricidad]]+sales2[[#This Row],[Nomina]] -> 70000 | E14: =+VLOOKUP(sales2[[#This Row],[Fecha]],Opex!C:J,8,1) -> 0 | F14: =+SUM(sales2[[#This Row],[Gas]:[Electricidad]]) -> 0 | K14: =+SUM(sales2[[#This Row],[Cajero]:[Domiciliario]]) -> 70000 | L14: 70000 | M14: 0 | N14: 0
B15: =+B14+1 -> 46080 | C15: =+TEXT(sales2[[#This Row],[Fecha]],"ddd") -> vie | D15: =+sales2[[#This Row],[Arriendo]]+sales2[[#This Row],[Gas]]+sales2[[#This Row],[Agua]]+sales2[[#This Row],[Electricidad]]+sales2[[#This Row],[Nomina]] -> 70000 | E15: =+VLOOKUP(sales2[[#This Row],[Fecha]],Opex!C:J,8,1) -> 0 | F15: =+SUM(sales2[[#This Row],[Gas]:[Electricidad]]) -> 0 | K15: =+SUM(sales2[[#This Row],[Cajero]:[Domiciliario]]) -> 70000 | L15: 70000 | M15: 0 | N15: 0
B16: =+B15+1 -> 46081 | C16: =+TEXT(sales2[[#This Row],[Fecha]],"ddd") -> sáb | D16: =+sales2[[#This Row],[Arriendo]]+sales2[[#This Row],[Gas]]+sales2[[#This Row],[Agua]]+sales2[[#This Row],[Electricidad]]+sales2[[#This Row],[Nomina]] -> 70000 | E16: =+VLOOKUP(sales2[[#This Row],[Fecha]],Opex!C:J,8,1) -> 0 | F16: =+SUM(sales2[[#This Row],[Gas]:[Electricidad]]) -> 0 | K16: =+SUM(sales2[[#This Row],[Cajero]:[Domiciliario]]) -> 70000 | L16: 70000 | M16: 0 | N16: 0
B17: =+B16+1 -> 46082 | C17: =+TEXT(sales2[[#This Row],[Fecha]],"ddd") -> dom | D17: =+sales2[[#This Row],[Arriendo]]+sales2[[#This Row],[Gas]]+sales2[[#This Row],[Agua]]+sales2[[#This Row],[Electricidad]]+sales2[[#This Row],[Nomina]] -> 0 | E17: =+VLOOKUP(sales2[[#This Row],[Fecha]],Opex!C:J,8,1) -> 0 | F17: =+SUM(sales2[[#This Row],[Gas]:[Electricidad]]) -> 0 | K17: =+SUM(sales2[[#This Row],[Cajero]:[Domiciliario]]) -> 0 | L17: 0 | M17: 0 | N17: 0
B18: =+B17+1 -> 46083 | C18: =+TEXT(sales2[[#This Row],[Fecha]],"ddd") -> lun | D18: =+sales2[[#This Row],[Arriendo]]+sales2[[#This Row],[Gas]]+sales2[[#This Row],[Agua]]+sales2[[#This Row],[Electricidad]]+sales2[[#This Row],[Nomina]] -> 0 | E18: =+VLOOKUP(sales2[[#This Row],[Fecha]],Opex!C:J,8,1) -> 0 | F18: =+SUM(sales2[[#This Row],[Gas]:[Electricidad]]) -> 0 | K18: =+SUM(sales2[[#This Row],[Cajero]:[Domiciliario]]) -> 0 | L18: 0 | M18: 0 | N18: 0
B19: =+B18+1 -> 46084 | C19: =+TEXT(sales2[[#This Row],[Fecha]],"ddd") -> mar | D19: =+sales2[[#This Row],[Arriendo]]+sales2[[#This Row],[Gas]]+sales2[[#This Row],[Agua]]+sales2[[#This Row],[Electricidad]]+sales2[[#This Row],[Nomina]] -> 0 | E19: =+VLOOKUP(sales2[[#This Row],[Fecha]],Opex!C:J,8,1) -> 0 | F19: =+SUM(sales2[[#This Row],[Gas]:[Electricidad]]) -> 0 | K19: =+SUM(sales2[[#This Row],[Cajero]:[Domiciliario]]) -> 0 | L19: 0 | M19: 0 | N19: 0
B20: =+B19+1 -> 46085 | C20: =+TEXT(sales2[[#This Row],[Fecha]],"ddd") -> mié | D20: =+sales2[[#This Row],[Arriendo]]+sales2[[#This Row],[Gas]]+sales2[[#This Row],[Agua]]+sales2[[#This Row],[Electricidad]]+sales2[[#This Row],[Nomina]] -> 0 | E20: =+VLOOKUP(sales2[[#This Row],[Fecha]],Opex!C:J,8,1) -> 0 | F20: =+SUM(sales2[[#This Row],[Gas]:[Electricidad]]) -> 0 | K20: =+SUM(sales2[[#This Row],[Cajero]:[Domiciliario]]) -> 0 | L20: 0 | M20: 0 | N20: 0
... B40: =+B39+1 -> 46105 | C40: =+TEXT(sales2[[#This Row],[Fecha]],"ddd") -> mar | D40: =+sales2[[#This Row],[Arriendo]]+sales2[[#This Row],[Gas]]+sales2[[#This Row],[Agua]]+sales2[[#This Row],[Electricidad]]+sales2[[#This Row],[Nomina]] -> 55000 | E40: =+VLOOKUP(sales2[[#This Row],[Fecha]],Opex!C:J,8,1) -> 55000 | F40: =+SUM(sales2[[#This Row],[Gas]:[Electricidad]]) -> 0 | K40: =+SUM(sales2[[#This Row],[Cajero]:[Domiciliario]]) -> 0 | L40: 0 | M40: 0 | N40: 0
B41: =+B40+1 -> 46106 | C41: =+TEXT(sales2[[#This Row],[Fecha]],"ddd") -> mié | D41: =+sales2[[#This Row],[Arriendo]]+sales2[[#This Row],[Gas]]+sales2[[#This Row],[Agua]]+sales2[[#This Row],[Electricidad]]+sales2[[#This Row],[Nomina]] -> 55000 | E41: =+VLOOKUP(sales2[[#This Row],[Fecha]],Opex!C:J,8,1) -> 55000 | F41: =+SUM(sales2[[#This Row],[Gas]:[Electricidad]]) -> 0 | K41: =+SUM(sales2[[#This Row],[Cajero]:[Domiciliario]]) -> 0 | L41: 0 | M41: 0 | N41: 0 | P41: 150 a Janet
B42: =+B41+1 -> 46107 | C42: =+TEXT(sales2[[#This Row],[Fecha]],"ddd") -> jue | D42: =+sales2[[#This Row],[Arriendo]]+sales2[[#This Row],[Gas]]+sales2[[#This Row],[Agua]]+sales2[[#This Row],[Electricidad]]+sales2[[#This Row],[Nomina]] -> 55000 | E42: =+VLOOKUP(sales2[[#This Row],[Fecha]],Opex!C:J,8,1) -> 55000 | F42: =+SUM(sales2[[#This Row],[Gas]:[Electricidad]]) -> 0 | K42: =+SUM(sales2[[#This Row],[Cajero]:[Domiciliario]]) -> 0 | L42: 0 | M42: 0 | N42: 0 | P42: le pago 100 al de la fama
B43: =+B42+1 -> 46108 | C43: =+TEXT(sales2[[#This Row],[Fecha]],"ddd") -> vie | D43: =+sales2[[#This Row],[Arriendo]]+sales2[[#This Row],[Gas]]+sales2[[#This Row],[Agua]]+sales2[[#This Row],[Electricidad]]+sales2[[#This Row],[Nomina]] -> 55000 | E43: =+VLOOKUP(sales2[[#This Row],[Fecha]],Opex!C:J,8,1) -> 55000 | F43: =+SUM(sales2[[#This Row],[Gas]:[Electricidad]]) -> 0 | K43: =+SUM(sales2[[#This Row],[Cajero]:[Domiciliario]]) -> 0 | L43: 0 | M43: 0 | N43: 0 | P43: 50,000 platano
B44: =+B43+1 -> 46109 | C44: =+TEXT(sales2[[#This Row],[Fecha]],"ddd") -> sáb | D44: =+sales2[[#This Row],[Arriendo]]+sales2[[#This Row],[Gas]]+sales2[[#This Row],[Agua]]+sales2[[#This Row],[Electricidad]]+sales2[[#This Row],[Nomina]] -> 55000 | E44: =+VLOOKUP(sales2[[#This Row],[Fecha]],Opex!C:J,8,1) -> 55000 | F44: =+SUM(sales2[[#This Row],[Gas]:[Electricidad]]) -> 0 | K44: =+SUM(sales2[[#This Row],[Cajero]:[Domiciliario]]) -> 0 | L44: 0 | M44: 0 | N44: 0
B45: =+B44+1 -> 46110 | C45: =+TEXT(sales2[[#This Row],[Fecha]],"ddd") -> dom | D45: =+sales2[[#This Row],[Arriendo]]+sales2[[#This Row],[Gas]]+sales2[[#This Row],[Agua]]+sales2[[#This Row],[Electricidad]]+sales2[[#This Row],[Nomina]] -> 55000 | E45: =+VLOOKUP(sales2[[#This Row],[Fecha]],Opex!C:J,8,1) -> 55000 | F45: =+SUM(sales2[[#This Row],[Gas]:[Electricidad]]) -> 0 | K45: =+SUM(sales2[[#This Row],[Cajero]:[Domiciliario]]) -> 0 | L45: 0 | M45: 0 | N45: 0
B46: =+B45+1 -> 46111 | C46: =+TEXT(sales2[[#This Row],[Fecha]],"ddd") -> lun | D46: =+sales2[[#This Row],[Arriendo]]+sales2[[#This Row],[Gas]]+sales2[[#This Row],[Agua]]+sales2[[#This Row],[Electricidad]]+sales2[[#This Row],[Nomina]] -> 55000 | E46: =+VLOOKUP(sales2[[#This Row],[Fecha]],Opex!C:J,8,1) -> 55000 | F46: =+SUM(sales2[[#This Row],[Gas]:[Electricidad]]) -> 0 | K46: =+SUM(sales2[[#This Row],[Cajero]:[Domiciliario]]) -> 0 | L46: 0 | M46: 0 | N46: 0 | P46: 50,000 platano
B47: =+B46+1 -> 46112 | C47: =+TEXT(sales2[[#This Row],[Fecha]],"ddd") -> mar | D47: =+sales2[[#This Row],[Arriendo]]+sales2[[#This Row],[Gas]]+sales2[[#This Row],[Agua]]+sales2[[#This Row],[Electricidad]]+sales2[[#This Row],[Nomina]] -> 55000 | E47: =+VLOOKUP(sales2[[#This Row],[Fecha]],Opex!C:J,8,1) -> 55000 | F47: =+SUM(sales2[[#This Row],[Gas]:[Electricidad]]) -> 0 | K47: =+SUM(sales2[[#This Row],[Cajero]:[Domiciliario]]) -> 0 | L47: 0 | M47: 0 | N47: 0
B48: =+B47+1 -> 46113 | C48: =+TEXT(sales2[[#This Row],[Fecha]],"ddd") -> mié | D48: =+sales2[[#This Row],[Arriendo]]+sales2[[#This Row],[Gas]]+sales2[[#This Row],[Agua]]+sales2[[#This Row],[Electricidad]]+sales2[[#This Row],[Nomina]] -> 55000 | E48: =+VLOOKUP(sales2[[#This Row],[Fecha]],Opex!C:J,8,1) -> 55000 | F48: =+SUM(sales2[[#This Row],[Gas]:[Electricidad]]) -> 0 | K48: =+SUM(sales2[[#This Row],[Cajero]:[Domiciliario]]) -> 0 | L48: 0 | M48: 0 | N48: 0 | P48: 3 almuerzo y petaco de cerveza
B49: =+B48+1 -> 46114 | C49: =+TEXT(sales2[[#This Row],[Fecha]],"ddd") -> jue | D49: =+sales2[[#This Row],[Arriendo]]+sales2[[#This Row],[Gas]]+sales2[[#This Row],[Agua]]+sales2[[#This Row],[Electricidad]]+sales2[[#This Row],[Nomina]] -> 55000 | E49: =+VLOOKUP(sales2[[#This Row],[Fecha]],Opex!C:J,8,1) -> 55000 | F49: =+SUM(sales2[[#This Row],[Gas]:[Electricidad]]) -> 0 | L49: 0 | M49: 0 | N49: 0 | Q49: vereda el verganzo | R49: sector, escuela, asadres
B50: =+B49+1 -> 46115 | C50: =+TEXT(sales2[[#This Row],[Fecha]],"ddd") -> vie | D50: =+sales2[[#This Row],[Arriendo]]+sales2[[#This Row],[Gas]]+sales2[[#This Row],[Agua]]+sales2[[#This Row],[Electricidad]]+sales2[[#This Row],[Nomina]] -> 55000 | E50: =+VLOOKUP(sales2[[#This Row],[Fecha]],Opex!C:J,8,1) -> 55000 | F50: =+SUM(sales2[[#This Row],[Gas]:[Electricidad]]) -> 0 | L50: 0 | M50: 0 | N50: 0
B51: =+B50+1 -> 46116 | C51: =+TEXT(sales2[[#This Row],[Fecha]],"ddd") -> sáb | D51: =+sales2[[#This Row],[Arriendo]]+sales2[[#This Row],[Gas]]+sales2[[#This Row],[Agua]]+sales2[[#This Row],[Electricidad]]+sales2[[#This Row],[Nomina]] -> 55000 | E51: =+VLOOKUP(sales2[[#This Row],[Fecha]],Opex!C:J,8,1) -> 55000 | F51: =+SUM(sales2[[#This Row],[Gas]:[Electricidad]]) -> 0 | L51: 0 | M51: 0 | N51: 0
B52: =+B51+1 -> 46117 | C52: =+TEXT(sales2[[#This Row],[Fecha]],"ddd") -> dom | D52: =+sales2[[#This Row],[Arriendo]]+sales2[[#This Row],[Gas]]+sales2[[#This Row],[Agua]]+sales2[[#This Row],[Electricidad]]+sales2[[#This Row],[Nomina]] -> 55000 | E52: =+VLOOKUP(sales2[[#This Row],[Fecha]],Opex!C:J,8,1) -> 55000 | F52: =+SUM(sales2[[#This Row],[Gas]:[Electricidad]]) -> 0 | L52: 0 | M52: 0 | N52: 0 | P52: 3000 | R52: Almierzo de $ 10,000
B53: =+B52+1 -> 46118 | C53: =+TEXT(sales2[[#This Row],[Fecha]],"ddd") -> lun | D53: =+sales2[[#This Row],[Arriendo]]+sales2[[#This Row],[Gas]]+sales2[[#This Row],[Agua]]+sales2[[#This Row],[Electricidad]]+sales2[[#This Row],[Nomina]] -> 55000 | E53: =+VLOOKUP(sales2[[#This Row],[Fecha]],Opex!C:J,8,1) -> 55000 | F53: =+SUM(sales2[[#This Row],[Gas]:[Electricidad]]) -> 0 | L53: 0 | M53: 0 | N53: 0 | P53: Pollo. $ 9000 | R53: Pollo. $ 20,000
B54: =+B53+1 -> 46119 | C54: =+TEXT(sales2[[#This Row],[Fecha]],"ddd") -> mar | D54: =+sales2[[#This Row],[Arriendo]]+sales2[[#This Row],[Gas]]+sales2[[#This Row],[Agua]]+sales2[[#This Row],[Electricidad]]+sales2[[#This Row],[Nomina]] -> 55000 | E54: =+VLOOKUP(sales2[[#This Row],[Fecha]],Opex!C:J,8,1) -> 55000 | F54: =+SUM(sales2[[#This Row],[Gas]:[Electricidad]]) -> 0 | L54: 0 | M54: 0 | N54: 0
B55: =+B54+1 -> 46120 | C55: =+TEXT(sales2[[#This Row],[Fecha]],"ddd") -> mié | D55: =+sales2[[#This Row],[Arriendo]]+sales2[[#This Row],[Gas]]+sales2[[#This Row],[Agua]]+sales2[[#This Row],[Electricidad]]+sales2[[#This Row],[Nomina]] -> 55000 | E55: =+VLOOKUP(sales2[[#This Row],[Fecha]],Opex!C:J,8,1) -> 55000 | F55: =+SUM(sales2[[#This Row],[Gas]:[Electricidad]]) -> 0 | L55: 0 | M55: 0 | N55: 0
B56: =+B55+1 -> 46121 | C56: =+TEXT(sales2[[#This Row],[Fecha]],"ddd") -> jue | D56: =+sales2[[#This Row],[Arriendo]]+sales2[[#This Row],[Gas]]+sales2[[#This Row],[Agua]]+sales2[[#This Row],[Electricidad]]+sales2[[#This Row],[Nomina]] -> 55000 | E56: =+VLOOKUP(sales2[[#This Row],[Fecha]],Opex!C:J,8,1) -> 55000 | F56: =+SUM(sales2[[#This Row],[Gas]:[Electricidad]]) -> 0 | L56: 0 | M56: 0 | N56: 0
B57: =+B56+1 -> 46122 | C57: =+TEXT(sales2[[#This Row],[Fecha]],"ddd") -> vie | D57: =+sales2[[#This Row],[Arriendo]]+sales2[[#This Row],[Gas]]+sales2[[#This Row],[Agua]]+sales2[[#This Row],[Electricidad]]+sales2[[#This Row],[Nomina]] -> 55000 | E57: =+VLOOKUP(sales2[[#This Row],[Fecha]],Opex!C:J,8,1) -> 55000 | F57: =+SUM(sales2[[#This Row],[Gas]:[Electricidad]]) -> 0 | L57: 0 | M57: 0 | N57: 0
B58: =+B57+1 -> 46123 | C58: =+TEXT(sales2[[#This Row],[Fecha]],"ddd") -> sáb | D58: =+sales2[[#This Row],[Arriendo]]+sales2[[#This Row],[Gas]]+sales2[[#This Row],[Agua]]+sales2[[#This Row],[Electricidad]]+sales2[[#This Row],[Nomina]] -> 55000 | E58: =+VLOOKUP(sales2[[#This Row],[Fecha]],Opex!C:J,8,1) -> 55000 | F58: =+SUM(sales2[[#This Row],[Gas]:[Electricidad]]) -> 0 | L58: 0 | M58: 0 | N58: 0
B59: =+B58+1 -> 46124 | C59: =+TEXT(sales2[[#This Row],[Fecha]],"ddd") -> dom | D59: =+sales2[[#This Row],[Arriendo]]+sales2[[#This Row],[Gas]]+sales2[[#This Row],[Agua]]+sales2[[#This Row],[Electricidad]]+sales2[[#This Row],[Nomina]] -> 55000 | E59: =+VLOOKUP(sales2[[#This Row],[Fecha]],Opex!C:J,8,1) -> 55000 | F59: =+SUM(sales2[[#This Row],[Gas]:[Electricidad]]) -> 0 | L59: 0 | M59: 0 | N59: 0
B60: =+B59+1 -> 46125 | C60: =+TEXT(sales2[[#This Row],[Fecha]],"ddd") -> lun | D60: =+sales2[[#This Row],[Arriendo]]+sales2[[#This Row],[Gas]]+sales2[[#This Row],[Agua]]+sales2[[#This Row],[Electricidad]]+sales2[[#This Row],[Nomina]] -> 55000 | E60: =+VLOOKUP(sales2[[#This Row],[Fecha]],Opex!C:J,8,1) -> 55000 | F60: =+SUM(sales2[[#This Row],[Gas]:[Electricidad]]) -> 0 | L60: 0 | M60: 0 | N60: 0
...

Sheet bolsas
E1: 320 | F1: apartamentos | G1: octubre
C2: 6300
C3: 7100
C4: =+SUM(C2:C3) -> 13400
C5: 15240 | D5: bolsas
C6: =+C4+C5 -> 28640

Sheet Opex
B1: Tipo | C1: Fecha | D1: fecha_fin | E1: Mes | F1: Cuentas x Pagar | G1: Día C x P | H1: Arriendo | I1: No. Días Arriendo | J1: Día Arriendo | K1: Gas | L1: No. Días Gas | M1: Consumo (m3) | N1: Costo prom. Gas | O1: Día Gas | P1: Agua | Q1: Dìa Agua | R1: Energia | S1: Financiació Energia | T1: No. Días Energia | U1: Consumo (KhW | V1: Costo prom. Energia | W1: Fecha corte enega | X1: Día Energia
B2: Histórico | C2: 46068 | D2: 46095 | E2: =+TEXT(C2,"mmmm") -> febrero | G2: =+Opex[[#This Row],[Cuentas x Pagar]]/31 -> 0 | H2: 0 | I2: =+Opex[[#This Row],[fecha_fin]]-Opex[[#This Row],[Fecha]] -> 27 | J2: =IFERROR(Opex[[#This Row],[Arriendo]]/Opex[[#This Row],[No. Días Arriendo]],0) -> 0 | K2: 430 | L2: 0 | M2: 0 | N2: =IFERROR(Opex[[#This Row],[Gas]]/Opex[[#This Row],[Consumo (m3)]],0) -> 0 | O2: =IFERROR(Opex[[#This Row],[Gas]]/Opex[[#This Row],[No. Días Arriendo]],0) -> 15.925926 | Q2: =IFERROR(Opex[[#This Row],[Agua]]/Opex[[#This Row],[No. Días Arriendo]],0) -> 0 | T2: =+AA2 -> 0 | V2: =IFERROR(Opex[[#This Row],[Energia]]/Opex[[#This Row],[Consumo (KhW]],0) -> 0 | X2: =IFERROR(Opex[[#This Row],[Energia]]/Opex[[#This Row],[No. Días Arriendo]],0) -> 0
B3: Forecast | C3: =+D2+1 -> 46096 | D3: 46126 | E3: =+TEXT(C3,"mmmm") -> marzo | G3: =+Opex[[#This Row],[Cuentas x Pagar]]/31 -> 0 | H3: 1650000 | I3: =+Opex[[#This Row],[fecha_fin]]-Opex[[#This Row],[Fecha]] -> 30 | J3: =IFERROR(Opex[[#This Row],[Arriendo]]/Opex[[#This Row],[No. Días Arriendo]],0) -> 55000 | K3: ='[3]Análisis Gas'!$I$22 -> 247319 | L3: =+#REF! -> #REF! | M3: =+AVERAGE(#REF!/#REF!,#REF!/#REF!,#REF!/#REF!)*Opex[[#This Row],[No. Días Gas]] -> #REF! | N3: =+AVERAGE(#REF!) -> #REF! | O3: =IFERROR(Opex[[#This Row],[Gas]]/Opex[[#This Row],[No. Días Arriendo]],0) -> 8243.9667 | P3: 120000 | Q3: =IFERROR(Opex[[#This Row],[Agua]]/Opex[[#This Row],[No. Días Arriendo]],0) -> 4000 | R3: ='[3]Análisis Energia'!$I$24 -> 319050 | S3: ='[4]Radicado Energia'!$C33 -> 264247 | T3: =+#REF! -> #REF! | U3: =+AVERAGE(#REF!/#REF!,#REF!/#REF!) -> #REF! | V3: =+AVERAGE(#REF!) -> #REF! | W3: Nd | X3: =IFERROR(Opex[[#This Row],[Energia]]/Opex[[#This Row],[No. Días Arriendo]],0) -> 10635
B4: Forecast | C4: =+D3+1 -> 46127 | D4: 46156 | E4: =+TEXT(C4,"mmmm") -> abril | G4: =+Opex[[#This Row],[Cuentas x Pagar]]/31 -> 0 | H4: 1650000 | I4: =+Opex[[#This Row],[fecha_fin]]-Opex[[#This Row],[Fecha]] -> 29 | J4: =IFERROR(Opex[[#This Row],[Arriendo]]/Opex[[#This Row],[No. Días Arriendo]],0) -> 56896.552 | K4: ='[3]Análisis Gas'!$I$22 -> 247319 | L4: =+I3 -> 30 | M4: =+AVERAGE(#REF!/#REF!,#REF!/#REF!,M3/L3)*Opex[[#This Row],[No. Días Gas]] -> #REF! | N4: =+AVERAGE(N3:N3) -> #REF! | O4: =IFERROR(Opex[[#This Row],[Gas]]/Opex[[#This Row],[No. Días Arriendo]],0) -> 8528.2414 | P4: 120000 | Q4: =IFERROR(Opex[[#This Row],[Agua]]/Opex[[#This Row],[No. Días Arriendo]],0) -> 4137.931 | R4: =+AVERAGE(R3:R3) -> 319050 | S4: ='[4]Radicado Energia'!$C34 -> 264247 | T4: =+#REF! -> #REF! | U4: =+AVERAGE(#REF!/#REF!,#REF!/#REF!,#REF!/V3) -> #REF! | V4: =+AVERAGE(V3:V3) -> #REF! | W4: Nd | X4: =IFERROR(Opex[[#This Row],[Energia]]/Opex[[#This Row],[No. Días Arriendo]],0) -> 11001.724
B5: Forecast | C5: =+D4+1 -> 46157 | D5: 46187 | E5: =+TEXT(C5,"mmmm") -> mayo | G5: =+Opex[[#This Row],[Cuentas x Pagar]]/31 -> 0 | H5: 1650000 | I5: =+Opex[[#This Row],[fecha_fin]]-Opex[[#This Row],[Fecha]] -> 30 | J5: =IFERROR(Opex[[#This Row],[Arriendo]]/Opex[[#This Row],[No. Días Arriendo]],0) -> 55000 | K5: ='[3]Análisis Gas'!$I$22 -> 247319 | L5: =+I4 -> 29 | M5: =+AVERAGE(#REF!/#REF!,M3/L3,M4/L4)*Opex[[#This Row],[No. Días Gas]] -> #REF! | N5: =+AVERAGE(N3:N4) -> #REF! | O5: =IFERROR(Opex[[#This Row],[Gas]]/Opex[[#This Row],[No. Días Arriendo]],0) -> 8243.9667 | P5: 120000 | Q5: =IFERROR(Opex[[#This Row],[Agua]]/Opex[[#This Row],[No. Días Arriendo]],0) -> 4000 | R5: =+AVERAGE(R3:R4) -> 319050 | S5: ='[4]Radicado Energia'!$C35 -> 264247 | T5: =+#REF! -> #REF! | U5: =+AVERAGE(#REF!/#REF!,#REF!/V3,#REF!/V4) -> #REF! | V5: =+AVERAGE(V3:V4) -> #REF! | W5: Nd | X5: =IFERROR(Opex[[#This Row],[Energia]]/Opex[[#This Row],[No. Días Arriendo]],0) -> 10635
B6: Forecast | C6: =+D5+1 -> 46188 | D6: 46217 | E6: =+TEXT(C6,"mmmm") -> junio | G6: =+Opex[[#This Row],[Cuentas x Pagar]]/31 -> 0 | H6: 1650000 | I6: =+Opex[[#This Row],[fecha_fin]]-Opex[[#This Row],[Fecha]] -> 29 | J6: =IFERROR(Opex[[#This Row],[Arriendo]]/Opex[[#This Row],[No. Días Arriendo]],0) -> 56896.552 | K6: ='[3]Análisis Gas'!$I$22 -> 247319 | L6: =+I5 -> 30 | M6: =+AVERAGE(M3/L3,M4/L4,M5/L5)*Opex[[#This Row],[No. Días Gas]] -> #REF! | N6: =+AVERAGE(N3:N5) -> #REF! | O6: =IFERROR(Opex[[#This Row],[Gas]]/Opex[[#This Row],[No. Días Arriendo]],0) -> 8528.2414 | P6: 120000 | Q6: =IFERROR(Opex[[#This Row],[Agua]]/Opex[[#This Row],[No. Días Arriendo]],0) -> 4137.931 | R6: =+AVERAGE(R4:R5) -> 319050 | S6: ='[4]Radicado Energia'!$C36 -> 264247 | T6: =+#REF! -> #REF! | U6: =+AVERAGE(#REF!/V3,#REF!/V4,#REF!/V5) -> #REF! | V6: =+AVERAGE(V3:V5) -> #REF! | W6: Nd | X6: =IFERROR(Opex[[#This Row],[Energia]]/Opex[[#This Row],[No. Días Arriendo]],0) -> 11001.724
B7: Forecast | C7: =+D6+1 -> 46218 | D7: 46248 | E7: =+TEXT(C7,"mmmm") -> julio | G7: =+Opex[[#This Row],[Cuentas x Pagar]]/31 -> 0 | H7: 1650000 | I7: =+Opex[[#This Row],[fecha_fin]]-Opex[[#This Row],[Fecha]] -> 30 | J7: =IFERROR(Opex[[#This Row],[Arriendo]]/Opex[[#This Row],[No. Días Arriendo]],0) -> 55000 | K7: ='[3]Análisis Gas'!$I$22 -> 247319 | L7: =+I6 -> 29 | M7: =+AVERAGE(M4/L4,M5/L5,M6/L6)*Opex[[#This Row],[No. Días Gas]] -> #REF! | N7: =+AVERAGE(N4:N6) -> #REF! | O7: =IFERROR(Opex[[#This Row],[Gas]]/Opex[[#This Row],[No. Días Arriendo]],0) -> 8243.9667 | P7: 120000 | Q7: =IFERROR(Opex[[#This Row],[Agua]]/Opex[[#This Row],[No. Días Arriendo]],0) -> 4000 | R7: =+AVERAGE(R5:R6) -> 319050 | S7: ='[4]Radicado Energia'!$C37 -> 0 | T7: =+#REF! -> #REF! | U7: =+AVERAGE(#REF!/V4,#REF!/V5,#REF!/V6) -> #REF! | V7: =+AVERAGE(V4:V6) -> #REF! | W7: Nd | X7: =IFERROR(Opex[[#This Row],[Energia]]/Opex[[#This Row],[No. Días Arriendo]],0) -> 10635
B8: Forecast | C8: =+D7+1 -> 46249 | D8: 46279 | E8: =+TEXT(C8,"mmmm") -> agosto | G8: =+Opex[[#This Row],[Cuentas x Pagar]]/31 -> 0 | H8: 1650000 | I8: =+Opex[[#This Row],[fecha_fin]]-Opex[[#This Row],[Fecha]] -> 30 | J8: =IFERROR(Opex[[#This Row],[Arriendo]]/Opex[[#This Row],[No. Días Arriendo]],0) -> 55000 | K8: ='[3]Análisis Gas'!$I$22 -> 247319 | L8: =+I7 -> 30 | M8: =+AVERAGE(M5/L5,M6/L6,M7/L7)*Opex[[#This Row],[No. Días Gas]] -> #REF! | N8: =+AVERAGE(N5:N7) -> #REF! | O8: =IFERROR(Opex[[#This Row],[Gas]]/Opex[[#This Row],[No. Días Arriendo]],0) -> 8243.9667 | P8: 120000 | Q8: =IFERROR(Opex[[#This Row],[Agua]]/Opex[[#This Row],[No. Días Arriendo]],0) -> 4000 | R8: =+AVERAGE(R6:R7) -> 319050 | S8: ='[4]Radicado Energia'!$C38 -> 0 | T8: =+#REF! -> #REF! | U8: =+AVERAGE(#REF!/V5,#REF!/V6,#REF!/V7) -> #REF! | V8: =+AVERAGE(V5:V7) -> #REF! | W8: Nd | X8: =IFERROR(Opex[[#This Row],[Energia]]/Opex[[#This Row],[No. Días Arriendo]],0) -> 10635
B9: Forecast | C9: =+D8+1 -> 46280 | D9: 46309 | E9: =+TEXT(C9,"mmmm") -> septiembre | G9: =+Opex[[#This Row],[Cuentas x Pagar]]/31 -> 0 | H9: 1650000 | I9: =+Opex[[#This Row],[fecha_fin]]-Opex[[#This Row],[Fecha]] -> 29 | J9: =IFERROR(Opex[[#This Row],[Arriendo]]/Opex[[#This Row],[No. Días Arriendo]],0) -> 56896.552 | K9: ='[3]Análisis Gas'!$I$22 -> 247319 | L9: =+I8 -> 30 | M9: =+AVERAGE(M6/L6,M7/L7,M8/L8)*Opex[[#This Row],[No. Días Gas]] -> #REF! | N9: =+AVERAGE(N6:N8) -> #REF! | O9: =IFERROR(Opex[[#This Row],[Gas]]/Opex[[#This Row],[No. Días Arriendo]],0) -> 8528.2414 | P9: 120000 | Q9: =IFERROR(Opex[[#This Row],[Agua]]/Opex[[#This Row],[No. Días Arriendo]],0) -> 4137.931 | R9: =+AVERAGE(R7:R8) -> 319050 | S9: ='[4]Radicado Energia'!$C39 -> 0 | T9: =+#REF! -> #REF! | U9: =+AVERAGE(#REF!/V6,#REF!/V7,#REF!/V8) -> #REF! | V9: =+AVERAGE(V6:V8) -> #REF! | W9: Nd | X9: =IFERROR(Opex[[#This Row],[Energia]]/Opex[[#This Row],[No. Días Arriendo]],0) -> 11001.724
B10: Forecast | C10: =+D9+1 -> 46310 | D10: 46340 | E10: =+TEXT(C10,"mmmm") -> octubre | G10: =+Opex[[#This Row],[Cuentas x Pagar]]/31 -> 0 | H10: 1650000 | I10: =+Opex[[#This Row],[fecha_fin]]-Opex[[#This Row],[Fecha]] -> 30 | J10: =IFERROR(Opex[[#This Row],[Arriendo]]/Opex[[#This Row],[No. Días Arriendo]],0) -> 55000 | K10: ='[3]Análisis Gas'!$I$22 -> 247319 | L10: =+I9 -> 29 | M10: =+AVERAGE(M7/L7,M8/L8,M9/L9)*Opex[[#This Row],[No. Días Gas]] -> #REF! | N10: =+AVERAGE(N7:N9) -> #REF! | O10: =IFERROR(Opex[[#This Row],[Gas]]/Opex[[#This Row],[No. Días Arriendo]],0) -> 8243.9667 | P10: 120000 | Q10: =IFERROR(Opex[[#This Row],[Agua]]/Opex[[#This Row],[No. Días Arriendo]],0) -> 4000 | R10: =+AVERAGE(R8:R9) -> 319050 | S10: ='[4]Radicado Energia'!$C40 -> 0 | T10: =+#REF! -> #REF! | U10: =+AVERAGE(#REF!/V7,#REF!/V8,#REF!/V9) -> #REF! | V10: =+AVERAGE(V7:V9) -> #REF! | W10: Nd | X10: =IFERROR(Opex[[#This Row],[Energia]]/Opex[[#This Row],[No. Días Arriendo]],0) -> 10635
B11: Forecast | C11: =+D10+1 -> 46341 | D11: 46370 | E11: =+TEXT(C11,"mmmm") -> noviembre | G11: =+Opex[[#This Row],[Cuentas x Pagar]]/31 -> 0 | H11: 1650000 | I11: =+Opex[[#This Row],[fecha_fin]]-Opex[[#This Row],[Fecha]] -> 29 | J11: =IFERROR(Opex[[#This Row],[Arriendo]]/Opex[[#This Row],[No. Días Arriendo]],0) -> 56896.552 | K11: ='[3]Análisis Gas'!$I$22 -> 247319 | L11: =+I10 -> 30 | M11: =+AVERAGE(M8/L8,M9/L9,M10/L10)*Opex[[#This Row],[No. Días Gas]] -> #REF! | N11: =+AVERAGE(N8:N10) -> #REF! | O11: =IFERROR(Opex[[#This Row],[Gas]]/Opex[[#This Row],[No. Días Arriendo]],0) -> 8528.2414 | P11: 120000 | Q11: =IFERROR(Opex[[#This Row],[Agua]]/Opex[[#This Row],[No. Días Arriendo]],0) -> 4137.931 | R11: =+AVERAGE(R9:R10) -> 319050 | S11: ='[4]Radicado Energia'!$C41 -> 0 | T11: =+#REF! -> #REF! | U11: =+AVERAGE(#REF!/V8,#REF!/V9,#REF!/V10) -> #REF! | V11: =+AVERAGE(V8:V10) -> #REF! | W11: Nd | X11: =IFERROR(Opex[[#This Row],[Energia]]/Opex[[#This Row],[No. Días Arriendo]],0) -> 11001.724
B12: Forecast | C12: =+D11+1 -> 46371 | D12: 46401 | E12: =+TEXT(C12,"mmmm") -> diciembre | G12: =+Opex[[#This Row],[Cuentas x Pagar]]/31 -> 0 | H12: 1650000 | I12: =+Opex[[#This Row],[fecha_fin]]-Opex[[#This Row],[Fecha]] -> 30 | J12: =IFERROR(Opex[[#This Row],[Arriendo]]/Opex[[#This Row],[No. Días Arriendo]],0) -> 55000 | K12: ='[3]Análisis Gas'!$I$22 -> 247319 | L12: =+I11 -> 29 | M12: =+AVERAGE(M9/L9,M10/L10,M11/L11)*Opex[[#This Row],[No. Días Gas]] -> #REF! | N12: =+AVERAGE(N9:N11) -> #REF! | O12: =IFERROR(Opex[[#This Row],[Gas]]/Opex[[#This Row],[No. Días Arriendo]],0) -> 8243.9667 | P12: 120000 | Q12: =IFERROR(Opex[[#This Row],[Agua]]/Opex[[#This Row],[No. Días Arriendo]],0) -> 4000 | R12: =+AVERAGE(R10:R11) -> 319050 | S12: ='[4]Radicado Energia'!$C42 -> 0 | T12: =+#REF! -> #REF! | U12: =+AVERAGE(#REF!/V9,#REF!/V10,#REF!/V11) -> #REF! | V12: =+AVERAGE(V9:V11) -> #REF! | W12: Nd | X12: =IFERROR(Opex[[#This Row],[Energia]]/Opex[[#This Row],[No. Días Arriendo]],0) -> 10635
B13: Forecast | C13: =+D12+1 -> 46402 | D13: 46432 | E13: =+TEXT(C13,"mmmm") -> enero | G13: =+Opex[[#This Row],[Cuentas x Pagar]]/31 -> 0 | H13: 1650000 | I13: =+Opex[[#This Row],[fecha_fin]]-Opex[[#This Row],[Fecha]] -> 30 | J13: =IFERROR(Opex[[#This Row],[Arriendo]]/Opex[[#This Row],[No. Días Arriendo]],0) -> 55000 | K13: ='[3]Análisis Gas'!$I$22 -> 247319 | L13: =+I12 -> 30 | M13: =+AVERAGE(M10/L10,M11/L11,M12/L12)*Opex[[#This Row],[No. Días Gas]] -> #REF! | N13: =+AVERAGE(N10:N12) -> #REF! | O13: =IFERROR(Opex[[#This Row],[Gas]]/Opex[[#This Row],[No. Días Arriendo]],0) -> 8243.9667 | P13: 120000 | Q13: =IFERROR(Opex[[#This Row],[Agua]]/Opex[[#This Row],[No. Días Arriendo]],0) -> 4000 | R13: =+AVERAGE(R11:R12) -> 319050 | S13: ='[4]Radicado Energia'!$C43 -> 0 | T13: =+#REF! -> #REF! | U13: =+AVERAGE(#REF!/V10,#REF!/V11,#REF!/V12) -> #REF! | V13: =+AVERAGE(V10:V12) -> #REF! | W13: Nd | X13: =IFERROR(Opex[[#This Row],[Energia]]/Opex[[#This Row],[No. Días Arriendo]],0) -> 10635

Sheet Hoja3
A1: fecha_inicio | B1: fecha_fin | C1: tipo | E1: fecha
A2: 46068 | B2: 46095 | C2: uno | E2: 46095 | F2: =VLOOKUP(E2,A:C,3,TRUE) -> uno
A3: =+B2+1 -> 46096 | B3: 46126 | C3: do

Sheet Inicio
AB1: 0

Sheet Activos
B4: Tipo de obligación | C4: Proveedor | D4: Nombre proveedor | E4: Valor | F4: Plan B | H4: Tipo de gasto | I4: Valor | K4: Activo | L4: Patrimonio | M4: =+M5+M6 -> 18150000 | N4: =+M4/$K$5 -> 0.61570257
B5: Pasivo de corto plazo | C5: FINANCIERO | D5: Gota x Gota | E5: 350000 | F5: 0 | H5: Mes de Arriendo Marzo | I5: 1000000 | K5: =+M4+M7 -> 29478519 | L5: Planta y Equipo | M5: =+Planta_y_Equipo[[#Totals],[Valor]] -> 16020000 | N5: =+M5/$M$4 -> 0.88264463
B6: Pasivo de corto plazo | C6: ARRIENDO | D6: Arredatario | E6: 0 | F6: 0 | H6: Arriendo Apto. Marzo | I6: =550000/2 -> 275000 | L6: Inventario (Stock) | M6: =+Stock_Actual[[#Totals],[Valor]] -> 2130000 | N6: =+M6/$M$4 -> 0.11735537
B7: Pasivo de corto plazo | C7: Carne de cerdo | D7: Diego | E7: 1088000 | F7: 0 | H7: Acarreo | I7: 200000 | L7: Pasivo Total | M7: =+M8+M9 -> 11328519 | N7: =+M7/$K$5 -> 0.38429743 | O7: =+M7/M4 -> 0.62416083 | P7: =+M4-M7 -> 6821481
B8: Pasivo de corto plazo | C8: Carne de res | D8: Vecino | E8: 380000 | F8: 0 | H8: Publidad tarjeteria | I8: 100000 | L8: Pasivo de corto plazo | M8: =+SUMIF(B5:B23,L8,E5:E23) -> 4728920 | N8: =+M8/$M$7 -> 0.41743497
B9: Pasivo de corto plazo | C9: Carne de Pollo | D9: Nd | E9: 750000 | F9: 0 | H9: Total | I9: =SUBTOTAL(109,Gastos_entrada[Valor]) -> 1575000 | L9: Pasivo de largo plazo | M9: =+SUMIF(B5:B23,L9,E5:E23) -> 6599599 | N9: =+M9/$M$7 -> 0.58256503
B10: Pasivo de corto plazo | C10: NOMINA | D10: Nomina | E10: 150000 | F10: 0
B11: Pasivo de corto plazo | C11: PUBLICIDAD | D11: Nd | E11: 400000 | F11: =+E11 -> 400000 | M11: Ideal | N11: Actual
B12: Pasivo de corto plazo | C12: Pintura, local | D12: Nd | E12: 370000 | F12: 0 | L12: Nivel de Endeudamiento (NE) | M12: =+M15/K5 -> 0.15604583 | N12: =+M7/K5 -> 0.38429743 | O12: Nivel de endeudamiento crítico
B13: Pasivo de corto plazo | C13: Vitrina, ollas | D13: Vitrina, ollas | E13: 180000 | F13: 0 | L13: Autonomía | M13: =M15/M4 -> 0.25344353 | N13: =+M7/M4 -> 0.62416083 | O13: El 70% del patrimonio esta comprometido con deudas
B14: Pasivo de corto plazo | C14: CODENSA | D14: enel - 6451508-5 | E14: 1060920 | F14: =+E14 -> 1060920
B15: Pasivo de corto plazo | C15: Arriendo Apto. | D15: Sandra | E15: 0 | F15: =+E15 -> 0 | L15: Meta ideal deuda | M15: =$I$54 -> 4600000
B16: Pasivo de corto plazo | C16: Contingencia: Gas | D16: Ladron de Gas | E16: 0 | F16: 0 | L16: Meta a Pagar | M16: =+M7-M15 -> 6728519
B17: Pasivo de corto plazo | C17: Contingencia: Licuadora | D17: Licuadora | E17: 0 | F17: 0
B18: Pasivo de largo plazo | C18: FINANCIERO | D18: Saul | E18: 3000000 | F18: 0
B19: Pasivo de largo plazo | C19: Carne de cerdo | D19: Martin | E19: 300000 | F19: 0
B20: Pasivo de largo plazo | C20: Carne de cerdo | D20: Sarmiento | E20: 350000 | F20: 0
B21: Pasivo de largo plazo | C21: Carne de res | D21: Leornardo | E21: 1350000 | F21: 100000
B22: Pasivo de largo plazo | C22: Menudo y prestamo | D22: Hector | E22: 0 | F22: 0
B23: Pasivo de largo plazo | C23: Mercado | D23: Orlando | E23: 1599599 | F23: =+SUM(F5:F22) -> 1560920
B24: Total general | E24: 11328519
B34: Inversion Proyecto | C34: Origen Equipo | D34: Valor | H34: Materia Prima | I34: Valor
B35: Horno de pollos | C35: Nuevo | D35: 10000000 | H35: Carne | I35: 200000
B36: Bicicleta - Parrilla | C36: Propio | D36: 1800000 | H36: Pollo | I36: =50*20000 -> 1000000 | K36: 50 pollos
B37: olla arrocera | C37: Antiguo | D37: 600000 | H37: Hamburguesa | I37: 0 | K37: 25.000 a 10 cada
B38: Nevera | C38: Antiguo | D38: 600000 | H38: Bebidas | I38: 280000 | K38: 49 gaseosas litro y media
B39: Mesas 4 meseras | C39: Antiguo | D39: 500000 | H39: Sazón | I39: 300000 | K39: gaseosas pequeñas 50
B40: Estufa | C40: Nuevo | D40: 480000 | H40: Cerdo | I40: 0
B41: Campana | C41: Nuevo | D41: 320000 | H41: Mercado y Hamburguesa | I41: 200000 | K41: Sason para un mes | L41: 200000
B42: Licuadrora | C42: Nuevo | D42: 200000 | H42: Pescado | I42: 150000
B43: olla espres | C43: Antiguo | D43: 200000 | H43: Total | I43: =SUBTOTAL(109,Stock_Actual[Valor]) -> 2130000
B44: Platos, cubiertos, Tablas bajijas de plasticos | C44: Antiguo | D44: 200000
B45: Extractor | C45: Antiguo | D45: 200000
B46: Equipo de sonido | C46: Antiguo | D46: 150000 | H46: Materia Prima | I46: Valor
B47: Platero | C47: Nuevo | D47: 120000 | H47: Carne | I47: 1500000
B48: Mesa para lavar pollo | C48: Antiguo | D48: 120000 | H48: Pollo | I48: =50*20000 -> 1000000
B49: Otras ollas | C49: Antiguo | D49: 100000 | H49: Bebidas | I49: 800000 | K49: 50 pollos un millon | M49: 60.000 por millar
B50: Mesa para dejar ollas | C50: Antiguo | D50: 90000 | H50: Sazón | I50: 300000 | M50: 35000 por millar
B51: Bascula | C51: Nuevo | D51: 70000 | H51: Cerdo | I51: 500000
B52: Mesa madera | C52: Antiguo | D52: 70000 | H52: Mercado y Hamburguesa | I52: 200000
...

Sheet Ingresos
A2: Tipo día | B2: (Todas) | W2: Mes de análisis | X2: Venta | Y2: Promedio Venta | Z2: Gastos | AA2: Rent. trabajo | AB2: Prom. Rent. Trabajo | AQ2: Tipo día | AR2: (Todas)
W3: abril | X3: 5230000 | Y3: 174333.33 | Z3: 1082730 | AA3: 747770 | AB3: 24925.667
A4: Mes | B4: Fecha | C4: Día | D4: Venta | E4: Gastos | AJ4: Mes | AK4: Fecha | AL4: Día | AM4: Venta | AQ4: Mes | AR4: Fecha | AS4: Día | AT4: Gastos
A5: abril | B5: 10-abr | C5: vie | D5: 150000 | E5: 25091 | AJ5: abril | AK5: 10-abr | AL5: vie | AM5: 150000 | AQ5: abril | AR5: 10-abr | AS5: vie | AT5: 25091
B6: 11-abr | C6: sáb | D6: 160000 | E6: 25091 | W6: Tendencia | X6: Ventas | Y6: Rentabilidad | Z6: Gastos | AA6: Utilidad trabajo | AB6: E (Renta) | AC6: Target MC | AD6: Target Ventas | AK6: 11-abr | AL6: sáb | AM6: 160000 | AR6: 11-abr | AS6: sáb | AT6: 25091
B7: 12-abr | C7: dom | D7: 160000 | E7: 25091 | W7: Días trascurridos | X7: =+SUBTOTAL(3,B5:B1048576) -> 30 | AK7: 12-abr | AL7: dom | AM7: 160000 | AR7: 12-abr | AS7: dom | AT7: 25091
B8: 13-abr | C8: lun | D8: 160000 | E8: 35091 | W8: Rentabilidad x día | X8: =+SUBTOTAL(9,D5:D1048576)/SUBTOTAL(3,B5:B1048576) -> 174333.33 | Y8: =+SUBTOTAL(9,E5:E1048576)/SUBTOTAL(3,B5:B1048576) -> 36091 | Z8: =+SUBTOTAL(9,F5:F1048576)/SUBTOTAL(3,B5:B1048576) -> 0 | AA8: =+Y8-Z8 -> 36091 | AB8: =+AB9/30 -> 53333.333 | AC8: =+AB8+Z8 -> 53333.333 | AD8: =+AD9/30 -> 177777.78 | AF8: 143241 | AK8: 13-abr | AL8: lun | AM8: 160000 | AR8: 13-abr | AS8: lun | AT8: 35091
B9: 14-abr | C9: mar | D9: 160000 | E9: 35091 | W9: Rentabilidad x mes | X9: =+X8*30 -> 5230000 | Y9: =+Y8*30 -> 1082730 | Z9: =+Z8*30 -> 0 | AA9: =+AA8*30 -> 1082730 | AB9: =+(20000*30)+1000000 -> 1600000 | AC9: =+AB9+Z9 -> 1600000 | AD9: =(AC9*100)/30 -> 5333333.3 | AF9: 174333.33 | AG9: =+AF9/AF8 -> 1.2170631 | AH9: =+AF9-AF8 -> 31092.333 | AK9: 14-abr | AL9: mar | AM9: 160000 | AR9: 14-abr | AS9: mar | AT9: 35091
B10: 15-abr | C10: mié | D10: 80000 | E10: 35091 | AK10: 15-abr | AL10: mié | AM10: 80000 | AR10: 15-abr | AS10: mié | AT10: 35091
B11: 16-abr | C11: jue | D11: 200000 | E11: 35091 | X11: Ventas | Y11: Rentabilidad | Z11: Gastos | AA11: Ganacia / Nomina | AB11: % Target | AC11: Target Día | AD11: Target % | AK11: 16-abr | AL11: jue | AM11: 200000 | AR11: 16-abr | AS11: jue | AT11: 35091
B12: 17-abr | C12: vie | D12: 80000 | E12: 35091 | W12: lunes | X12: =+AVERAGEIF($C$5:$C$1048576,$W12,$D$5:$D$1048576) -> #DIV/0! | Y12: =+AVERAGEIF($C$5:$C$1048576,W12,$E$5:$E$1048576) -> #DIV/0! | Z12: =+AVERAGEIF($C$5:$C$1048576,W12,$F$5:$F$1048576) -> #DIV/0! | AA12: =+Y12-Z12 -> #DIV/0! | AB12: =+X12/$X$20 -> #DIV/0! | AC12: =+AB12*$AD$8 -> #DIV/0! | AD12: =+AC12/X12-1 -> #DIV/0! | AK12: 17-abr | AL12: vie | AM12: 80000 | AR12: 17-abr | AS12: vie | AT12: 35091
B13: 18-abr | C13: sáb | D13: 300000 | E13: 35091 | W13: martes | X13: =+AVERAGEIF($C$5:$C$1048576,$W13,$D$5:$D$1048576) -> #DIV/0! | Y13: =+AVERAGEIF($C$5:$C$1048576,W13,$E$5:$E$1048576) -> #DIV/0! | Z13: =+AVERAGEIF($C$5:$C$1048576,W13,$F$5:$F$1048576) -> #DIV/0! | AA13: =+Y13-Z13 -> #DIV/0! | AB13: =+X13/$X$20 -> #DIV/0! | AC13: =+AB13*$AD$8 -> #DIV/0! | AD13: =+AC13/X13-1 -> #DIV/0! | AK13: 18-abr | AL13: sáb | AM13: 300000 | AR13: 18-abr | AS13: sáb | AT13: 35091
B14: 19-abr | C14: dom | D14: 320000 | E14: 35091 | W14: miércoles | X14: =+AVERAGEIF($C$5:$C$1048576,$W14,$D$5:$D$1048576) -> #DIV/0! | Y14: =+AVERAGEIF($C$5:$C$1048576,W14,$E$5:$E$1048576) -> #DIV/0! | Z14: =+AVERAGEIF($C$5:$C$1048576,W14,$F$5:$F$1048576) -> #DIV/0! | AA14: =+Y14-Z14 -> #DIV/0! | AB14: =+X14/$X$20 -> #DIV/0! | AC14: =+AB14*$AD$8 -> #DIV/0! | AD14: =+AC14/X14-1 -> #DIV/0! | AK14: 19-abr | AL14: dom | AM14: 320000 | AR14: 19-abr | AS14: dom | AT14: 35091
B15: 20-abr | C15: lun | D15: 150000 | E15: 35091 | W15: jueves | X15: =+AVERAGEIF($C$5:$C$1048576,$W15,$D$5:$D$1048576) -> #DIV/0! | Y15: =+AVERAGEIF($C$5:$C$1048576,W15,$E$5:$E$1048576) -> #DIV/0! | Z15: =+AVERAGEIF($C$5:$C$1048576,W15,$F$5:$F$1048576) -> #DIV/0! | AA15: =+Y15-Z15 -> #DIV/0! | AB15: =+X15/$X$20 -> #DIV/0! | AC15: =+AB15*$AD$8 -> #DIV/0! | AD15: =+AC15/X15-1 -> #DIV/0! | AK15: 20-abr | AL15: lun | AM15: 150000 | AR15: 20-abr | AS15: lun | AT15: 35091
B16: 21-abr | C16: mar | D16: 100000 | E16: 35091 | W16: viernes | X16: =+AVERAGEIF($C$5:$C$1048576,$W16,$D$5:$D$1048576) -> #DIV/0! | Y16: =+AVERAGEIF($C$5:$C$1048576,W16,$E$5:$E$1048576) -> #DIV/0! | Z16: =+AVERAGEIF($C$5:$C$1048576,W16,$F$5:$F$1048576) -> #DIV/0! | AA16: =+Y16-Z16 -> #DIV/0! | AB16: =+X16/$X$20 -> #DIV/0! | AC16: =+AB16*$AD$8 -> #DIV/0! | AD16: =+AC16/X16-1 -> #DIV/0! | AK16: 21-abr | AL16: mar | AM16: 100000 | AR16: 21-abr | AS16: mar | AT16: 35091
B17: 22-abr | C17: mié | D17: 70000 | E17: 35091 | W17: sábado | X17: =+AVERAGEIF($C$5:$C$1048576,$W17,$D$5:$D$1048576) -> #DIV/0! | Y17: =+AVERAGEIF($C$5:$C$1048576,W17,$E$5:$E$1048576) -> #DIV/0! | Z17: =+AVERAGEIF($C$5:$C$1048576,W17,$F$5:$F$1048576) -> #DIV/0! | AA17: =+Y17-Z17 -> #DIV/0! | AB17: =+X17/$X$20 -> #DIV/0! | AC17: =+AB17*$AD$8 -> #DIV/0! | AD17: =+AC17/X17-1 -> #DIV/0! | AK17: 22-abr | AL17: mié | AM17: 70000 | AR17: 22-abr | AS17: mié | AT17: 35091
