Workbook
Name empleados: [1]Empleados!$A$6:$H$17
Name fDate: '[2]Previsión de ventas'!$D$3
Name fYear: '[2]Previsión de ventas'!$I$2
Name THE: [1]HorasExtras!$A$13:$P$24

Sheet Scotiabank_Platino
C3: Valor del préstamo | D3: =2670000+850000 -> 3520000 | F3: Resumen:
C4: TNA (30/360) | D4: 0.1043 | F4: Valor préstamo | G4: =D3 -> 3520000
C5: Años | D5: 2 | F5: Suma de Cuotas | G5: =SUM($D$14:$D$400) -> 3915111.1 | N5: Equivalencias TASAS efectiVas
C6: Frecuencia de Pago | D6: Mensual | F6: Suma de Interés | G6: =SUM($E$14:$E$400) -> 395111.08 | N6: Anual | O6: =360/360 -> 1
C7: Interés equivalente | D7: =((1+EFFECT(D4,D8))^VLOOKUP(D6,$N$6:$O$11,2,0))-1 -> 0.0086916667 | N7: Semestral | O7: =180/360 -> 0.5
C8: N° de pagos por año | D8: =IF(D6="Mensual",12,IF(D6="Bimensual",6,IF(D6="Trimestral",4,IF(D6="Cuatrimestral",3,IF(D6="Semestral",2,1))))) -> 12 | N8: Cuatrimestral | O8: =120/360 -> 0.33333333
C9: N° Total de Cuotas | D9: =D5*D8 -> 24 | N9: Trimestral | O9: =90/360 -> 0.25
N10: Bimensual | O10: =60/360 -> 0.16666667
N11: Mensual | O11: =30/360 -> 0.083333333
C12: Número de Cuota | D12: CUOTA A PAGAR | E12: INTERÉS | F12: CAPITAL AMORTIZADO | G12: CAPITAL VIVO
C13: 0 | G13: =D3 -> 3520000
C14: =IF(OR(C13=$D$9,C13=""),"",IF(ISNUMBER(C13),C13+1,1)) -> 1 | D14: =IF(C14>$D$9,"",PMT($D$7,$D$9,$D$3)*-1) -> 163129.63 | E14: =IF(C14>$D$9,"",$D$7*G13) -> 30594.667 | F14: =IF(C14>$D$9,"",D14-E14) -> 132534.96 | G14: =IF(C14>$D$9,"",G13-F14) -> 3387465
C15: =IF(OR(C14=$D$9,C14=""),"",IF(ISNUMBER(C14),C14+1,1)) -> 2 | D15: =IF(C15>$D$9,"",PMT($D$7,$D$9,$D$3)*-1) -> 163129.63 | E15: =IF(C15>$D$9,"",$D$7*G14) -> 29442.717 | F15: =IF(C15>$D$9,"",D15-E15) -> 133686.91 | G15: =IF(C15>$D$9,"",G14-F15) -> 3253778.1
C16: =IF(OR(C15=$D$9,C15=""),"",IF(ISNUMBER(C15),C15+1,1)) -> 3 | D16: =IF(C16>$D$9,"",PMT($D$7,$D$9,$D$3)*-1) -> 163129.63 | E16: =IF(C16>$D$9,"",$D$7*G15) -> 28280.755 | F16: =IF(C16>$D$9,"",D16-E16) -> 134848.87 | G16: =IF(C16>$D$9,"",G15-F16) -> 3118929.3
C17: =IF(OR(C16=$D$9,C16=""),"",IF(ISNUMBER(C16),C16+1,1)) -> 4 | D17: =IF(C17>$D$9,"",PMT($D$7,$D$9,$D$3)*-1) -> 163129.63 | E17: =IF(C17>$D$9,"",$D$7*G16) -> 27108.693 | F17: =IF(C17>$D$9,"",D17-E17) -> 136020.94 | G17: =IF(C17>$D$9,"",G16-F17) -> 2982908.3
C18: =IF(OR(C17=$D$9,C17=""),"",IF(ISNUMBER(C17),C17+1,1)) -> 5 | D18: =IF(C18>$D$9,"",PMT($D$7,$D$9,$D$3)*-1) -> 163129.63 | E18: =IF(C18>$D$9,"",$D$7*G17) -> 25926.445 | F18: =IF(C18>$D$9,"",D18-E18) -> 137203.18 | G18: =IF(C18>$D$9,"",G17-F18) -> 2845705.1
C19: =IF(OR(C18=$D$9,C18=""),"",IF(ISNUMBER(C18),C18+1,1)) -> 6 | D19: =IF(C19>$D$9,"",PMT($D$7,$D$9,$D$3)*-1) -> 163129.63 | E19: =IF(C19>$D$9,"",$D$7*G18) -> 24733.92 | F19: =IF(C19>$D$9,"",D19-E19) -> 138395.71 | G19: =IF(C19>$D$9,"",G18-F19) -> 2707309.4
C20: =IF(OR(C19=$D$9,C19=""),"",IF(ISNUMBER(C19),C19+1,1)) -> 7 | D20: =IF(C20>$D$9,"",PMT($D$7,$D$9,$D$3)*-1) -> 163129.63 | E20: =IF(C20>$D$9,"",$D$7*G19) -> 23531.031 | F20: =IF(C20>$D$9,"",D20-E20) -> 139598.6 | G20: =IF(C20>$D$9,"",G19-F20) -> 2567710.8
C21: =IF(OR(C20=$D$9,C20=""),"",IF(ISNUMBER(C20),C20+1,1)) -> 8 | D21: =IF(C21>$D$9,"",PMT($D$7,$D$9,$D$3)*-1) -> 163129.63 | E21: =IF(C21>$D$9,"",$D$7*G20) -> 22317.687 | F21: =IF(C21>$D$9,"",D21-E21) -> 140811.94 | G21: =IF(C21>$D$9,"",G20-F21) -> 2426898.9
C22: =IF(OR(C21=$D$9,C21=""),"",IF(ISNUMBER(C21),C21+1,1)) -> 9 | D22: =IF(C22>$D$9,"",PMT($D$7,$D$9,$D$3)*-1) -> 163129.63 | E22: =IF(C22>$D$9,"",$D$7*G21) -> 21093.796 | F22: =IF(C22>$D$9,"",D22-E22) -> 142035.83 | G22: =IF(C22>$D$9,"",G21-F22) -> 2284863.1
C23: =IF(OR(C22=$D$9,C22=""),"",IF(ISNUMBER(C22),C22+1,1)) -> 10 | D23: =IF(C23>$D$9,"",PMT($D$7,$D$9,$D$3)*-1) -> 163129.63 | E23: =IF(C23>$D$9,"",$D$7*G22) -> 19859.268 | F23: =IF(C23>$D$9,"",D23-E23) -> 143270.36 | G23: =IF(C23>$D$9,"",G22-F23) -> 2141592.7
C24: =IF(OR(C23=$D$9,C23=""),"",IF(ISNUMBER(C23),C23+1,1)) -> 11 | D24: =IF(C24>$D$9,"",PMT($D$7,$D$9,$D$3)*-1) -> 163129.63 | E24: =IF(C24>$D$9,"",$D$7*G23) -> 18614.01 | F24: =IF(C24>$D$9,"",D24-E24) -> 144515.62 | G24: =IF(C24>$D$9,"",G23-F24) -> 1997077.1
C25: =IF(OR(C24=$D$9,C24=""),"",IF(ISNUMBER(C24),C24+1,1)) -> 12 | D25: =IF(C25>$D$9,"",PMT($D$7,$D$9,$D$3)*-1) -> 163129.63 | E25: =IF(C25>$D$9,"",$D$7*G24) -> 17357.928 | F25: =IF(C25>$D$9,"",D25-E25) -> 145771.7 | G25: =IF(C25>$D$9,"",G24-F25) -> 1851305.4
... C121: =IF(OR(C120=$D$9,C120=""),"",IF(ISNUMBER(C120),C120+1,1)) | D121: =IF(C121>$D$9,"",PMT($D$7,$D$9,$D$3)*-1) | E121: =IF(C121>$D$9,"",$D$7*G120) | F121: =IF(C121>$D$9,"",D121-E121) | G121: =IF(C121>$D$9,"",G120-F121)

Sheet Bancolombia
C3: Valor del préstamo | D3: =3000000+650000+1200000 -> 4850000 | F3: Resumen:
C4: TNA (30/360) | D4: 0.2892 | F4: Valor préstamo | G4: =D3 -> 4850000
C5: Años | D5: 2 | F5: Suma de Cuotas | G5: =SUM($D$14:$D$400) -> 6443717.7 | N5: Equivalencias TASAS efectiVas
C6: Frecuencia de Pago | D6: Mensual | F6: Suma de Interés | G6: =SUM($E$14:$E$400) -> 1593717.7 | J6: 143000 | N6: Anual | O6: =360/360 -> 1
C7: Interés equivalente | D7: =((1+EFFECT(D4,D8))^VLOOKUP(D6,$N$6:$O$11,2,0))-1 -> 0.0241 | N7: Semestral | O7: =180/360 -> 0.5
C8: N° de pagos por año | D8: =IF(D6="Mensual",12,IF(D6="Bimensual",6,IF(D6="Trimestral",4,IF(D6="Cuatrimestral",3,IF(D6="Semestral",2,1))))) -> 12 | N8: Cuatrimestral | O8: =120/360 -> 0.33333333
C9: N° Total de Cuotas | D9: =D5*D8 -> 24 | N9: Trimestral | O9: =90/360 -> 0.25
N10: Bimensual | O10: =60/360 -> 0.16666667
N11: Mensual | O11: =30/360 -> 0.083333333
C12: Número de Cuota | D12: CUOTA A PAGAR | E12: INTERÉS | F12: CAPITAL AMORTIZADO | G12: CAPITAL VIVO
C13: 0 | G13: =D3 -> 4850000
C14: =IF(OR(C13=$D$9,C13=""),"",IF(ISNUMBER(C13),C13+1,1)) -> 1 | D14: =IF(C14>$D$9,"",PMT($D$7,$D$9,$D$3)*-1) -> 268488.24 | E14: =IF(C14>$D$9,"",$D$7*G13) -> 116885 | F14: =IF(C14>$D$9,"",D14-E14) -> 151603.24 | G14: =IF(C14>$D$9,"",G13-F14) -> 4698396.8
C15: =IF(OR(C14=$D$9,C14=""),"",IF(ISNUMBER(C14),C14+1,1)) -> 2 | D15: =IF(C15>$D$9,"",PMT($D$7,$D$9,$D$3)*-1) -> 268488.24 | E15: =IF(C15>$D$9,"",$D$7*G14) -> 113231.36 | F15: =IF(C15>$D$9,"",D15-E15) -> 155256.88 | G15: =IF(C15>$D$9,"",G14-F15) -> 4543139.9
C16: =IF(OR(C15=$D$9,C15=""),"",IF(ISNUMBER(C15),C15+1,1)) -> 3 | D16: =IF(C16>$D$9,"",PMT($D$7,$D$9,$D$3)*-1) -> 268488.24 | E16: =IF(C16>$D$9,"",$D$7*G15) -> 109489.67 | F16: =IF(C16>$D$9,"",D16-E16) -> 158998.57 | G16: =IF(C16>$D$9,"",G15-F16) -> 4384141.3
C17: =IF(OR(C16=$D$9,C16=""),"",IF(ISNUMBER(C16),C16+1,1)) -> 4 | D17: =IF(C17>$D$9,"",PMT($D$7,$D$9,$D$3)*-1) -> 268488.24 | E17: =IF(C17>$D$9,"",$D$7*G16) -> 105657.81 | F17: =IF(C17>$D$9,"",D17-E17) -> 162830.43 | G17: =IF(C17>$D$9,"",G16-F17) -> 4221310.9
C18: =IF(OR(C17=$D$9,C17=""),"",IF(ISNUMBER(C17),C17+1,1)) -> 5 | D18: =IF(C18>$D$9,"",PMT($D$7,$D$9,$D$3)*-1) -> 268488.24 | E18: =IF(C18>$D$9,"",$D$7*G17) -> 101733.59 | F18: =IF(C18>$D$9,"",D18-E18) -> 166754.65 | G18: =IF(C18>$D$9,"",G17-F18) -> 4054556.2
C19: =IF(OR(C18=$D$9,C18=""),"",IF(ISNUMBER(C18),C18+1,1)) -> 6 | D19: =IF(C19>$D$9,"",PMT($D$7,$D$9,$D$3)*-1) -> 268488.24 | E19: =IF(C19>$D$9,"",$D$7*G18) -> 97714.805 | F19: =IF(C19>$D$9,"",D19-E19) -> 170773.43 | G19: =IF(C19>$D$9,"",G18-F19) -> 3883782.8
C20: =IF(OR(C19=$D$9,C19=""),"",IF(ISNUMBER(C19),C19+1,1)) -> 7 | D20: =IF(C20>$D$9,"",PMT($D$7,$D$9,$D$3)*-1) -> 268488.24 | E20: =IF(C20>$D$9,"",$D$7*G19) -> 93599.166 | F20: =IF(C20>$D$9,"",D20-E20) -> 174889.07 | G20: =IF(C20>$D$9,"",G19-F20) -> 3708893.7
C21: =IF(OR(C20=$D$9,C20=""),"",IF(ISNUMBER(C20),C20+1,1)) -> 8 | D21: =IF(C21>$D$9,"",PMT($D$7,$D$9,$D$3)*-1) -> 268488.24 | E21: =IF(C21>$D$9,"",$D$7*G20) -> 89384.339 | F21: =IF(C21>$D$9,"",D21-E21) -> 179103.9 | G21: =IF(C21>$D$9,"",G20-F21) -> 3529789.8
C22: =IF(OR(C21=$D$9,C21=""),"",IF(ISNUMBER(C21),C21+1,1)) -> 9 | D22: =IF(C22>$D$9,"",PMT($D$7,$D$9,$D$3)*-1) -> 268488.24 | E22: =IF(C22>$D$9,"",$D$7*G21) -> 85067.935 | F22: =IF(C22>$D$9,"",D22-E22) -> 183420.3 | G22: =IF(C22>$D$9,"",G21-F22) -> 3346369.5
C23: =IF(OR(C22=$D$9,C22=""),"",IF(ISNUMBER(C22),C22+1,1)) -> 10 | D23: =IF(C23>$D$9,"",PMT($D$7,$D$9,$D$3)*-1) -> 268488.24 | E23: =IF(C23>$D$9,"",$D$7*G22) -> 80647.506 | F23: =IF(C23>$D$9,"",D23-E23) -> 187840.73 | G23: =IF(C23>$D$9,"",G22-F23) -> 3158528.8
C24: =IF(OR(C23=$D$9,C23=""),"",IF(ISNUMBER(C23),C23+1,1)) -> 11 | D24: =IF(C24>$D$9,"",PMT($D$7,$D$9,$D$3)*-1) -> 268488.24 | E24: =IF(C24>$D$9,"",$D$7*G23) -> 76120.544 | F24: =IF(C24>$D$9,"",D24-E24) -> 192367.69 | G24: =IF(C24>$D$9,"",G23-F24) -> 2966161.1
C25: =IF(OR(C24=$D$9,C24=""),"",IF(ISNUMBER(C24),C24+1,1)) -> 12 | D25: =IF(C25>$D$9,"",PMT($D$7,$D$9,$D$3)*-1) -> 268488.24 | E25: =IF(C25>$D$9,"",$D$7*G24) -> 71484.483 | F25: =IF(C25>$D$9,"",D25-E25) -> 197003.76 | G25: =IF(C25>$D$9,"",G24-F25) -> 2769157.4
... C121: =IF(OR(C120=$D$9,C120=""),"",IF(ISNUMBER(C120),C120+1,1)) | D121: =IF(C121>$D$9,"",PMT($D$7,$D$9,$D$3)*-1) | E121: =IF(C121>$D$9,"",$D$7*G120) | F121: =IF(C121>$D$9,"",D121-E121) | G121: =IF(C121>$D$9,"",G120-F121)

Sheet Inicio

Sheet Inversión sociedad
D3: Aporte socios | E3: Caja menor
A4: Edwin | B4: Scotiabank | C4: losa, Trompo, empleados | D4: =2600000-E4 -> 2350000 | E4: 250000 | F4: =+SUM(D4:D9) -> 8460000 | G4: =+F4/$F$18 -> 0.37666963 | J4: 7000000 | K4: Aporte
B5: Bancolombia | C5: empleados, deudas, otros | D5: 3000000
B6: Bancolombia | C6: Mercado y otros | D6: 650000 | J6: 960000 | K6: nomina
B7: sueldo | C7: honorarios contrucción | D7: 960000 | J7: 600000
B8: Scotiabank | C8: caja electronica y seguridad | D8: 800000
B9: American | C9: hugo | D9: 700000 | J9: =+SUM(J4:J7) -> 8560000
A10: Hector | C10: Arriendo | D10: 2500000 | F10: =+SUM(D10:D13) -> 12500000 | G10: =+F10/$F$18 -> 0.55654497 | J10: 1000000 | K10: Cámaras
C11: locativas local | D11: =10000000-D10-D13 -> 5900000 | J11: 1000000 | K11: Caja electronica
C12: Moto | D12: 2500000 | J12: 500000 | K12: Software
C13: honorarios Papá (Manutención) | D13: =1000000+600000 -> 1600000 | J13: =+SUM(J10:J12) -> 2500000
A14: Papá | C14: Gestión del local | F14: =+SUM(D14:D17) -> 1500000 | G14: =+F14/$F$18 -> 0.066785396
C15: Experiencia, Sason | J15: =+J9+J13 -> 11060000
C16: Administrador (comisión 33% del negocio)
C17: Bicicleta, Parrilla | D17: 1500000
F18: =+SUM(F4:F17) -> 22460000 | G18: =+SUM(G4:G17) -> 1
A21: Papá | C21: Ahorro servicios | D21: 600000

Sheet Flujo de caja
G1: 20 | H1: 10
E2: Mes | F2: Promedio diario | G2: Dìa habil | H2: Fines de semana
G3: =+E4-H3 -> 8750000 | H3: =+H4*H1 -> 10000000
A4: INGRESOS | E4: =+E6/C6 -> 18750000 | F4: =+E4/30 -> 625000 | G4: =+G3/$G$1 -> 437500 | H4: 1000000
A5: Costos | B5: %Costo | C5: 0.6 | E5: =+$E$4*C5 -> 11250000 | F5: =+E5/30 -> 375000 | G5: =+G4*$C$5 -> 262500 | H5: =+H4*$C$5 -> 600000
A6: GASTOS | C6: 0.4 | E6: =+SUM(E7:E1048576)-E26 -> 7500000 | F6: =+E6/30 -> 250000 | G6: =+G4*$C$6 -> 175000 | H6: =+H4*$C$6 -> 400000
A7: Arriendo | E7: 2500000
A8: Servicios | B8: Agua | E8: 1500000
B9: Luz
B10: Gas | I10: Inventario | J10: Veces | K10: Dias
A11: Nomina | B11: Cocinera y dos meseros | D11: 3 trabajadores | E11: =1000000+600000+900000 -> 2500000 | I11: =1000000*6 -> 6000000 | J11: =+E4/I11 -> 3.125 | K11: =+I11/E4*30 -> 9.6
A12: Financieros | E12: 1000000
A14: Financieros | B14: ScotiaBank | C14: Visa/platinum | D14: 5300000
B15: ScotiaBank | C15: Master Card / Clasica | D15: 1500000 | I15: =+I11/K11 -> 625000
B16: ScotiaBank | C16: Visa Clasica | D16: 1500000
B17: Bancolombia | C17: Visa Clasica | D17: 4000000
B18: Bancolombia | C18: American Express /Otra | D18: 3000000
B19: Banco de Bogotá | C19: Visa Clasica | D19: 500000 | G19: =+E4*12 -> 225000000
B20: Falabella | D20: 3800000
B21: Codensa | D21: 2000000 | G21: =+G19*0.3 -> 67500000
D22: =+SUM(D14:D21) -> 21600000
C23: Polular | D23: 500000
A26: Servicios | B26: Adecuaciones del local | E26: 16000000
D28: =+E5+E26 -> 27250000
D30: =+E11/D28 -> 0.091743119

Sheet Ventas
B4: Politica implantada | C4: FECHA | D4: Dia | E4: Dia semanal | F4: Tipo Dìa | G4: No. de semana | H4: Vendedor | I4: Id. Client por dìa | J4: Producto | K4: Q | L4: Precio item | M4: Ventas | N4: Detalle | O4: Gastos | P4: Hay soportes
B5: Se implanto el sistema de facturación; | C5: 43730 | D5: =+DAY(Ventas[[#This Row],[FECHA]]) -> 22 | E5: =+TEXT(C5,"dddd") -> domingo | F5: Fds y Festivo | G5: 0 | M5: 572000 | X5: No. | Y5: Ventas | Z5: Venta promedio
B6: se cerro la negociación con rapiexpress; Se entrevisto a un sabatino; Se hizo arreglos del trompo por lo cual no se vendio platos de parrilla | C6: 43731 | D6: =+DAY(Ventas[[#This Row],[FECHA]]) -> 23 | E6: =+TEXT(C6,"dddd") -> lunes | F6: Día hábil | G6: 1 | H6: Yusmeidy | I6: 1 | J6: Ejecutivo | K6: 1 | L6: 12000 | M6: =+Ventas[[#This Row],[Precio item]]*Ventas[[#This Row],[Q]] -> 12000 | W6: lunes | X6: =+COUNTIF($E$5:$E$322,W6) -> 46 | Y6: =+SUMIF($E$6:$E$322,W6,$M$6:$M$322) -> 1550710 | Z6: =+Y6/X6 -> 33711.087
C7: 43731 | D7: =+DAY(Ventas[[#This Row],[FECHA]]) -> 23 | E7: =+TEXT(C7,"dddd") -> lunes | F7: Día hábil | G7: 1 | H7: Yusmeidy | I7: 1 | J7: Tè | K7: 1 | L7: 2000 | M7: =+Ventas[[#This Row],[Precio item]]*Ventas[[#This Row],[Q]] -> 2000 | W7: martes | X7: =+COUNTIF($E$5:$E$322,W7) -> 26 | Y7: =+SUMIF($E$6:$E$322,W7,$M$6:$M$322) -> 1058100 | Z7: =+Y7/X7 -> 40696.154
C8: 43731 | D8: =+DAY(Ventas[[#This Row],[FECHA]]) -> 23 | E8: =+TEXT(C8,"dddd") -> lunes | F8: Día hábil | G8: 1 | H8: Yusmeidy | I8: 1 | J8: Jugo Hit | K8: 1 | L8: 2000 | M8: =+Ventas[[#This Row],[Precio item]]*Ventas[[#This Row],[Q]] -> 2000 | R8: 600000 | W8: miércoles | X8: =+COUNTIF($E$5:$E$322,W8) -> 28 | Y8: =+SUMIF($E$6:$E$322,W8,$M$6:$M$322) -> 791500 | Z8: =+Y8/X8 -> 28267.857
C9: 43731 | D9: =+DAY(Ventas[[#This Row],[FECHA]]) -> 23 | E9: =+TEXT(C9,"dddd") -> lunes | F9: Día hábil | G9: 1 | H9: Yusmeidy | I9: 2 | J9: Sopa | K9: 1 | L9: 6000 | M9: =+Ventas[[#This Row],[Precio item]]*Ventas[[#This Row],[Q]] -> 6000 | W9: jueves | X9: =+COUNTIF($E$5:$E$322,W9) -> 19 | Y9: =+SUMIF($E$6:$E$322,W9,$M$6:$M$322) -> 638500 | Z9: =+Y9/X9 -> 33605.263
C10: 43731 | D10: =+DAY(Ventas[[#This Row],[FECHA]]) -> 23 | E10: =+TEXT(C10,"dddd") -> lunes | F10: Día hábil | G10: 1 | H10: Yusmeidy | I10: 3 | J10: Ejecutivo | K10: 2 | L10: 12000 | M10: =+Ventas[[#This Row],[Precio item]]*Ventas[[#This Row],[Q]] -> 24000 | W10: viernes | X10: =+COUNTIF($E$5:$E$322,W10) -> 22 | Y10: =+SUMIF($E$6:$E$322,W10,$M$6:$M$322) -> 1269400 | Z10: =+Y10/X10 -> 57700
C11: 43731 | D11: =+DAY(Ventas[[#This Row],[FECHA]]) -> 23 | E11: =+TEXT(C11,"dddd") -> lunes | F11: Día hábil | G11: 1 | H11: Yusmeidy | I11: 3 | J11: Gaseosa 350 | K11: 2 | L11: 2000 | M11: =+Ventas[[#This Row],[Precio item]]*Ventas[[#This Row],[Q]] -> 4000 | W11: sábado | X11: =+COUNTIF($E$5:$E$322,W11) -> 70 | Y11: =+SUMIF($E$6:$E$322,W11,$M$6:$M$322) -> 2826300 | Z11: =+Y11/X11 -> 40375.714
C12: 43731 | D12: =+DAY(Ventas[[#This Row],[FECHA]]) -> 23 | E12: =+TEXT(C12,"dddd") -> lunes | F12: Día hábil | G12: 1 | H12: Yusmeidy | I12: 4 | J12: Ejecutivo | K12: 1 | L12: 10000 | M12: =+Ventas[[#This Row],[Precio item]]*Ventas[[#This Row],[Q]] -> 10000 | N12: El señor José lo dejo en $ 10.000 | W12: domingo | X12: =+COUNTIF($E$5:$E$322,W12) -> 107 | Y12: =+SUMIF($E$6:$E$322,W12,$M$6:$M$322) -> 3287100 | Z12: =+Y12/X12 -> 30720.561
C13: 43731 | D13: =+DAY(Ventas[[#This Row],[FECHA]]) -> 23 | E13: =+TEXT(C13,"dddd") -> lunes | F13: Día hábil | G13: 1 | H13: Yusmeidy | I13: 5 | J13: Ejecutivo | K13: 2 | L13: 10000 | M13: =+Ventas[[#This Row],[Precio item]]*Ventas[[#This Row],[Q]] -> 20000 | N13: Sin nota
C14: 43731 | D14: =+DAY(Ventas[[#This Row],[FECHA]]) -> 23 | E14: =+TEXT(C14,"dddd") -> lunes | F14: Día hábil | G14: 1 | H14: Yusmeidy | I14: 6 | J14: Ejecutivo | K14: 4 | L14: 10000 | M14: =+Ventas[[#This Row],[Precio item]]*Ventas[[#This Row],[Q]] -> 40000
C15: 43731 | D15: =+DAY(Ventas[[#This Row],[FECHA]]) -> 23 | E15: =+TEXT(C15,"dddd") -> lunes | F15: Día hábil | G15: 1 | H15: Yusmeidy | I15: 7 | J15: Caderita | K15: 1 | L15: 22000 | M15: =+Ventas[[#This Row],[Precio item]]*Ventas[[#This Row],[Q]] -> 22000 | Q15: bajo revisiòn | S15: cita medica
C16: 43732 | D16: =+DAY(Ventas[[#This Row],[FECHA]]) -> 24 | E16: =+TEXT(C16,"dddd") -> martes | F16: Día hábil | G16: 1 | H16: Yusmeidy | I16: 1 | J16: Medias carnes | K16: 1 | L16: 15000 | M16: =+Ventas[[#This Row],[Precio item]]*Ventas[[#This Row],[Q]] -> 15000
C17: 43732 | D17: =+DAY(Ventas[[#This Row],[FECHA]]) -> 24 | E17: =+TEXT(C17,"dddd") -> martes | F17: Día hábil | G17: 1 | H17: Yusmeidy | I17: 2 | J17: Carne llanera | K17: 2 | L17: 22000 | M17: =+Ventas[[#This Row],[Precio item]]*Ventas[[#This Row],[Q]] -> 44000
C18: 43732 | D18: =+DAY(Ventas[[#This Row],[FECHA]]) -> 24 | E18: =+TEXT(C18,"dddd") -> martes | F18: Día hábil | G18: 1 | H18: Yusmeidy | I18: 2 | J18: Sopa | K18: 3 | L18: 4000 | M18: =+Ventas[[#This Row],[Precio item]]*Ventas[[#This Row],[Q]] -> 12000
C19: 43732 | D19: =+DAY(Ventas[[#This Row],[FECHA]]) -> 24 | E19: =+TEXT(C19,"dddd") -> martes | F19: Día hábil | G19: 1 | H19: Yusmeidy | I19: 2 | J19: Gaseosa litro y medio | K19: 1 | L19: 4000 | M19: =+Ventas[[#This Row],[Precio item]]*Ventas[[#This Row],[Q]] -> 4000
C20: 43732 | D20: =+DAY(Ventas[[#This Row],[FECHA]]) -> 24 | E20: =+TEXT(C20,"dddd") -> martes | F20: Día hábil | G20: 1 | H20: Yusmeidy | I20: 3 | J20: Carne llanera | K20: 1 | L20: 25000 | M20: =+Ventas[[#This Row],[Precio item]]*Ventas[[#This Row],[Q]] -> 25000
C21: 43732 | D21: =+DAY(Ventas[[#This Row],[FECHA]]) -> 24 | E21: =+TEXT(C21,"dddd") -> martes | F21: Día hábil | G21: 1 | H21: Yusmeidy | I21: 3 | J21: Gaseosa 350 | K21: 1 | L21: 2000 | M21: =+Ventas[[#This Row],[Precio item]]*Ventas[[#This Row],[Q]] -> 2000
C22: 43732 | D22: =+DAY(Ventas[[#This Row],[FECHA]]) -> 24 | E22: =+TEXT(C22,"dddd") -> martes | F22: Día hábil | G22: 1 | H22: Yusmeidy | I22: 4 | J22: Carne llanera | K22: 1 | L22: 25000 | M22: =+Ventas[[#This Row],[Precio item]]*Ventas[[#This Row],[Q]] -> 25000
C23: 43732 | D23: =+DAY(Ventas[[#This Row],[FECHA]]) -> 24 | E23: =+TEXT(C23,"dddd") -> martes | F23: Día hábil | G23: 1 | H23: Yusmeidy | I23: 4 | J23: Cerbeza | K23: 3 | L23: 3000 | M23: =+Ventas[[#This Row],[Precio item]]*Ventas[[#This Row],[Q]] -> 9000 | N23: No dice que marca es?
C24: 43732 | D24: =+DAY(Ventas[[#This Row],[FECHA]]) -> 24 | E24: =+TEXT(C24,"dddd") -> martes | F24: Día hábil | G24: 1 | H24: Yusmeidy | I24: 5 | J24: Media carne | K24: 1 | L24: 15000 | M24: =+Ventas[[#This Row],[Precio item]]*Ventas[[#This Row],[Q]] -> 15000
C25: 43732 | D25: =+DAY(Ventas[[#This Row],[FECHA]]) -> 24 | E25: =+TEXT(C25,"dddd") -> martes | F25: Día hábil | G25: 1 | H25: Yusmeidy | I25: 6 | J25: Ejecutivo | K25: 2 | L25: 10000 | M25: =+Ventas[[#This Row],[Precio item]]*Ventas[[#This Row],[Q]] -> 20000
C26: 43732 | D26: =+DAY(Ventas[[#This Row],[FECHA]]) -> 24 | E26: =+TEXT(C26,"dddd") -> martes | F26: Día hábil | G26: 1 | H26: Yusmeidy | I26: 7 | J26: Carne llanera | K26: 2 | L26: 25000 | M26: =+Ventas[[#This Row],[Precio item]]*Ventas[[#This Row],[Q]] -> 50000
C27: 43732 | D27: =+DAY(Ventas[[#This Row],[FECHA]]) -> 24 | E27: =+TEXT(C27,"dddd") -> martes | F27: Día hábil | G27: 1 | H27: Yusmeidy | I27: 7 | J27: Gaseosa 350 | K27: 3 | L27: 2000 | M27: =+Ventas[[#This Row],[Precio item]]*Ventas[[#This Row],[Q]] -> 6000
C28: 43732 | D28: =+DAY(Ventas[[#This Row],[FECHA]]) -> 24 | E28: =+TEXT(C28,"dddd") -> martes | F28: Día hábil | G28: 1 | H28: Yusmeidy | I28: 8 | J28: Ejecutivo | K28: 1 | L28: 10000 | M28: =+Ventas[[#This Row],[Precio item]]*Ventas[[#This Row],[Q]] -> 10000
C29: 43732 | D29: =+DAY(Ventas[[#This Row],[FECHA]]) -> 24 | E29: =+TEXT(C29,"dddd") -> martes | F29: Día hábil | G29: 1 | H29: Yusmeidy | I29: 9 | J29: Ejecutivo | K29: 2 | L29: 10000 | M29: =+Ventas[[#This Row],[Precio item]]*Ventas[[#This Row],[Q]] -> 20000
C30: 43732 | D30: =+DAY(Ventas[[#This Row],[FECHA]]) -> 24 | E30: =+TEXT(C30,"dddd") -> martes | F30: Día hábil | G30: 1 | H30: Yusmeidy | I30: 9 | J30: Agua | K30: 1 | L30: 2000 | M30: =+Ventas[[#This Row],[Precio item]]*Ventas[[#This Row],[Q]] -> 2000
C31: 43732 | D31: =+DAY(Ventas[[#This Row],[FECHA]]) -> 24 | E31: =+TEXT(C31,"dddd") -> martes | F31: Día hábil | G31: 1 | H31: Yusmeidy | I31: 10 | J31: Cerbeza | K31: 9 | L31: 3000 | M31: =+Ventas[[#This Row],[Precio item]]*Ventas[[#This Row],[Q]] -> 27000
C32: 43732 | D32: =+DAY(Ventas[[#This Row],[FECHA]]) -> 24 | E32: =+TEXT(C32,"dddd") -> martes | F32: Día hábil | G32: 1 | H32: Yusmeidy | I32: 11 | J32: Sopa especial | K32: 2 | L32: 15000 | M32: =+Ventas[[#This Row],[Precio item]]*Ventas[[#This Row],[Q]] -> 30000 | N32: dice que la sopa pequeña vale, lo mismo que la grande
C33: 43732 | D33: =+DAY(Ventas[[#This Row],[FECHA]]) -> 24 | E33: =+TEXT(C33,"dddd") -> martes | F33: Día hábil | G33: 1 | H33: Yusmeidy | I33: 11 | J33: Cerbeza | K33: 2 | L33: 3000 | M33: =+Ventas[[#This Row],[Precio item]]*Ventas[[#This Row],[Q]] -> 6000
C34: 43732 | D34: =+DAY(Ventas[[#This Row],[FECHA]]) -> 24 | E34: =+TEXT(C34,"dddd") -> martes | F34: Día hábil | G34: 1 | H34: Yusmeidy | I34: 11 | J34: Gaseosa litro y medio | K34: 1 | L34: 4000 | M34: =+Ventas[[#This Row],[Precio item]]*Ventas[[#This Row],[Q]] -> 4000
C35: 43732 | D35: =+DAY(Ventas[[#This Row],[FECHA]]) -> 24 | E35: =+TEXT(C35,"dddd") -> martes | F35: Día hábil | G35: 1 | H35: Yusmeidy | I35: 12 | J35: Ejecutivo | K35: 2 | L35: 10000 | M35: =+Ventas[[#This Row],[Precio item]]*Ventas[[#This Row],[Q]] -> 20000
C36: 43732 | D36: =+DAY(Ventas[[#This Row],[FECHA]]) -> 24 | E36: =+TEXT(C36,"dddd") -> martes | F36: Día hábil | G36: 1 | H36: Yusmeidy | I36: 13 | J36: Cerbeza | K36: 11 | L36: 3000 | M36: =+Ventas[[#This Row],[Precio item]]*Ventas[[#This Row],[Q]] -> 33000
C37: 43732 | D37: =+DAY(Ventas[[#This Row],[FECHA]]) -> 24 | E37: =+TEXT(C37,"dddd") -> martes | F37: Día hábil | G37: 1 | H37: Yusmeidy | I37: 13 | J37: Agua | K37: 1 | L37: 2000 | M37: =+Ventas[[#This Row],[Precio item]]*Ventas[[#This Row],[Q]] -> 2000
C38: 43732 | D38: =+DAY(Ventas[[#This Row],[FECHA]]) -> 24 | E38: =+TEXT(C38,"dddd") -> martes | F38: Día hábil | G38: 1 | H38: Yusmeidy | I38: 14 | J38: Sopa | K38: 2 | L38: 6000 | M38: =+Ventas[[#This Row],[Precio item]]*Ventas[[#This Row],[Q]] -> 12000 | N38: Changua
B39: Se le pago a Hugo por arreglos locativos | C39: 43733 | D39: =+DAY(Ventas[[#This Row],[FECHA]]) -> 25 | E39: =+TEXT(C39,"dddd") -> miércoles | F39: Día hábil | G39: 1 | H39: Yusmeidy | I39: 1 | J39: Picada | K39: 1 | L39: 25000 | M39: =+Ventas[[#This Row],[Precio item]]*Ventas[[#This Row],[Q]] -> 25000 | N39: ¿Cuántas personas?
C40: 43733 | D40: =+DAY(Ventas[[#This Row],[FECHA]]) -> 25 | E40: =+TEXT(C40,"dddd") -> miércoles | F40: Día hábil | G40: 1 | H40: Yusmeidy | I40: 2 | J40: Ejecutivo | K40: 2 | L40: 10000 | M40: =+Ventas[[#This Row],[Precio item]]*Ventas[[#This Row],[Q]] -> 20000
C41: 43733 | D41: =+DAY(Ventas[[#This Row],[FECHA]]) -> 25 | E41: =+TEXT(C41,"dddd") -> miércoles | F41: Día hábil | G41: 1 | H41: Yusmeidy | I41: 3 | J41: Ejecutivo | K41: 1 | L41: 10000 | M41: =+Ventas[[#This Row],[Precio item]]*Ventas[[#This Row],[Q]] -> 10000
C42: 43733 | D42: =+DAY(Ventas[[#This Row],[FECHA]]) -> 25 | E42: =+TEXT(C42,"dddd") -> miércoles | F42: Día hábil | G42: 1 | H42: Yusmeidy | I42: 4 | J42: Sopa | K42: 1 | L42: 5000 | M42: =+Ventas[[#This Row],[Precio item]]*Ventas[[#This Row],[Q]] -> 5000
C43: 43733 | D43: =+DAY(Ventas[[#This Row],[FECHA]]) -> 25 | E43: =+TEXT(C43,"dddd") -> miércoles | F43: Día hábil | G43: 1 | H43: Yusmeidy | I43: 5 | J43: Picada | K43: 1 | L43: 20000 | M43: =+Ventas[[#This Row],[Precio item]]*Ventas[[#This Row],[Q]] -> 20000
...

Sheet Clientes institucionales
C6: 900551266 CONSORCIO CCC ITUANGO

Sheet Revenue Forecasting
D1: Nombre cliente | E1: Turistas | K1: Turistas | L1: Domicilios
D2: Producto | E2: (Todas) | K2: Clientes de la zona | L2: Eventos
D4: Suma de Ventas | E4: Mes
D5: Día | E5: dic | F5: nov | G5: oct | H5: sep | AB5: Nov | AC5: oct | AD5: sep
D6: 1 | E6: 1500000 | F6: 370000 | G6: 229800 | AB6: Sin hist | AC6: NO REALIZADO
D7: 2 | E7: 250000 | F7: 500000 | G7: 238000 | AB7: Sin hist | AC7: NO REALIZADO
D8: 3 | E8: 120000 | F8: 1700000 | G8: 238000 | AB8: Sin hist | AC8: NO REALIZADO
D9: 4 | E9: 180000 | F9: 600000 | G9: 420500 | AB9: Sin hist | AC9: NO REALIZADO
D10: 5 | E10: 250000 | F10: 194000 | G10: 1210300 | AB10: Sin hist | AC10: NO REALIZADO
D11: 6 | E11: 220000 | F11: 627000 | G11: 1345600 | AB11: Sin hist | AC11: NO REALIZADO
D12: 7 | E12: 900000 | F12: 332500 | G12: 603500 | AC12: NO REALIZADO
D13: 8 | E13: 1200000 | F13: 342000 | G13: 426300 | AC13: NO REALIZADO
D14: 9 | E14: 140000 | F14: 1552000 | G14: 134000 | AC14: NO REALIZADO
D15: 10 | E15: 0 | F15: 1690000 | G15: 85500 | AC15: NO REALIZADO
D16: 11 | E16: 220000 | F16: 700000 | G16: 427900 | AC16: NO REALIZADO
D17: 12 | E17: 400000 | F17: 122000 | G17: 664500 | AC17: NO REALIZADO
D18: 13 | E18: 350000 | F18: 165000 | G18: 1283500 | AC18: NO REALIZADO
D19: 14 | E19: 900000 | F19: 61000 | G19: 622000 | AC19: completo
D20: 15 | E20: 800000 | F20: 235000 | G20: 227000 | AC20: completo
D21: 16 | E21: 207200 | F21: 811500 | G21: 385300 | AC21: completo
D22: 17 | E22: 157500 | F22: 1300900 | G22: 250800 | AC22: completo
D23: 18 | E23: 220000 | F23: 350000 | G23: 363500 | AC23: completo
... D26: 21 | E26: 450000 | F26: 216500 | G26: 350000 | AC26: Sin hist
D27: 22 | E27: 638500 | F27: 186000 | G27: 380000 | H27: 572000 | AC27: Sin hist | AD27: Sin hist
D28: 23 | E28: 308500 | F28: 587500 | G28: 550000 | H28: 142000 | AC28: Sin hist | AD28: completo
D29: 24 | E29: 604000 | F29: 960000 | G29: 380000 | H29: 393000 | AC29: Sin hist | AD29: completo
D30: 25 | E30: 589500 | F30: 500000 | G30: 1200000 | H30: 419500 | AC30: Sin hist | AD30: completo
D31: 26 | E31: 120500 | F31: 400000 | G31: 655000 | H31: 315000 | AC31: Sin hist | AD31: completo
D32: 27 | E32: 82500 | F32: 210000 | G32: 1200000 | H32: 421000 | AC32: Sin hist | AD32: completo
D33: 28 | E33: 824000 | F33: 200000 | G33: 300000 | H33: 951500 | AC33: Sin hist | AD33: completo
D34: 29 | E34: 720000 | F34: 400000 | G34: 220000 | H34: 658000 | AC34: Sin hist | AD34: completo
D35: 30 | E35: 149500 | F35: 900000 | G35: 320000 | H35: 183210 | AC35: Sin hist | AD35: NO REALIZADO
D36: 31 | E36: 448500 | G36: 370000
D37: Total general | E37: 13745700 | F37: 16752900 | G37: 17351500 | H37: 4055210 | AC37: 11855040 | AD37: 4055210
D38: =+D6 -> 1 | E38: =+E6 -> 1500000 | F38: =+F6 -> 370000 | G38: =+G6 -> 229800 | H38: =+H6 -> 0
D39: =+D7 -> 2 | E39: =+E7 -> 250000 | F39: =+F7 -> 500000 | G39: =+G7 -> 238000 | H39: =+H7 -> 0 | K39: =+E5 -> dic | L39: D | M39: D% | N39: =+F5 -> nov | O39: D | P39: D% | Q39: =+G5 -> oct | R39: D | S39: D% | T39: =+H5 -> sep | V39: ¿Qué afecta las ventas?
D40: =+D8 -> 3 | E40: =+E8 -> 120000 | F40: =+F8 -> 1700000 | G40: =+G8 -> 238000 | H40: =+H8 -> 0 | K40: =+AVERAGE(E39:E42) -> 200000 | L40: =+K40-N40 -> -79857.143 | M40: =+K40/N40-1 -> -0.28534967 | N40: =+AVERAGE(F42:F44,F49:F51,F55:F58,F62:F65) -> 279857.14 | O40: =+N40-Q40 -> -36153.968 | P40: =+N40/Q40-1 -> -0.11440727 | Q40: =+AVERAGE(G38:G40,G44:G47,G52:G54,G58:G61,G65:G68) -> 316011.11 | R40: =+Q40-T40 -> 25469.111 | S40: =+Q40/T40-1 -> 0.087660686 | T40: =+AVERAGE(H60:H63,H67) -> 290542 | V40: el humo
D41: =+D9 -> 4 | E41: =+E9 -> 180000 | F41: =+F9 -> 600000 | G41: =+G9 -> 420500 | H41: =+H9 -> 0 | K41: =+AVERAGE(E43) -> 220000 | L41: =+K41-N41 -> -86600 | M41: =+K41/N41-1 -> -0.28245271 | N41: =+AVERAGE(F38,F45,F52,F59,F66) -> 306600 | O41: =+N41-Q41 -> -296375 | P41: =+N41/Q41-1 -> -0.49152121 | Q41: =+AVERAGE(G41,G48,G55,G62) -> 602975 | R41: =+Q41-T41 -> 181975 | S41: =+Q41/T41-1 -> 0.43224466 | T41: =+H64 -> 421000 | V41: factura electronica
D42: =+D10 -> 5 | E42: =+E10 -> 250000 | F42: =+F10 -> 194000 | G42: =+G10 -> 1210300 | H42: =+H10 -> 0 | K42: =+AVERAGE(E44) -> 900000 | L42: =+K42-N42 -> 29800 | M42: =+K42/N42-1 -> 0.034245001 | N42: =+AVERAGE(F39,F46,F53,F60,F67) -> 870200 | O42: =+N42-Q42 -> 57750 | P42: =+N42/Q42-1 -> 0.071081297 | Q42: =+AVERAGE(G42,G49,G56,G63) -> 812450 | R42: =+Q42-T42 -> -139050 | S42: =+Q42/T42-1 -> -0.14613768 | T42: =+H65 -> 951500 | V42: vandedero
D43: =+D11 -> 6 | E43: =+E11 -> 220000 | F43: =+F11 -> 627000 | G43: =+G11 -> 1345600 | H43: =+H11 -> 0 | K43: =+AVERAGE(E45) -> 1200000 | L43: =+K43-N43 -> -212725 | M43: =+K43/N43-1 -> -0.15057778 | N43: =+AVERAGE(F40,F47,F54,F61) -> 1412725 | O43: =+N43-Q43 -> 67825 | P43: =+N43/Q43-1 -> 0.050431259 | Q43: =+AVERAGE(G43,G50,G57,G64) -> 1344900 | R43: =+Q43-T43 -> 729900 | S43: =+Q43/T43-1 -> 1.1868293 | T43: =+AVERAGE(H59,H66) -> 615000 | V43: aviso publicidad
...

Sheet Clima
A1: FECHA | B1: Dia | C1: Dia semanal | D1: Estado clima
A2: 43730 | B2: =+DAY(A2) -> 22 | C2: =+TEXT(A2,"dddd") -> domingo
A3: =+A2+1 -> 43731 | B3: =+DAY(A3) -> 23 | C3: =+TEXT(A3,"dddd") -> lunes
A4: =+A3+1 -> 43732 | B4: =+DAY(A4) -> 24 | C4: =+TEXT(A4,"dddd") -> martes
A5: =+A4+1 -> 43733 | B5: =+DAY(A5) -> 25 | C5: =+TEXT(A5,"dddd") -> miércoles
A6: =+A5+1 -> 43734 | B6: =+DAY(A6) -> 26 | C6: =+TEXT(A6,"dddd") -> jueves
A7: =+A6+1 -> 43735 | B7: =+DAY(A7) -> 27 | C7: =+TEXT(A7,"dddd") -> viernes
A8: =+A7+1 -> 43736 | B8: =+DAY(A8) -> 28 | C8: =+TEXT(A8,"dddd") -> sábado
A9: =+A8+1 -> 43737 | B9: =+DAY(A9) -> 29 | C9: =+TEXT(A9,"dddd") -> domingo
A10: =+A9+1 -> 43738 | B10: =+DAY(A10) -> 30 | C10: =+TEXT(A10,"dddd") -> lunes
A11: =+A10+1 -> 43739 | B11: =+DAY(A11) -> 1 | C11: =+TEXT(A11,"dddd") -> martes
A12: =+A11+1 -> 43740 | B12: =+DAY(A12) -> 2 | C12: =+TEXT(A12,"dddd") -> miércoles
A13: =+A12+1 -> 43741 | B13: =+DAY(A13) -> 3 | C13: =+TEXT(A13,"dddd") -> jueves
A14: =+A13+1 -> 43742 | B14: =+DAY(A14) -> 4 | C14: =+TEXT(A14,"dddd") -> viernes
... A30: =+A29+1 -> 43758 | B30: =+DAY(A30) -> 20 | C30: =+TEXT(A30,"dddd") -> domingo
A31: =+A30+1 -> 43759 | B31: =+DAY(A31) -> 21 | C31: =+TEXT(A31,"dddd") -> lunes | D31: Llovio levemente
A32: =+A31+1 -> 43760 | B32: =+DAY(A32) -> 22 | C32: =+TEXT(A32,"dddd") -> martes
A33: =+A32+1 -> 43761 | B33: =+DAY(A33) -> 23 | C33: =+TEXT(A33,"dddd") -> miércoles
A34: =+A33+1 -> 43762 | B34: =+DAY(A34) -> 24 | C34: =+TEXT(A34,"dddd") -> jueves
A35: =+A34+1 -> 43763 | B35: =+DAY(A35) -> 25 | C35: =+TEXT(A35,"dddd") -> viernes

Sheet Modelo Econométrico
F2: Y (Ventas los tunos parrilla) | G2: = | H2: aX1 | I2: X2 | J2: X3 | K2: X4
D3: Precio de mercado
K4: X5
B5: Y
B6: =
B7: X1 | C7: Precio
B8: X2 | C8: Servicio
B9: X3 | C9: Clima
B10: X4 | C10: Precios compentencia
B11: X5 | C11: Servicio compentencia
B12: x6 | C12: Instalaciones | D12: el daño de hugo

Sheet Bono Yery
D4: 43773 | E4: 4 | F4: =+TEXT(D4,"dddd") -> lunes | G4: si
D5: 43774 | E5: 5 | F5: =+TEXT(D5,"dddd") -> martes | G5: si
D6: 43775 | E6: 6 | F6: =+TEXT(D6,"dddd") -> miércoles | G6: si
D7: 43776 | E7: 7 | F7: =+TEXT(D7,"dddd") -> jueves | G7: no
D8: 43777 | E8: 16 | F8: =+TEXT(D8,"dddd") -> viernes | G8: no
D9: 43778 | E9: 17 | F9: =+TEXT(D9,"dddd") -> sábado | G9: no | H9: No hay copias de Alenis | I9: Se me quedaron
D10: 43779 | E10: 18 | F10: =+TEXT(D10,"dddd") -> domingo | G10: Si
D11: 43780 | E11: 19 | F11: =+TEXT(D11,"dddd") -> lunes
D12: 43781 | E12: 20 | F12: =+TEXT(D12,"dddd") -> martes

Sheet Revenue Forecasting (2)
D1: Nombre cliente | E1: Turistas | H1: Turistas | I1: Domicilios
D2: Producto | E2: (Todas) | H2: Clientes de la zona | I2: Eventos
D4: Día | E4: Máx. de Id. Client por dìa
D5: 1 | H5: Día | I5: oct | J5: sep
A6: Viernes (18) | D6: 2 | H6: 1 | I6: NO REALIZADO
A7: Viernes (18) | D7: 3 | H7: 2 | I7: NO REALIZADO
A8: Sabàdo 19 | D8: 4 | H8: 3 | I8: NO REALIZADO
A9: Sabàdo 19 | D9: 5 | H9: 4 | I9: NO REALIZADO
A10: Sabàdo 19 | D10: 6 | H10: 5 | I10: NO REALIZADO
A11: Domingo 20 | D11: 7 | H11: 6 | I11: NO REALIZADO
A12: Domingo 20 | D12: 8 | H12: 7 | I12: NO REALIZADO
A13: Domingo 20 | D13: 9 | H13: 8 | I13: NO REALIZADO
A14: Lunes 21 | D14: 10 | H14: 9 | I14: NO REALIZADO
A15: Lunes 21 | D15: 11 | H15: 10 | I15: NO REALIZADO
A16: Lunes 21 | D16: 12 | H16: 11 | I16: NO REALIZADO
A17: Martes 22 | D17: 13 | E17: 21 | H17: 12 | I17: NO REALIZADO
A18: Martes 22 | D18: 14 | E18: 14 | H18: 13 | I18: NO REALIZADO
A19: Martes 23 | D19: 15 | E19: 19 | H19: 14 | I19: NO REALIZADO
A20: Miercoles 24 | D20: 16 | E20: 19 | H20: 15 | I20: completo
A21: Miercoles 24 | D21: 17 | E21: 14 | H21: 16 | I21: NO REALIZADO
A22: Miercoles 24 | D22: 18 | E22: 15 | H22: 17 | I22: completo
A23: Jueves 25 | D23: 19 | H23: 18 | I23: completo
A24: Jueves 25 | C24: sab | D24: 20 | E24: 36 | H24: 19 | I24: SE QUEDO
D25: 21 | H25: 20 | I25: NO REALIZADO
D26: 22 | H26: 21 | I26: Sin hist
D27: 23 | E27: 7 | H27: 22 | J27: Sin hist
D28: 24 | E28: 14 | H28: 23 | J28: completo
D29: 25 | E29: 17 | H29: 24 | J29: completo
D30: 26 | E30: 10 | H30: 25 | J30: completo
D31: 27 | E31: 15 | H31: 26 | J31: completo
D32: 28 | E32: 29 | H32: 27 | J32: completo
D33: 29 | E33: 19 | H33: 28 | J33: completo
D34: 30 | H34: 29 | J34: completo
D35: 31 | H35: 30 | J35: NO REALIZADO
D36: Total general | E36: 36 | H36: 31
H37: Total general | I37: 11855040 | J37: 4055210
D38: =+D6 -> 2 | E38: =+E6 -> 0 | F38: =+F6 -> 0
D39: =+D7 -> 3 | E39: =+E7 -> 0 | F39: =+F7 -> 0 | H39: D | I39: D% | J39: =+E5 -> 0 | K39: =+F5 -> 0
D40: =+D8 -> 4 | E40: =+E8 -> 0 | F40: =+F8 -> 0 | H40: =+J40-K40 -> 4.3636364 | I40: =+J40/K40-1 -> #DIV/0! | J40: =+AVERAGE(E38:E40,E44:E47,E52:E54,E58) -> 4.3636364 | K40: =+AVERAGE(F60:F63) -> 0
D41: =+D9 -> 5 | E41: =+E9 -> 0 | F41: =+F9 -> 0 | H41: =+J41-K41 -> 0 | I41: =+J41/K41-1 -> #DIV/0! | J41: =+AVERAGE(E41,E48,E55) -> 0 | K41: =+F64 -> 0
...

Sheet Anàlisis de ingreso
F1: Análisis de ingresos por día semanal | W1: Noviembre
I2: Mes | V2: Nomina | W2: ='PE (2)'!K2 -> 2310000
D3: Inicio de operación | E3: Fecha actual | F3: Venta | I3: sep | J3: oct | K3: nov | L3: dic | M3: Total general | V3: Arriendo | W3: ='PE (2)'!K3 -> 2500000
D4: 43730 | E4: 43830 | F4: 51905310 | H4: Ventas | I4: 4055210 | J4: 17351500 | K4: 16752900 | L4: 13745700 | M4: 51905310 | S4: No. de semana | T4: (Todas) | V4: Financieros | W4: ='PE (2)'!K4 -> 0
S5: Dia semanal | T5: (Varios elementos) | V5: Servicios | W5: ='PE (2)'!K5 -> 780000
A6: Semana | C6: 23-29 sep | D6: 30 Sep al 6 Oct | E6: 7-13 Oct | F6: 14-20 Oct | G6: 21-27 Oct | H6: 28 Oct -3Nov | I6: 4-10Nov | J6: 11-17Nov | K6: 18-24Nov | L6: 25Nov-1Dic | M6: 1-8Dic | N6: 9-15Dic | O6: 16-22Dic | P6: 22-28Dic | Q6: 29Dic-4Ene | W6: =+SUM(W2:W5) -> 5590000
B7: Semana | S7: Día | T7: Valor | U7: 0.3 | V7: =100%-U7 -> 0.7
A8: Día | B8: 0 | C8: 1 | D8: 2 | E8: 3 | F8: 4 | G8: 5 | H8: 6 | I8: 7 | J8: 8 | K8: 9 | L8: 10 | M8: 11 | N8: 12 | O8: 13 | P8: 14 | Q8: 15 | S8: oct | T8: 11041300 | U8: =+$U$7*T8 -> 3312390 | V8: =+T8-U8 -> 7728910
A9: lunes | C9: 142000 | D9: 183210 | E9: 603500 | F9: 622000 | G9: 350000 | H9: 300000 | I9: 600000 | J9: 700000 | K9: 350000 | L9: 500000 | M9: 250000 | N9: 140000 | O9: 207200 | P9: 308500 | Q9: 149500 | S9: nov | T9: 11534900 | U9: =+$U$7*T9 -> 3460470 | V9: =+T9-U9 -> 8074430 | W9: =+V9-W6 -> 2484430
A10: martes | C10: 393000 | D10: 229800 | E10: 426300 | F10: 227000 | G10: 380000 | H10: 220000 | I10: 194000 | J10: 122000 | K10: 220000 | L10: 400000 | M10: 120000 | N10: 0 | O10: 157500 | P10: 604000 | Q10: 448500 | S10: Total general | T10: 22576200 | U10: =+$U$7*T10 -> 6772860 | V10: =+T10-U10 -> 15803340
A11: miércoles | C11: 419500 | D11: 238000 | E11: 134000 | F11: 385300 | G11: 550000 | H11: 320000 | I11: 627000 | J11: 165000 | K11: 320000 | L11: 210000 | M11: 180000 | N11: 220000 | O11: 220000 | P11: 589500
A12: jueves | C12: 315000 | D12: 238000 | E12: 85500 | F12: 250800 | G12: 380000 | H12: 370000 | I12: 332500 | J12: 61000 | K12: 216500 | L12: 200000 | M12: 250000 | N12: 400000 | O12: 445500 | P12: 120500
A13: viernes | C13: 421000 | D13: 420500 | E13: 427900 | F13: 363500 | G13: 1200000 | H13: 370000 | I13: 342000 | J13: 235000 | K13: 186000 | L13: 400000 | M13: 220000 | N13: 350000 | O13: 350000 | P13: 82500
A14: sábado | C14: 951500 | D14: 1210300 | E14: 664500 | F14: 720000 | G14: 655000 | H14: 500000 | I14: 1552000 | J14: 811500 | K14: 587500 | L14: 900000 | M14: 900000 | N14: 900000 | O14: 450000 | P14: 824000
A15: domingo | B15: 572000 | C15: 658000 | D15: 1345600 | E15: 1283500 | F15: 1550500 | G15: 1200000 | H15: 1700000 | I15: 1690000 | J15: 1300900 | K15: 960000 | L15: 1500000 | M15: 1200000 | N15: 800000 | O15: 638500 | P15: 720000
A16: Total general | B16: 572000 | C16: 3300000 | D16: 3865410 | E16: 3625200 | F16: 4119100 | G16: 4715000 | H16: 3780000 | I16: 5337500 | J16: 3395400 | K16: 2840000 | L16: 4110000 | M16: 3120000 | N16: 2810000 | O16: 2468700 | P16: 3249000 | Q16: 598000 | S16: No. de semana | T16: (Todas)
C17: % | D17: =+D16/C16-1 -> 0.17133636 | E17: =+E16/D16-1 -> -0.062143472 | F17: =+F16/E16-1 -> 0.13624076 | G17: =+G16/F16-1 -> 0.14466752 | H17: =+H16/G16-1 -> -0.19830329 | I17: =+I16/H16-1 -> 0.41203704 | J17: =+J16/I16-1 -> -0.36385948 | K17: =+K16/J16-1 -> -0.16357425 | ... P17: =+P16/O16-1 -> 0.31607729
S18: Día | T18: Valor | U18: 0.6 | V18: 0.4
C19: =+SUM(C13:C15) -> 2030500 | D19: =+SUM(D13:D15) -> 2976400 | E19: =+SUM(E13:E15) -> 2375900 | F19: =+SUM(F13:F15) -> 2634000 | G19: =+SUM(G13:G15) -> 3055000 | H19: =+SUM(H13:H15) -> 2570000 | I19: =+SUM(I13:I15) -> 3584000 | J19: =+SUM(J13:J15) -> 2347400 | ... O19: =+SUM(O13:O15) -> 1438500 | S19: oct | T19: 17351500
S20: nov | T20: 16752900
A21: Variación relativa | C21: 23-29 sep | D21: 30 Sep al 6 Oct | E21: 7-13 Oct | F21: 14-20 Oct | G21: 21-27 Oct | H21: 28 Oct -3Nov | I21: 4-10Nov | J21: 11-17Nov | K21: 18-24Nov | L21: 25Nov-1Dic | M21: 1-8Dic | N21: 9-15Dic | O21: 16-22Dic | P21: 22-28Dic | Q21: 29Dic-4Ene | S21: Total general | T21: 34104400
A22: Día | B22: 0 | C22: 1 | D22: 2 | E22: 3 | F22: 4 | G22: 5 | H22: 6 | I22: 7 | J22: 8 | K22: 9 | L22: 10 | M22: 11 | N22: 12 | O22: 12 | P22: 14 | Q22: 15
A23: lunes | B23: - | D23: =+D9/C9-1 -> 0.29021127 | E23: =+E9/D9-1 -> 2.2940342 | F23: =+F9/E9-1 -> 0.030654515 | G23: =+G9/F9-1 -> -0.43729904 | H23: =+H9/G9-1 -> -0.14285714 | I23: =+I9/H9-1 -> 1 | J23: =+J9/I9-1 -> 0.16666667 | K23: =+K9/J9-1 -> -0.5 | ... Q23: =+Q9/P9-1 -> -0.51539708
A24: martes | B24: - | D24: =+D10/C10-1 -> -0.41526718 | E24: =+E10/D10-1 -> 0.85509138 | F24: =+F10/E10-1 -> -0.46751114 | G24: =+G10/F10-1 -> 0.67400881 | H24: =+H10/G10-1 -> -0.42105263 | I24: =+I10/H10-1 -> -0.11818182 | J24: =+J10/I10-1 -> -0.37113402 | K24: =+K10/J10-1 -> 0.80327869 | ... N24: =+N10/M10-1 -> -1 | O24: =IFERROR(O10/N10-1,"Abierto") -> Abierto | P24: =+P10/O10-1 -> 2.8349206 | Q24: =+Q10/P10-1 -> -0.25745033
A25: miércoles | B25: - | D25: =+D11/C11-1 -> -0.43265793 | E25: =+E11/D11-1 -> -0.43697479 | F25: =+F11/E11-1 -> 1.8753731 | G25: =+G11/F11-1 -> 0.42745912 | H25: =+H11/G11-1 -> -0.41818182 | I25: =+I11/H11-1 -> 0.959375 | J25: =+J11/I11-1 -> -0.73684211 | K25: =+K11/J11-1 -> 0.93939394 | ... P25: =+P11/O11-1 -> 1.6795455
A26: jueves | B26: - | D26: =+D12/C12-1 -> -0.24444444 | E26: =+E12/D12-1 -> -0.6407563 | F26: =+F12/E12-1 -> 1.9333333 | G26: =+G12/F12-1 -> 0.51515152 | H26: =+H12/G12-1 -> -0.026315789 | I26: =+I12/H12-1 -> -0.10135135 | J26: =+J12/I12-1 -> -0.81654135 | K26: =+K12/J12-1 -> 2.5491803 | ... P26: =+P12/O12-1 -> -0.7295174
A27: viernes | B27: - | D27: =+D13/C13-1 -> -0.0011876485 | E27: =+E13/D13-1 -> 0.017598098 | F27: =+F13/E13-1 -> -0.15050245 | G27: =+G13/F13-1 -> 2.301238 | H27: =+H13/G13-1 -> -0.69166667 | I27: =+I13/H13-1 -> -0.075675676 | J27: =+J13/I13-1 -> -0.3128655 | K27: =+K13/J13-1 -> -0.20851064 | ... P27: =+P13/O13-1 -> -0.76428571
A28: sábado | B28: - | D28: =+D14/C14-1 -> 0.27199159 | E28: =+E14/D14-1 -> -0.45096257 | F28: =+F14/E14-1 -> 0.083521445 | G28: =+G14/F14-1 -> -0.090277778 | H28: =+H14/G14-1 -> -0.23664122 | I28: =+I14/H14-1 -> 2.104 | J28: =+J14/I14-1 -> -0.47712629 | K28: =+K14/J14-1 -> -0.27603204 | ... P28: =+P14/O14-1 -> 0.83111111
A29: domingo | B29: - | C29: =+C15/B15-1 -> 0.15034965 | D29: =+D15/C15-1 -> 1.0449848 | E29: =+E15/D15-1 -> -0.046150416 | F29: =+F15/E15-1 -> 0.20802493 | G29: =+G15/F15-1 -> -0.22605611 | H29: =+H15/G15-1 -> 0.41666667 | I29: =+I15/H15-1 -> -0.0058823529 | J29: =+J15/I15-1 -> -0.23023669 | ... P29: =+P15/O15-1 -> 0.12764291
A30: Total general | B30: - | D30: =+D16/C16-1 -> 0.17133636 | E30: =+E16/D16-1 -> -0.062143472 | F30: =+F16/E16-1 -> 0.13624076 | G30: =+G16/F16-1 -> 0.14466752 | H30: =+H16/G16-1 -> -0.19830329 | I30: =+I16/H16-1 -> 0.41203704 | J30: =+J16/I16-1 -> -0.36385948 | K30: =+K16/J16-1 -> -0.16357425 | ... P30: =+P16/O16-1 -> 0.31607729
C34: 23-29 sep | D34: 30 Sep al 6 Oct | E34: 7-13 Oct | F34: 14-20 Oct | G34: 21-27 Oct | H34: 28 Oct -3Nov | I34: 4-10Nov | J34: 11-17Nov | K34: 18-24Nov | L34: 25Nov-1Dic | M34: 1-8Dic | N34: 9-15Dic | O34: 16-22Dic | P34: 22-28Dic | Q34: 29Dic-4Ene
A35: Día | B35: 0 | C35: 1 | D35: 2 | E35: 3 | F35: 4 | G35: 5 | H35: 6 | I35: 7 | J35: 8 | K35: 9 | L35: 10 | M35: 11 | N35: 12 | O35: 13 | P35: 14 | Q35: 15
A36: lunes | B36: - | C36: =+C9-B9 -> 142000 | D36: =+D9-C9 -> 41210 | E36: =+E9-D9 -> 420290 | F36: =+F9-E9 -> 18500 | G36: =+G9-F9 -> -272000 | H36: =+H9-G9 -> -50000 | I36: =+I9-H9 -> 300000 | J36: =+J9-I9 -> 100000 | ... O36: =+O9-N9 -> 67200
A37: martes | B37: - | C37: =+C10-B10 -> 393000 | D37: =+D10-C10 -> -163200 | E37: =+E10-D10 -> 196500 | F37: =+F10-E10 -> -199300 | G37: =+G10-F10 -> 153000 | H37: =+H10-G10 -> -160000 | I37: =+I10-H10 -> -26000 | J37: =+J10-I10 -> -72000 | ... O37: =+O10-N10 -> 157500
A38: miércoles | B38: - | C38: =+C11-B11 -> 419500 | D38: =+D11-C11 -> -181500 | E38: =+E11-D11 -> -104000 | F38: =+F11-E11 -> 251300 | G38: =+G11-F11 -> 164700 | H38: =+H11-G11 -> -230000 | I38: =+I11-H11 -> 307000 | J38: =+J11-I11 -> -462000 | ... O38: =+O11-N11 -> 0
A39: jueves | B39: - | C39: =+C12-B12 -> 315000 | D39: =+D12-C12 -> -77000 | E39: =+E12-D12 -> -152500 | F39: =+F12-E12 -> 165300 | G39: =+G12-F12 -> 129200 | H39: =+H12-G12 -> -10000 | I39: =+I12-H12 -> -37500 | J39: =+J12-I12 -> -271500 | ... O39: =+O12-N12 -> 45500
A40: viernes | B40: - | C40: =+C13-B13 -> 421000 | D40: =+D13-C13 -> -500 | E40: =+E13-D13 -> 7400 | F40: =+F13-E13 -> -64400 | G40: =+G13-F13 -> 836500 | H40: =+H13-G13 -> -830000 | I40: =+I13-H13 -> -28000 | J40: =+J13-I13 -> -107000 | ... O40: =+O13-N13 -> 0
A41: sábado | B41: - | C41: =+C14-B14 -> 951500 | D41: =+D14-C14 -> 258800 | E41: =+E14-D14 -> -545800 | F41: =+F14-E14 -> 55500 | G41: =+G14-F14 -> -65000 | H41: =+H14-G14 -> -155000 | I41: =+I14-H14 -> 1052000 | J41: =+J14-I14 -> -740500 | ... O41: =+O14-N14 -> -450000
A42: domingo | B42: - | C42: =+C15-B15 -> 86000 | D42: =+D15-C15 -> 687600 | E42: =+E15-D15 -> -62100 | F42: =+F15-E15 -> 267000 | G42: =+G15-F15 -> -350500 | H42: =+H15-G15 -> 500000 | I42: =+I15-H15 -> -10000 | J42: =+J15-I15 -> -389100 | ... O42: =+O15-N15 -> -161500
A43: Total general | B43: - | C43: =+C16-B16 -> 2728000 | D43: =+D16-C16 -> 565410 | E43: =+E16-D16 -> -240210 | F43: =+F16-E16 -> 493900 | G43: =+G16-F16 -> 595900 | H43: =+H16-G16 -> -935000 | I43: =+I16-H16 -> 1557500 | J43: =+J16-I16 -> -1942100 | ... O43: =+O16-N16 -> -341300

Sheet Anàlisis de producto
A1: Máx. de Id. Client por dìa | B1: Semana
A2: Día | B2: 0 | C2: 1 | D2: 4
A3: lunes | C3: 7 | D3: 14
A4: martes | C4: 14 | D4: 19
A5: miércoles | C5: 17 | D5: 19
A6: jueves | C6: 10 | D6: 14
A7: viernes | C7: 15 | D7: 15
A8: sábado | C8: 29
A9: domingo | C9: 19 | D9: 36
A10: Total general | C10: 29 | D10: 36
A14: Cuenta de Id. Client por dìa | B14: Semana
A15: Día | B15: 1 | C15: 3 | D15: 4
A16: lunes
A17: Picada | D17: 11
A18: martes
A19: Picada | D19: 1
A20: miércoles
A21: Picada | B21: 3 | D21: 7
A22: jueves
A23: Picada | B23: 1 | D23: 1
A24: Picada con Refajo | B24: 1
A25: viernes
A26: Picada | B26: 2 | D26: 5
A27: sábado
A28: Picada | B28: 12
A29: Picada con Refajo | B29: 1
A30: domingo
A31: Canasta de picada mixta | B31: 1
A32: Canasta de picada mixta + Carne Parrila | B32: 1
A33: Canasta de picada mixta + Carne Parrila + 1/4 de Gallina | B33: 1
A34: Picada | B34: 8 | C34: 17 | D34: 23
A35: Total general | B35: 31 | C35: 17 | D35: 48

Sheet OPEX_deuda
B1: Septiembre | I1: Octubre | Q1: Noviembre | Y1: Diciembre
D2: Inversiòn | E2: Viernes | F2: Dia fds | G2: Mensual | K2: Inversiòn | L2: Saldo actual | M2: Viernes | N2: Dia fds | O2: Mensual | S2: Inversiòn | T2: Saldo actual | U2: Viernes | V2: Dia fds | W2: Mensual | AA2: Inversiòn | AB2: Saldo actual | AC2: Viernes | AD2: Dia fds | AE2: Mensual
E3: 1 | F3: 4 | G3: =+E3+F3 -> 5 | M3: 4 | N3: 9 | O3: =+M3+N3 -> 13 | U3: 5 | V3: 11 | W3: =+U3+V3 -> 16 | AC3: 4 | AD3: 10 | AE3: =+AC3+AD3 -> 14
B4: Arriendo | C4: Arriendo | E4: =+G4/G3 -> 300000 | G4: 1500000 | I4: Arriendo | J4: Arriendo | M4: =+O4/O3 -> 192307.69 | O4: 2500000 | Q4: Arriendo | R4: Arriendo | U4: =+W4/W3 -> 156250 | W4: 2500000 | Y4: Arriendo | Z4: Arriendo | AC4: =+AE4/AE3 -> 178571.43 | AE4: 2500000
B5: Servicios | C5: Agua | I5: Servicios | J5: Agua | M5: =+O5/O3 -> 23076.923 | O5: 300000 | Q5: Servicios | R5: Agua | U5: =+W5/W3 -> 12500 | W5: 200000 | Y5: Servicios | Z5: Agua | AC5: =+AE5/30 -> 5000 | AE5: 150000
C6: Luz | J6: Luz | M6: =+O6/O3 -> 19230.769 | O6: 250000 | R6: Luz | U6: =+W6/W3 -> 15625 | W6: 250000 | Z6: Luz | AC6: =+AE6/30 -> 8333.3333 | AE6: 250000
C7: Gas | J7: Gas | M7: =+O7/O3 -> 19230.769 | O7: 250000 | R7: Gas | U7: =+W7/W3 -> 20625 | W7: 330000 | Z7: Gas | AC7: =+AE7/30 -> 8333.3333 | AE7: 250000
C8: Telefonía, internet y televisión | J8: Telefonía, internet y televisión | R8: Telefonía, internet y televisión | Z8: Telefonía, internet y televisión
B9: Nomina | C9: Ayudante de cocina senior (Señora Rosa) | E9: 35000 | F9: 35000 | G9: =+(E9*E3)+(F9*F3) -> 175000 | I9: Nomina | J9: Ayudante de cocina senior (Señora Rosa) | M9: 35000 | N9: 35000 | O9: =+(M9*M3)+(N9*N3) -> 455000 | Q9: Nomina | R9: Ayudante de cocina senior (Señora Rosa) | U9: 35000 | V9: 35000 | W9: =+(U9*U3)+(V9*V3) -> 560000 | X9: 10000 | Y9: Nomina | Z9: Ayudante de cocina senior (Señora Rosa) | AC9: 35000 | AD9: 35000 | AE9: =+(AC9*AC3)+(AD9*AD3) -> 490000
C10: Ayudante de cocina Junior (Yeri) | E10: 25000 | F10: 30000 | G10: =+(E10*E3)+(F10*F3) -> 145000 | J10: Ayudante de cocina Junior (Yeri) | M10: 25000 | N10: 30000 | O10: =+(M10*M3)+(N10*N3) -> 370000 | R10: Ayudante de cocina Junior (Henry) | U10: 25000 | V10: 30000 | W10: =+(U10*U3)+(V10*V3) -> 455000 | X10: 10000 | Z10: Ayudante de cocina Junior (Janeth) | AC10: 25000 | AD10: 30000 | AE10: =+(AC10*AC3)+(AD10*AD3) -> 400000
C11: Mesero (a) fijo (Yusmeidy y Alines) | E11: 25000 | F11: 30000 | G11: =+(E11*E3)+(F11*F3) -> 145000 | J11: Mesero (a) fijo (Yusmeidy y Alines) | M11: 25000 | N11: 30000 | O11: =+(M11*M3)+(N11*N3) -> 370000 | R11: Mesero (a) fijo (Yusmeidy) | U11: 25000 | V11: 30000 | W11: =+(U11*U3)+(V11*V3) -> 455000 | X11: 10000 | Z11: Mesero (a) fijo (Mauricio) | AC11: 25000 | AD11: 30000 | AE11: =+(AC11*AC3)+(AD11*AD3) -> 400000
C12: Mesero (a) sabatino (Stefania) | E12: 0 | F12: 35000 | G12: =+(E12*0)+(F12*F3) -> 140000 | J12: Mesero (a) sabatino (Stefania) | M12: 0 | N12: 35000 | O12: =+(M12*0)+(N12*N3) -> 315000 | R12: Mesero (a) sabatino (Stefania) | U12: 0 | V12: 35000 | W12: =+(U12*0)+(V12*V3) -> 385000 | Z12: Mesero (a) sabatino (Yuly y Danda) | AC12: 0 | AD12: 35000 | AE12: =+(AC12*0)+(AD12*AD3) -> 350000
C13: Chef- Cocinero sabatino (Eduardo e Ingacio) | E13: 50000 | F13: 50000 | G13: =+(E13*8)+(F13*5) -> 650000 | J13: Chef- Cocinero sabatino (Eduardo e Ingacio) | M13: 30000 | N13: 60000 | O13: =+(M13*8)+(N13*5) -> 540000 | R13: Chef- Cocinero sabatino | U13: 0 | V13: 0 | W13: =+(U13*20)+(V13*10) -> 0 | Z13: Chef- Cocinero sabatino | AC13: 0 | AD13: 0 | AE13: =+(AC13*20)+(AD13*10) -> 0
C14: Banderero y domiciliario (Rolando y Manuel) | E14: 25000 | F14: 25000 | G14: =+(E14*E3)+(F14*F3) -> 125000 | J14: Banderero y domiciliario (Rolando y Manuel) | M14: 25000 | N14: 25000 | O14: =+(M14*M3)+(N14*N3) -> 325000 | R14: Banderero y domiciliario (Manuel) | U14: 25000 | V14: 30000 | W14: =+(U14*U3)+(V14*V3) -> 455000 | X14: 10000 | Z14: Banderero y domiciliario (Manuel) | AC14: 25000 | AD14: 25000 | AE14: =+(AC14*AC3)+(AD14*AD3) -> 350000
C15: Asistente administrativo y mercadeo | G15: =+(E15*20)+(F15*10) -> 0 | J15: Asistente administrativo y mercadeo | O15: =+(M15*20)+(N15*10) -> 0 | R15: Asistente administrativo y mercadeo | W15: =+(U15*20)+(V15*10) -> 0 | Z15: Asistente administrativo y mercadeo | AE15: =+(AC15*20)+(AD15*10) -> 0
C16: Parrillero, Jefe de compras, jefe de tesorería, jefe de personal | E16: 0 | F16: 0 | G16: =+(E16*20)+(F16*10) -> 0 | J16: Parrillero, Jefe de compras, jefe de tesorería, jefe de personal | M16: 0 | N16: 0 | O16: =+(M16*20)+(N16*10) -> 0 | R16: Parrillero, Jefe de compras, jefe de tesorería, jefe de personal | W16: =+(U16*20)+(V16*10) -> 0 | X16: =+SUM(X9:X14,U9:U14) -> 150000 | Z16: Parrillero, Jefe de compras, jefe de tesorería, jefe de personal | AC16: 0 | AD16: 0 | AE16: =+(AC16*20)+(AD16*10) -> 0
C17: Caja, Jefe de contabilidad Administrador, jefe de compras, Auditor interno, Facturación Investigador de mercados, analista de negocios (datos), Gerente comercial | E17: 0 | F17: 0 | G17: =+(E17*20)+(F17*10) -> 0 | J17: Caja, Jefe de contabilidad Administrador, jefe de compras, Auditor interno, Facturación Investigador de mercados, analista de negocios (datos), Gerente comercial | M17: 0 | N17: 0 | O17: =+(M17*20)+(N17*10) -> 0 | R17: Caja, Jefe de contabilidad Administrador, jefe de compras, Auditor interno, Facturación Investigador de mercados, analista de negocios (datos), Gerente comercial | U17: 0 | V17: 0 | W17: =+(U17*20)+(V17*10) -> 0 | Z17: Caja, Jefe de contabilidad Administrador, jefe de compras, Auditor interno, Facturación Investigador de mercados, analista de negocios (datos), Gerente comercial | AC17: 0 | AD17: 0 | AE17: =+(AC17*20)+(AD17*10) -> 0
B18: Financieros | C18: ScotiaBank | D18: =2600000+67500+824000 -> 3491500 | I18: Financieros | J18: ScotiaBank | K18: =2600000+67500+824000 -> 3491500 | L18: 3439103.3 | M18: =+O18/O3 -> 9846.1538 | O18: 128000 | Q18: Financieros | R18: ScotiaBank | S18: =2600000+67500+824000 -> 3491500 | T18: 3439103.3 | U18: =+W18/W3 -> 0 | Y18: Financieros | Z18: ScotiaBank | AC18: =+AE18/AE3 -> 0
C19: Bancolombia (American Express) | D19: 1242548.5 | J19: Bancolombia (American Express) | K19: 1242548.5 | L19: 1198874 | M19: =+O19/O3 -> 7605.7692 | O19: 98875 | R19: Bancolombia (American Express) | S19: 1242548.5 | T19: 1198874 | U19: =+W19/W3 -> 0 | Z19: Bancolombia (American Express) | AC19: =+AE19/AE3 -> 0
C20: Bancolombia (Visa) | D20: 3737029.6 | J20: Bancolombia (Visa) | K20: 3737029.6 | L20: 3299796 | M20: =+O20/O3 -> 42346.308 | O20: 550502 | R20: Bancolombia (Visa) | S20: 3737029.6 | T20: 3299796 | U20: =+W20/W3 -> 0 | Z20: Bancolombia (Visa) | AC20: =+AE20/AE3 -> 0
C21: Banco Hector (cuantos meses) | E21: =+G21/30 -> 0 | G21: 0 | J21: Banco Hector (cuantos meses) | M21: =+O21/O3 -> 0 | R21: Banco Hector (cuantos meses) | U21: =+W21/W3 -> 0 | Z21: Banco Hector (cuantos meses) | AC21: =+AE21/AE3 -> 42857.143 | AE21: 600000
B23: Gastos Fijos y Variables | C23: 0.4 | E23: =+SUM(E4:F8,E18:F21,E9:E17) -> 460000 | F23: =+SUM(E4:F8,E18:F21,F9:F17) -> 505000 | G23: =+SUM(G4:G21) -> 2880000 | I23: Gastos Fijos y Variables | J23: 0.4 | M23: =+SUM(M4:N8,M18:N21,M9:M17) -> 453644.38 | N23: =+SUM(M4:N8,M18:N21,N9:N17) -> 528644.38 | O23: =+SUM(O4:O21) -> 6452377 | Q23: Gastos Fijos y Variables | R23: 0.4 | U23: =+SUM(U4:V8,U18:V21,U9:U17) -> 315000 | V23: =+SUM(U4:V8,U18:V21,V9:V17) -> 365000 | W23: =+SUM(W4:W21) -> 5590000 | Y23: Gastos Fijos y Variables | Z23: 0.4 | AC23: =+SUM(AC4:AD8,AC18:AD21,AC9:AC17) -> 353095.24 | AD23: =+SUM(AC4:AD8,AC18:AD21,AD9:AD17) -> 398095.24 | AE23: =+SUM(AE4:AE21) -> 5740000
B24: Costos Variables | C24: 0.6 | E24: =+E$25*$R24 -> 690000 | F24: =+F$25*$R24 -> 757500 | G24: =+G$25*C24 -> 4320000 | I24: Costos Variables | J24: 0.6 | M24: =+M$25*$R24 -> 680466.58 | N24: =+N$25*$R24 -> 792966.58 | O24: =+O$25*J24 -> 9678565.5 | Q24: Costos Variables | R24: 0.6 | U24: =+U$25*$R24 -> 472500 | V24: =+V$25*$R24 -> 547500 | W24: =+W$25*R24 -> 8385000 | Y24: Costos Variables | Z24: 0.6 | AC24: =+AC$25*$R24 -> 529642.86 | AD24: =+AD$25*$R24 -> 597142.86 | AE24: =+AE$25*Z24 -> 8610000
E25: =(E23/40)*100 -> 1150000 | F25: =(F23/40)*100 -> 1262500 | G25: =(G23/40)*100 -> 7200000 | M25: =(M23/40)*100 -> 1134111 | N25: =(N23/40)*100 -> 1321611 | O25: =(O23/40)*100 -> 16130942 | U25: =(U23/40)*100 -> 787500 | V25: =(V23/40)*100 -> 912500 | W25: =(W23/40)*100 -> 13975000 | AC25: =(AC23/40)*100 -> 882738.1 | AD25: =(AD23/40)*100 -> 995238.1 | AE25: =(AE23/40)*100 -> 14350000
M27: Dìas habiles | N27: 22 | O27: =+N27*U25 -> 17325000
F28: Venta Real | G28: 4055210 | M28: Fin Semana | N28: 9 | O28: =+N28*V25 -> 8212500
F29: 60% Mercancia en uso y a crédito | G29: =+G28*60% -> 2433126 | O29: =+SUM(O27:O28) -> 25537500
F30: Gastos 40% | G30: =+G29-G28 -> -1622084 | M30: Gastos Fijo diario prom. | O30: =+O29/31 -> 823790.32
F31: Aporte Edwin Mercado | G31: 900000
G32: =+G31+G30 -> -722084
F33: Aporte Carne Hector | G33: =+G32 -> -722084

Sheet OPEX (3)
B1: Septiembre | I1: Octubre | Q1: Noviembre | Y1: Diciembre
D2: Inversiòn | E2: Viernes | F2: Dia fds | G2: Mensual | K2: Inversiòn | L2: Saldo actual | M2: Viernes | N2: Dia fds | O2: Mensual | S2: Inversiòn | T2: Saldo actual | U2: Viernes | V2: Dia fds | W2: Mensual | AA2: Inversiòn | AB2: Saldo actual | AC2: Viernes | AD2: Dia fds | AE2: Mensual
E3: 0 | F3: 3 | G3: =+E3+F3 -> 3 | M3: 0 | N3: 9 | O3: =+M3+N3 -> 9 | U3: 0 | V3: 11 | W3: =+U3+V3 -> 11 | AC3: 0 | AD3: 10 | AE3: =+AC3+AD3 -> 10
B4: Arriendo | C4: Arriendo | E4: =+G4/G3 -> 500000 | G4: 1500000 | I4: Arriendo | J4: Arriendo | M4: =+O4/O3 -> 277777.78 | O4: 2500000 | Q4: Arriendo | R4: Arriendo | U4: =+W4/W3 -> 227272.73 | W4: 2500000 | Y4: Arriendo | Z4: Arriendo | AC4: =+AE4/AE3 -> 250000 | AE4: 2500000
B5: Servicios | C5: Agua | I5: Servicios | J5: Agua | M5: =+O5/O3 -> 33333.333 | O5: 300000 | Q5: Servicios | R5: Agua | U5: =+W5/W3 -> 27272.727 | W5: 300000 | Y5: Servicios | Z5: Agua | AC5: =+AE5/30 -> 10000 | AE5: 300000
C6: Luz | J6: Luz | M6: =+O6/O3 -> 27777.778 | O6: 250000 | R6: Luz | U6: =+W6/W3 -> 22727.273 | W6: 250000 | Z6: Luz | AC6: =+AE6/30 -> 8333.3333 | AE6: 250000
C7: Gas | J7: Gas | M7: =+O7/O3 -> 27777.778 | O7: 250000 | R7: Gas | U7: =+W7/W3 -> 22727.273 | W7: 250000 | Z7: Gas | AC7: =+AE7/30 -> 8333.3333 | AE7: 250000
C8: Telefonía, internet y televisión | J8: Telefonía, internet y televisión | R8: Telefonía, internet y televisión | Z8: Telefonía, internet y televisión
B9: Nomina | C9: Ayudante de cocina senior (Señora Rosa) | F9: 35000 | G9: =+(E9*E3)+(F9*F3) -> 105000 | I9: Nomina | J9: Ayudante de cocina senior (Señora Rosa) | N9: 35000 | O9: =+(M9*M3)+(N9*N3) -> 315000 | Q9: Nomina | R9: Ayudante de cocina senior (Señora Rosa) | V9: 35000 | W9: =+(U9*U3)+(V9*V3) -> 385000 | X9: 10000 | Y9: Nomina | Z9: Ayudante de cocina senior (Señora Rosa) | AD9: 35000 | AE9: =+(AC9*AC3)+(AD9*AD3) -> 350000
C10: Ayudante de cocina Junior (Yeri) | F10: 30000 | G10: =+(E10*E3)+(F10*F3) -> 90000 | J10: Ayudante de cocina Junior (Yeri) | N10: 30000 | O10: =+(M10*M3)+(N10*N3) -> 270000 | R10: Ayudante de cocina Junior (Henry) | V10: 30000 | W10: =+(U10*U3)+(V10*V3) -> 330000 | X10: 10000 | Z10: Ayudante de cocina Junior (Henry) | AD10: 30000 | AE10: =+(AC10*AC3)+(AD10*AD3) -> 300000
C11: Mesero (a) fijo (Yusmeidy y Alines) | F11: 30000 | G11: =+(E11*E3)+(F11*F3) -> 90000 | J11: Mesero (a) fijo (Yusmeidy y Alines) | N11: 30000 | O11: =+(M11*M3)+(N11*N3) -> 270000 | R11: Mesero (a) fijo (Yusmeidy) | V11: 30000 | W11: =+(U11*U3)+(V11*V3) -> 330000 | X11: 10000 | Z11: Mesero (a) fijo (Yusmeidy) | AD11: 30000 | AE11: =+(AC11*AC3)+(AD11*AD3) -> 300000
C12: Mesero (a) sabatino (Stefania) | F12: 35000 | G12: =+(E12*0)+(F12*F3) -> 105000 | J12: Mesero (a) sabatino (Stefania) | N12: 35000 | O12: =+(M12*0)+(N12*N$3) -> 315000 | R12: Mesero (a) sabatino (Stefania) | V12: 35000 | W12: =+(U12*0)+(V12*V3) -> 385000 | Z12: Mesero (a) sabatino (Stefania) | AD12: 35000 | AE12: =+(AC12*0)+(AD12*AD3) -> 350000
C13: Chef- Cocinero sabatino (Eduardo e Ingacio) | F13: 50000 | G13: =+(E13*8)+(F13*5) -> 250000 | J13: Chef- Cocinero sabatino (Eduardo e Ingacio) | N13: 60000 | O13: =+(M13*0)+(N13*N$3) -> 540000 | R13: Chef- Cocinero sabatino | V13: 0 | W13: =+(U13*20)+(V13*10) -> 0 | Z13: Chef- Cocinero sabatino | AD13: 0 | AE13: =+(AC13*20)+(AD13*10) -> 0
C14: Banderero y domiciliario (Rolando y Manuel) | F14: 25000 | G14: =+(E14*E3)+(F14*F3) -> 75000 | J14: Banderero y domiciliario (Rolando y Manuel) | N14: 25000 | O14: =+(M14*M3)+(N14*N3) -> 225000 | R14: Banderero y domiciliario (Manuel) | V14: 30000 | W14: =+(U14*U3)+(V14*V3) -> 330000 | X14: 10000 | Z14: Banderero y domiciliario (Manuel) | AD14: 25000 | AE14: =+(AC14*AC3)+(AD14*AD3) -> 250000
C15: Asistente administrativo y mercadeo | G15: =+(E15*20)+(F15*10) -> 0 | J15: Asistente administrativo y mercadeo | O15: =+(M15*20)+(N15*10) -> 0 | R15: Asistente administrativo y mercadeo | W15: =+(U15*20)+(V15*10) -> 0 | Z15: Asistente administrativo y mercadeo | AE15: =+(AC15*20)+(AD15*10) -> 0
C16: Parrillero, Jefe de compras, jefe de tesorería, jefe de personal | E16: 0 | F16: 0 | G16: =+(E16*20)+(F16*10) -> 0 | J16: Parrillero, Jefe de compras, jefe de tesorería, jefe de personal | M16: 0 | N16: 0 | O16: =+(M16*20)+(N16*10) -> 0 | R16: Parrillero, Jefe de compras, jefe de tesorería, jefe de personal | W16: =+(U16*20)+(V16*10) -> 0 | X16: =+SUM(X9:X14,U9:U14) -> 40000 | Z16: Parrillero, Jefe de compras, jefe de tesorería, jefe de personal | AC16: 0 | AD16: 0 | AE16: =+(AC16*20)+(AD16*10) -> 0
C17: Caja, Jefe de contabilidad Administrador, jefe de compras, Auditor interno, Facturación Investigador de mercados, analista de negocios (datos), Gerente comercial | E17: 0 | F17: 0 | G17: =+(E17*20)+(F17*10) -> 0 | J17: Caja, Jefe de contabilidad Administrador, jefe de compras, Auditor interno, Facturación Investigador de mercados, analista de negocios (datos), Gerente comercial | M17: 0 | N17: 0 | O17: =+(M17*20)+(N17*10) -> 0 | R17: Caja, Jefe de contabilidad Administrador, jefe de compras, Auditor interno, Facturación Investigador de mercados, analista de negocios (datos), Gerente comercial | U17: 0 | V17: 0 | W17: =+(U17*20)+(V17*10) -> 0 | Z17: Caja, Jefe de contabilidad Administrador, jefe de compras, Auditor interno, Facturación Investigador de mercados, analista de negocios (datos), Gerente comercial | AC17: 0 | AD17: 0 | AE17: =+(AC17*20)+(AD17*10) -> 0
B18: Financieros | C18: ScotiaBank | D18: =2600000+67500+824000 -> 3491500 | I18: Financieros | J18: ScotiaBank | K18: =2600000+67500+824000 -> 3491500 | L18: 3439103.3 | M18: =+O18/O3 -> 14222.222 | O18: 128000 | Q18: Financieros | R18: ScotiaBank | S18: =2600000+67500+824000 -> 3491500 | T18: 3439103.3 | U18: =+W18/W3 -> 18566.182 | W18: 204228 | Y18: Financieros | Z18: ScotiaBank | AC18: =+AE18/AE3 -> 20422.8 | AE18: 204228
C19: Bancolombia (American Express) | D19: 1242548.5 | J19: Bancolombia (American Express) | K19: 1242548.5 | L19: 1198874 | M19: =+O19/O3 -> 10986.111 | O19: 98875 | R19: Bancolombia (American Express) | S19: 1242548.5 | T19: 1198874 | U19: =+W19/W3 -> 8988.6364 | W19: 98875 | Z19: Bancolombia (American Express) | AC19: =+AE19/AE3 -> 9887.5 | AE19: 98875
C20: Bancolombia (Visa) | D20: 3737029.6 | J20: Bancolombia (Visa) | K20: 3737029.6 | L20: 3299796 | M20: =+O20/O3 -> 61166.889 | O20: 550502 | R20: Bancolombia (Visa) | S20: 3737029.6 | T20: 3299796 | U20: =+W20/W3 -> 50045.636 | W20: 550502 | Z20: Bancolombia (Visa) | AC20: =+AE20/AE3 -> 20246.2 | AE20: 202462
C21: Banco Hector (cuantos meses) | E21: =+G21/30 -> 0 | G21: 0 | J21: Banco Hector (cuantos meses) | M21: =+O21/O3 -> 66666.667 | O21: 600000 | R21: Banco Hector (cuantos meses) | U21: =+W21/W3 -> 54545.455 | W21: 600000 | Z21: Banco Hector (cuantos meses) | AC21: =+AE21/AE3 -> 60000 | AE21: 600000
